Workbook
Name aircrafttype: #REF!
Name Boeing: '[1]PSA Escalation'!$H$4
Name BoeingPPDS: '[1]PSA Escalation'!$H$5
Name Canadian: #REF!
Name ColourPerc: [2]Formats!#REF!
Name ColourStart: [2]Formats!#REF!
Name ColourStart1: [2]Formats!#REF!
Name ColourStart2: [2]Formats!#REF!
Name CoverIncDisclaimer: #REF!
Name Crown: #REF!
Name DATA1: #REF!
Name DATA10: #REF!
Name DATA11: #REF!
Name DATA12: #REF!
Name DATA13: #REF!
Name DATA14: #REF!
Name DATA15: #REF!
Name DATA16: #REF!
Name DATA17: #REF!
Name DATA18: #REF!
Name DATA19: #REF!
Name DATA2: #REF!
Name DATA20: #REF!
Name DATA21: #REF!
Name DATA3: #REF!
Name DATA4: #REF!
Name DATA5: #REF!
Name DATA6: #REF!
Name DATA7: #REF!
Name DATA8: #REF!
Name DATA9: #REF!
Name Date: #REF!
Name doctypedescription: #REF!
Name doctypefull: #REF!
Name Dollar: #REF!
Name EMB170190_AMS: '[1]PSA Escalation'!$H$14
Name Euro: #REF!
Name Fleetparam: #REF!
Name FleetParamRows: #REF!
Name forecast: #REF!
Name Franc: #REF!
Name FutureDel: #REF!
Name INCDisclaimer: #REF!
Name lastrundate: #REF!
Name nameofairline: #REF!
Name Negative: '[1]Non-Constrained'!$D$38:$I$42
Name Negative2: '[1]2Tier&ATC'!$D$36:$E$40
Name Neutral: '[1]Non-Constrained'!$D$31:$I$35
Name Neutral2: '[1]2Tier&ATC'!$D$29:$E$33
Name No: #REF!
Name note: #REF!
Name note2: [3]Parameter!#REF!
Name Positive: '[1]Non-Constrained'!$D$24:$I$28
Name Positive2: '[1]2Tier&ATC'!$D$22:$E$26
Name Pound: #REF!
Name price: #REF!
Name PW_A380_GP7000: '[1]PSA Escalation'!$H$9
Name rates: #REF!
Name studytitle: #REF!
Name studytypefulldescription: #REF!

Sheet Parameters
A1: Supported Fleet Statistics | F1: ESS CODE | G1: Tolerance Level
A2: Annual Flying Hours (per aircraft) | C2: see Column B in Provisioning Model tab | F2: 1 | G2: 0
A3: Total Repair Time (Including Freight) | C3: see Column J in Provisioning Model tab | F3: 2 | G3: 0
A4: CRF | B4: 0 | C4: 0-1 | F4: 3 | G4: 0
A8: Provisioning Criteria | B8: ESS | C8: Protection Level | D8: Minimum Annual Demand (MAD) | E8: Arisings TRT | F8: Actual TRT Demand | G8: Actual Fill Rate (TAT) | H8: Arisings TRT (Annual) | I8: Actual TRT Demand (Annual) | J8: Actual Fill Rate (Annual) | L8: Desired SL%
A9: Target Fill Rate % Ess 1 | B9: 1 | C9: 0.98 | D9: 0.1 | E9: =' PROVISIONING Model'!BI284 -> 139.15 | F9: =' PROVISIONING Model'!BM284 -> 137.23089 | G9: =F9/E9 -> 0.98620837 | H9: =' PROVISIONING Model'!BQ284 -> 1115.614 | I9: =' PROVISIONING Model'!BU284 -> 1100.2245 | J9: =I9/H9 -> 0.98620533 | L9: 98
A10: Target Fill Rate % Ess 2 | B10: 2 | C10: 0.93 | D10: 0.1 | E10: =' PROVISIONING Model'!BJ284 -> 248.49 | F10: =' PROVISIONING Model'!BN284 -> 237.13467 | G10: =F10/E10 -> 0.95430267 | H10: =' PROVISIONING Model'!BR284 -> 1991.4962 | I10: =' PROVISIONING Model'!BV284 -> 1899.8751 | J10: =I10/H10 -> 0.95399386 | L10: 95
A11: Target Fill Rate % Ess 3 | B11: 3 | C11: 0.91 | D11: 0.1 | E11: =' PROVISIONING Model'!BK284 -> 83.26 | F11: =' PROVISIONING Model'!BO284 -> 77.261447 | G11: =F11/E11 -> 0.92795396 | H11: =' PROVISIONING Model'!BS284 -> 653.39287 | I11: =' PROVISIONING Model'!BW284 -> 606.52276 | J11: =I11/H11 -> 0.92826657 | L11: 92
C12: Vary the Protection Level in Column C such that the "Actual Fill Rate" in Column G meets the Desired Service Level% in Column L
A16: PNs with #N/A output issues - record data if applicable
A17: Prt Number | B17: Selected MTBUR | C17: amended MTBUR

Sheet  PROVISIONING Model
A1: PN | B1: Annual FH | C1: SPC | D1: ESS | E1: QPA | F1: MTBUR for IP | G1: RRI | H1: Buy Price (USD) | I1: Aircraft Count | J1: TAT | K1: Annual Demand - Dann | L1: Expected Demand during Re-supply Time | M1: Protection Level (P.L) | N1: MAD | O1: Does part qualify as spare? | P1: M1 | Q1: M2 | R1: M3 | S1: M4 | T1: M5 | U1: M6 | V1: M7 | W1: M8 | X1: M9 | Y1: M10 | Z1: M11 | AA1: M12 | AB1: M13 | AC1: M14 | AD1: M15 | AE1: M16 | AF1: M17 | AG1: M18 | AH1: M19 | AI1: M20 | AJ1: M21 | AK1: M22 | AL1: M23 | AM1: M24 | AN1: M25 | AO1: M26 | AP1: M27 | AQ1: M28 | AR1: M29 | AS1: M30 | AT1: M31 | AU1: M32 | AV1: M33 | AW1: M34 | AX1: M35 | AY1: M36 | AZ1: M37 | BA1: M38 | BB1: M39 | BC1: M40 | BD1: M41 | BE1: M42 | BF1: Actual P.L. | BG1: Deviation | BH1: Calculation Status | BI1: ESS1 Arising TRT | BJ1: ESS2 Arising TRT | BK1: ESS3 Arising TRT | BM1: ESS1 Actual TRT Demand | BN1: ESS2 Actual TRT Demand | BO1: ESS3 Actual TRT Demand | BQ1: ESS1 Arising Years | BR1: ESS2 Arising Years | BS1: ESS3 Arising Years | BU1: ESS1 Actual annual Demand | BV1: ESS2 Actual Annual Demand | BW1: ESS3 Actual Annual Demand
A2: AR4709-13 | B2: 4000 | C2: 6 | D2: 2 | E2: 1 | F2: 120000 | G2: 0 | H2: 19380 | I2: 60 | J2: 48 | K2: =B2*' PROVISIONING Model'!I2*' PROVISIONING Model'!E2/(' PROVISIONING Model'!F2*POWER(10,' PROVISIONING Model'!G2)) -> 2 | L2: =ROUND(K2*J2/365,2) -> 0.26 | M2: =VLOOKUP(D2,Parameters!$B$9:$C$11,2,FALSE) -> 0.93 | N2: =VLOOKUP(D2,Parameters!$B$9:$D$11,3,FALSE) -> 0.1 | O2: =IF(K2>N2,"Yes","No") -> Yes | P2: =IF(O2="Yes",IF(M2-ROUND(VLOOKUP(L2,'Poisson Distribution Table'!$A$4:$AO$2934,2,FALSE),2)>VLOOKUP(D2,Parameters!$F$1:$G$4,2,FALSE),1,0),0) -> 1 | Q2: =IF(M2-ROUND(POISSON(IF(O2="Yes",IF(M2-ROUND(VLOOKUP(L2,'Poisson Distribution Table'!$A$4:$AO$2934,2,FALSE),2)>VLOOKUP(D2,Parameters!$F$1:$G$4,2,FALSE),1,0),0),L2,TRUE),2)>VLOOKUP(D2,Parameters!$F$1:$G$4,2,FALSE),P2+1,P2) -> 1 | R2: =IF(IF(M2-ROUND(POISSON(Q2,L2,TRUE),2)>VLOOKUP(D2,Parameters!$F$1:$G$4,2,FALSE),"Re-calculate", "OK")="OK",Q2,Q2+1) -> 1 | S2: =IF(IF(M2-ROUND(POISSON(IF(IF(M2-ROUND(POISSON(Q2,L2,TRUE),2)>VLOOKUP(D2,Parameters!$F$1:$G$4,2,FALSE),"Re-calculate", "OK")="OK",Q2,Q2+1),L2,TRUE),2)>VLOOKUP(D2,Parameters!$F$1:$G$4,2,FALSE),"Re-calculate", "OK")="OK",R2,R2+1) -> 1 | T2: =IF(IF(M2-ROUND(POISSON(S2,L2,TRUE),2)>VLOOKUP(D2,Parameters!$F$1:$G$4,2,FALSE),"Re-calculate", "OK")="OK",S2,S2+1) -> 1 | U2: =IF(IF(M2-ROUND(POISSON(IF(IF(M2-ROUND(POISSON(S2,L2,TRUE),2)>VLOOKUP(D2,Parameters!$F$1:$G$4,2,FALSE),"Re-calculate", "OK")="OK",S2,S2+1),L2,TRUE),2)>VLOOKUP(D2,Parameters!$F$1:$G$4,2,FALSE),"Re-calculate", "OK")="OK",T2,T2+1) -> 1 | V2: =IF(IF(M2-ROUND(POISSON(U2,L2,TRUE),2)>VLOOKUP(D2,Parameters!$F$1:$G$4,2,FALSE),"Re-calculate", "OK")="OK",U2,U2+1) -> 1 | W2: =IF(IF(M2-ROUND(POISSON(IF(IF(M2-ROUND(POISSON(U2,L2,TRUE),2)>VLOOKUP(D2,Parameters!$F$1:$G$4,2,FALSE),"Re-calculate", "OK")="OK",U2,U2+1),L2,TRUE),2)>VLOOKUP(D2,Parameters!$F$1:$G$4,2,FALSE),"Re-calculate", "OK")="OK",V2,V2+1) -> 1 | X2: =IF(IF(M2-ROUND(POISSON(W2,L2,TRUE),2)>VLOOKUP(D2,Parameters!$F$1:$G$4,2,FALSE),"Re-calculate", "OK")="OK",W2,W2+1) -> 1 | Y2: =IF(IF(M2-ROUND(POISSON(X2,L2,TRUE),2)>VLOOKUP(D2,Parameters!$F$1:$G$4,2,FALSE),"Re-calculate", "OK")="OK",X2,X2+1) -> 1 | Z2: =IF(IF(M2-ROUND(POISSON(Y2,L2,TRUE),2)>VLOOKUP(D2,Parameters!$F$1:$G$4,2,FALSE),"Re-calculate", "OK")="OK",Y2,Y2+1) -> 1 | AA2: =IF(IF(M2-ROUND(POISSON(Z2,L2,TRUE),2)>VLOOKUP(D2,Parameters!$F$1:$G$4,2,FALSE),"Re-calculate", "OK")="OK",Z2,Z2+1) -> 1 | AB2: =IF(IF(M2-ROUND(POISSON(AA2,L2,TRUE),2)>VLOOKUP(D2,Parameters!$F$1:$G$4,2,FALSE),"Re-calculate", "OK")="OK",AA2,AA2+1) -> 1 | AC2: =IF(IF(M2-ROUND(POISSON(AB2,L2,TRUE),2)>VLOOKUP(D2,Parameters!$F$1:$G$4,2,FALSE),"Re-calculate", "OK")="OK",AB2,AB2+1) -> 1 | AD2: =IF(IF(M2-ROUND(POISSON(AC2,L2,TRUE),2)>VLOOKUP(D2,Parameters!$F$1:$G$4,2,FALSE),"Re-calculate", "OK")="OK",AC2,AC2+1) -> 1 | AE2: =IF(IF(M2-ROUND(POISSON(AD2,L2,TRUE),2)>VLOOKUP(D2,Parameters!$F$1:$G$4,2,FALSE),"Re-calculate", "OK")="OK",AD2,AD2+1) -> 1 | AF2: =IF(IF(M2-ROUND(POISSON(AE2,L2,TRUE),2)>VLOOKUP(D2,Parameters!$F$1:$G$4,2,FALSE),"Re-calculate", "OK")="OK",AE2,AE2+1) -> 1 | AG2: =IF(IF(M2-ROUND(POISSON(AF2,L2,TRUE),2)>VLOOKUP(D2,Parameters!$F$1:$G$4,2,FALSE),"Re-calculate", "OK")="OK",AF2,AF2+1) -> 1 | AH2: =IF(IF(M2-ROUND(POISSON(AG2,L2,TRUE),2)>VLOOKUP(D2,Parameters!$F$1:$G$4,2,FALSE),"Re-calculate", "OK")="OK",AG2,AG2+1) -> 1 | AI2: =IF(IF(M2-ROUND(POISSON(AH2,L2,TRUE),2)>VLOOKUP(D2,Parameters!$F$1:$G$4,2,FALSE),"Re-calculate", "OK")="OK",AH2,AH2+1) -> 1 | AJ2: =IF(IF(M2-ROUND(POISSON(AI2,L2,TRUE),2)>VLOOKUP(D2,Parameters!$F$1:$G$4,2,FALSE),"Re-calculate", "OK")="OK",AI2,AI2+1) -> 1 | AK2: =IF(IF(M2-ROUND(POISSON(AJ2,L2,TRUE),2)>VLOOKUP(D2,Parameters!$F$1:$G$4,2,FALSE),"Re-calculate", "OK")="OK",AJ2,AJ2+1) -> 1 | AL2: =IF(IF(M2-ROUND(POISSON(AK2,L2,TRUE),2)>VLOOKUP(D2,Parameters!$F$1:$G$4,2,FALSE),"Re-calculate", "OK")="OK",AK2,AK2+1) -> 1 | AM2: =IF(IF(M2-ROUND(POISSON(AL2,L2,TRUE),2)>VLOOKUP(D2,Parameters!$F$1:$G$4,2,FALSE),"Re-calculate", "OK")="OK",AL2,AL2+1) -> 1 | AN2: =IF(IF(M2-ROUND(POISSON(AM2,L2,TRUE),2)>VLOOKUP(D2,Parameters!$F$1:$G$4,2,FALSE),"Re-calculate", "OK")="OK",AM2,AM2+1) -> 1 | AO2: =IF(IF(M2-ROUND(POISSON(AN2,L2,TRUE),2)>VLOOKUP(D2,Parameters!$F$1:$G$4,2,FALSE),"Re-calculate", "OK")="OK",AN2,AN2+1) -> 1 | AP2: =IF(IF(M2-ROUND(POISSON(AO2,L2,TRUE),2)>VLOOKUP(D2,Parameters!$F$1:$G$4,2,FALSE),"Re-calculate", "OK")="OK",AO2,AO2+1) -> 1 | AQ2: =IF(IF(M2-ROUND(POISSON(AP2,L2,TRUE),2)>VLOOKUP(D2,Parameters!$F$1:$G$4,2,FALSE),"Re-calculate", "OK")="OK",AP2,AP2+1) -> 1 | AR2: =IF(IF(M2-ROUND(POISSON(AQ2,L2,TRUE),2)>VLOOKUP(D2,Parameters!$F$1:$G$4,2,FALSE),"Re-calculate", "OK")="OK",AQ2,AQ2+1) -> 1 | AS2: =IF(IF(M2-ROUND(POISSON(AR2,L2,TRUE),2)>VLOOKUP(D2,Parameters!$F$1:$G$4,2,FALSE),"Re-calculate", "OK")="OK",AR2,AR2+1) -> 1 | AT2: =IF(IF(M2-ROUND(POISSON(AS2,L2,TRUE),2)>VLOOKUP(D2,Parameters!$F$1:$G$4,2,FALSE),"Re-calculate", "OK")="OK",AS2,AS2+1) -> 1 | AU2: =IF(IF(M2-ROUND(POISSON(AT2,L2,TRUE),2)>VLOOKUP(D2,Parameters!$F$1:$G$4,2,FALSE),"Re-calculate", "OK")="OK",AT2,AT2+1) -> 1 | AV2: =IF(IF(M2-ROUND(POISSON(AU2,L2,TRUE),2)>VLOOKUP(D2,Parameters!$F$1:$G$4,2,FALSE),"Re-calculate", "OK")="OK",AU2,AU2+1) -> 1 | AW2: =IF(IF(M2-ROUND(POISSON(AV2,L2,TRUE),2)>VLOOKUP(D2,Parameters!$F$1:$G$4,2,FALSE),"Re-calculate", "OK")="OK",AV2,AV2+1) -> 1 | AX2: =IF(IF(M2-ROUND(POISSON(AW2,L2,TRUE),2)>VLOOKUP(D2,Parameters!$F$1:$G$4,2,FALSE),"Re-calculate", "OK")="OK",AW2,AW2+1) -> 1 | AY2: =IF(IF(M2-ROUND(POISSON(AX2,L2,TRUE),2)>VLOOKUP(D2,Parameters!$F$1:$G$4,2,FALSE),"Re-calculate", "OK")="OK",AX2,AX2+1) -> 1 | AZ2: =IF(IF(M2-ROUND(POISSON(AY2,L2,TRUE),2)>VLOOKUP(D2,Parameters!$F$1:$G$4,2,FALSE),"Re-calculate", "OK")="OK",AY2,AY2+1) -> 1 | BA2: =IF(IF(M2-ROUND(POISSON(AZ2,L2,TRUE),2)>VLOOKUP(D2,Parameters!$F$1:$G$4,2,FALSE),"Re-calculate", "OK")="OK",AZ2,AZ2+1) -> 1 | BB2: =IF(IF(M2-ROUND(POISSON(BA2,L2,TRUE),2)>VLOOKUP(D2,Parameters!$F$1:$G$4,2,FALSE),"Re-calculate", "OK")="OK",BA2,BA2+1) -> 1 | BC2: =IF(IF(M2-ROUND(POISSON(BB2,L2,TRUE),2)>VLOOKUP(D2,Parameters!$F$1:$G$4,2,FALSE),"Re-calculate", "OK")="OK",BB2,BB2+1) -> 1 | BD2: =IF(IF(M2-ROUND(POISSON(BC2,L2,TRUE),2)>VLOOKUP(D2,Parameters!$F$1:$G$4,2,FALSE),"Re-calculate", "OK")="OK",BC2,BC2+1) -> 1 | BE2: =IF(IF(M2-ROUND(POISSON(BD2,L2,TRUE),2)>VLOOKUP(D2,Parameters!$F$1:$G$4,2,FALSE),"Re-calculate", "OK")="OK",BD2,BD2+1) -> 1 | BF2: =POISSON(BE2,L2,TRUE) -> 0.971525 | BG2: =ROUND(M2-BF2, 2) -> -0.04 | BH2: =IF(BG2>VLOOKUP(D2,Parameters!$F$1:$G$4,2,FALSE),"Re-Calculate","OK") -> OK | BI2: =IF(D2=1,L2," ") | BJ2: =IF(D2=2,L2," ") -> 0.26 | BK2: =IF(D2=3,L2," ") | BM2: =IF(D2=1,L2*BF2," ") | BN2: =IF(D2=2,L2*BF2," ") -> 0.2525965 | BO2: =IF(D2=3,L2*BF2," ") | BQ2: =IF(D2=1,K2," ") | BR2: =IF(D2=2,K2," ") -> 2 | BS2: =IF(D2=3,K2," ") | BU2: =IF(D2=1,K2*BF2," ") | BV2: =IF(D2=2,K2*BF2," ") -> 1.94305 | BW2: =IF(D2=3,K2*BF2," ")
A3: AR4714-11 | B3: 4000 | C3: 2 | D3: 2 | E3: 1 | F3: 120000 | G3: 0 | H3: 5877.3333 | I3: 60 | J3: 48 | K3: =B3*' PROVISIONING Model'!I3*' PROVISIONING Model'!E3/(' PROVISIONING Model'!F3*POWER(10,' PROVISIONING Model'!G3)) -> 2 | L3: =ROUND(K3*J3/365,2) -> 0.26 | M3: =VLOOKUP(D3,Parameters!$B$9:$C$11,2,FALSE) -> 0.93 | N3: =VLOOKUP(D3,Parameters!$B$9:$D$11,3,FALSE) -> 0.1 | O3: =IF(K3>N3,"Yes","No") -> Yes | P3: =IF(O3="Yes",IF(M3-ROUND(VLOOKUP(L3,'Poisson Distribution Table'!$A$4:$AO$2934,2,FALSE),2)>VLOOKUP(D3,Parameters!$F$1:$G$4,2,FALSE),1,0),0) -> 1 | Q3: =IF(M3-ROUND(POISSON(IF(O3="Yes",IF(M3-ROUND(VLOOKUP(L3,'Poisson Distribution Table'!$A$4:$AO$2934,2,FALSE),2)>VLOOKUP(D3,Parameters!$F$1:$G$4,2,FALSE),1,0),0),L3,TRUE),2)>VLOOKUP(D3,Parameters!$F$1:$G$4,2,FALSE),P3+1,P3) -> 1 | R3: =IF(IF(M3-ROUND(POISSON(Q3,L3,TRUE),2)>VLOOKUP(D3,Parameters!$F$1:$G$4,2,FALSE),"Re-calculate", "OK")="OK",Q3,Q3+1) -> 1 | S3: =IF(IF(M3-ROUND(POISSON(IF(IF(M3-ROUND(POISSON(Q3,L3,TRUE),2)>VLOOKUP(D3,Parameters!$F$1:$G$4,2,FALSE),"Re-calculate", "OK")="OK",Q3,Q3+1),L3,TRUE),2)>VLOOKUP(D3,Parameters!$F$1:$G$4,2,FALSE),"Re-calculate", "OK")="OK",R3,R3+1) -> 1 | T3: =IF(IF(M3-ROUND(POISSON(S3,L3,TRUE),2)>VLOOKUP(D3,Parameters!$F$1:$G$4,2,FALSE),"Re-calculate", "OK")="OK",S3,S3+1) -> 1 | U3: =IF(IF(M3-ROUND(POISSON(IF(IF(M3-ROUND(POISSON(S3,L3,TRUE),2)>VLOOKUP(D3,Parameters!$F$1:$G$4,2,FALSE),"Re-calculate", "OK")="OK",S3,S3+1),L3,TRUE),2)>VLOOKUP(D3,Parameters!$F$1:$G$4,2,FALSE),"Re-calculate", "OK")="OK",T3,T3+1) -> 1 | V3: =IF(IF(M3-ROUND(POISSON(U3,L3,TRUE),2)>VLOOKUP(D3,Parameters!$F$1:$G$4,2,FALSE),"Re-calculate", "OK")="OK",U3,U3+1) -> 1 | W3: =IF(IF(M3-ROUND(POISSON(IF(IF(M3-ROUND(POISSON(U3,L3,TRUE),2)>VLOOKUP(D3,Parameters!$F$1:$G$4,2,FALSE),"Re-calculate", "OK")="OK",U3,U3+1),L3,TRUE),2)>VLOOKUP(D3,Parameters!$F$1:$G$4,2,FALSE),"Re-calculate", "OK")="OK",V3,V3+1) -> 1 | X3: =IF(IF(M3-ROUND(POISSON(W3,L3,TRUE),2)>VLOOKUP(D3,Parameters!$F$1:$G$4,2,FALSE),"Re-calculate", "OK")="OK",W3,W3+1) -> 1 | Y3: =IF(IF(M3-ROUND(POISSON(X3,L3,TRUE),2)>VLOOKUP(D3,Parameters!$F$1:$G$4,2,FALSE),"Re-calculate", "OK")="OK",X3,X3+1) -> 1 | Z3: =IF(IF(M3-ROUND(POISSON(Y3,L3,TRUE),2)>VLOOKUP(D3,Parameters!$F$1:$G$4,2,FALSE),"Re-calculate", "OK")="OK",Y3,Y3+1) -> 1 | AA3: =IF(IF(M3-ROUND(POISSON(Z3,L3,TRUE),2)>VLOOKUP(D3,Parameters!$F$1:$G$4,2,FALSE),"Re-calculate", "OK")="OK",Z3,Z3+1) -> 1 | AB3: =IF(IF(M3-ROUND(POISSON(AA3,L3,TRUE),2)>VLOOKUP(D3,Parameters!$F$1:$G$4,2,FALSE),"Re-calculate", "OK")="OK",AA3,AA3+1) -> 1 | AC3: =IF(IF(M3-ROUND(POISSON(AB3,L3,TRUE),2)>VLOOKUP(D3,Parameters!$F$1:$G$4,2,FALSE),"Re-calculate", "OK")="OK",AB3,AB3+1) -> 1 | AD3: =IF(IF(M3-ROUND(POISSON(AC3,L3,TRUE),2)>VLOOKUP(D3,Parameters!$F$1:$G$4,2,FALSE),"Re-calculate", "OK")="OK",AC3,AC3+1) -> 1 | AE3: =IF(IF(M3-ROUND(POISSON(AD3,L3,TRUE),2)>VLOOKUP(D3,Parameters!$F$1:$G$4,2,FALSE),"Re-calculate", "OK")="OK",AD3,AD3+1) -> 1 | AF3: =IF(IF(M3-ROUND(POISSON(AE3,L3,TRUE),2)>VLOOKUP(D3,Parameters!$F$1:$G$4,2,FALSE),"Re-calculate", "OK")="OK",AE3,AE3+1) -> 1 | AG3: =IF(IF(M3-ROUND(POISSON(AF3,L3,TRUE),2)>VLOOKUP(D3,Parameters!$F$1:$G$4,2,FALSE),"Re-calculate", "OK")="OK",AF3,AF3+1) -> 1 | AH3: =IF(IF(M3-ROUND(POISSON(AG3,L3,TRUE),2)>VLOOKUP(D3,Parameters!$F$1:$G$4,2,FALSE),"Re-calculate", "OK")="OK",AG3,AG3+1) -> 1 | AI3: =IF(IF(M3-ROUND(POISSON(AH3,L3,TRUE),2)>VLOOKUP(D3,Parameters!$F$1:$G$4,2,FALSE),"Re-calculate", "OK")="OK",AH3,AH3+1) -> 1 | AJ3: =IF(IF(M3-ROUND(POISSON(AI3,L3,TRUE),2)>VLOOKUP(D3,Parameters!$F$1:$G$4,2,FALSE),"Re-calculate", "OK")="OK",AI3,AI3+1) -> 1 | AK3: =IF(IF(M3-ROUND(POISSON(AJ3,L3,TRUE),2)>VLOOKUP(D3,Parameters!$F$1:$G$4,2,FALSE),"Re-calculate", "OK")="OK",AJ3,AJ3+1) -> 1 | AL3: =IF(IF(M3-ROUND(POISSON(AK3,L3,TRUE),2)>VLOOKUP(D3,Parameters!$F$1:$G$4,2,FALSE),"Re-calculate", "OK")="OK",AK3,AK3+1) -> 1 | AM3: =IF(IF(M3-ROUND(POISSON(AL3,L3,TRUE),2)>VLOOKUP(D3,Parameters!$F$1:$G$4,2,FALSE),"Re-calculate", "OK")="OK",AL3,AL3+1) -> 1 | AN3: =IF(IF(M3-ROUND(POISSON(AM3,L3,TRUE),2)>VLOOKUP(D3,Parameters!$F$1:$G$4,2,FALSE),"Re-calculate", "OK")="OK",AM3,AM3+1) -> 1 | AO3: =IF(IF(M3-ROUND(POISSON(AN3,L3,TRUE),2)>VLOOKUP(D3,Parameters!$F$1:$G$4,2,FALSE),"Re-calculate", "OK")="OK",AN3,AN3+1) -> 1 | AP3: =IF(IF(M3-ROUND(POISSON(AO3,L3,TRUE),2)>VLOOKUP(D3,Parameters!$F$1:$G$4,2,FALSE),"Re-calculate", "OK")="OK",AO3,AO3+1) -> 1 | AQ3: =IF(IF(M3-ROUND(POISSON(AP3,L3,TRUE),2)>VLOOKUP(D3,Parameters!$F$1:$G$4,2,FALSE),"Re-calculate", "OK")="OK",AP3,AP3+1) -> 1 | AR3: =IF(IF(M3-ROUND(POISSON(AQ3,L3,TRUE),2)>VLOOKUP(D3,Parameters!$F$1:$G$4,2,FALSE),"Re-calculate", "OK")="OK",AQ3,AQ3+1) -> 1 | AS3: =IF(IF(M3-ROUND(POISSON(AR3,L3,TRUE),2)>VLOOKUP(D3,Parameters!$F$1:$G$4,2,FALSE),"Re-calculate", "OK")="OK",AR3,AR3+1) -> 1 | AT3: =IF(IF(M3-ROUND(POISSON(AS3,L3,TRUE),2)>VLOOKUP(D3,Parameters!$F$1:$G$4,2,FALSE),"Re-calculate", "OK")="OK",AS3,AS3+1) -> 1 | AU3: =IF(IF(M3-ROUND(POISSON(AT3,L3,TRUE),2)>VLOOKUP(D3,Parameters!$F$1:$G$4,2,FALSE),"Re-calculate", "OK")="OK",AT3,AT3+1) -> 1 | AV3: =IF(IF(M3-ROUND(POISSON(AU3,L3,TRUE),2)>VLOOKUP(D3,Parameters!$F$1:$G$4,2,FALSE),"Re-calculate", "OK")="OK",AU3,AU3+1) -> 1 | AW3: =IF(IF(M3-ROUND(POISSON(AV3,L3,TRUE),2)>VLOOKUP(D3,Parameters!$F$1:$G$4,2,FALSE),"Re-calculate", "OK")="OK",AV3,AV3+1) -> 1 | AX3: =IF(IF(M3-ROUND(POISSON(AW3,L3,TRUE),2)>VLOOKUP(D3,Parameters!$F$1:$G$4,2,FALSE),"Re-calculate", "OK")="OK",AW3,AW3+1) -> 1 | AY3: =IF(IF(M3-ROUND(POISSON(AX3,L3,TRUE),2)>VLOOKUP(D3,Parameters!$F$1:$G$4,2,FALSE),"Re-calculate", "OK")="OK",AX3,AX3+1) -> 1 | AZ3: =IF(IF(M3-ROUND(POISSON(AY3,L3,TRUE),2)>VLOOKUP(D3,Parameters!$F$1:$G$4,2,FALSE),"Re-calculate", "OK")="OK",AY3,AY3+1) -> 1 | BA3: =IF(IF(M3-ROUND(POISSON(AZ3,L3,TRUE),2)>VLOOKUP(D3,Parameters!$F$1:$G$4,2,FALSE),"Re-calculate", "OK")="OK",AZ3,AZ3+1) -> 1 | BB3: =IF(IF(M3-ROUND(POISSON(BA3,L3,TRUE),2)>VLOOKUP(D3,Parameters!$F$1:$G$4,2,FALSE),"Re-calculate", "OK")="OK",BA3,BA3+1) -> 1 | BC3: =IF(IF(M3-ROUND(POISSON(BB3,L3,TRUE),2)>VLOOKUP(D3,Parameters!$F$1:$G$4,2,FALSE),"Re-calculate", "OK")="OK",BB3,BB3+1) -> 1 | BD3: =IF(IF(M3-ROUND(POISSON(BC3,L3,TRUE),2)>VLOOKUP(D3,Parameters!$F$1:$G$4,2,FALSE),"Re-calculate", "OK")="OK",BC3,BC3+1) -> 1 | BE3: =IF(IF(M3-ROUND(POISSON(BD3,L3,TRUE),2)>VLOOKUP(D3,Parameters!$F$1:$G$4,2,FALSE),"Re-calculate", "OK")="OK",BD3,BD3+1) -> 1 | BF3: =POISSON(BE3,L3,TRUE) -> 0.971525 | BG3: =ROUND(M3-BF3, 2) -> -0.04 | BH3: =IF(BG3>VLOOKUP(D3,Parameters!$F$1:$G$4,2,FALSE),"Re-Calculate","OK") -> OK | BI3: =IF(D3=1,L3," ") | BJ3: =IF(D3=2,L3," ") -> 0.26 | BK3: =IF(D3=3,L3," ") | BM3: =IF(D3=1,L3*BF3," ") | BN3: =IF(D3=2,L3*BF3," ") -> 0.2525965 | BO3: =IF(D3=3,L3*BF3," ") | BQ3: =IF(D3=1,K3," ") | BR3: =IF(D3=2,K3," ") -> 2 | BS3: =IF(D3=3,K3," ") | BU3: =IF(D3=1,K3*BF3," ") | BV3: =IF(D3=2,K3*BF3," ") -> 1.94305 | BW3: =IF(D3=3,K3*BF3," ")
A4: AR4714-7 | B4: 4000 | C4: 2 | D4: 2 | E4: 2 | F4: 120000 | G4: 0 | H4: 6100 | I4: 60 | J4: 39 | K4: =B4*' PROVISIONING Model'!I4*' PROVISIONING Model'!E4/(' PROVISIONING Model'!F4*POWER(10,' PROVISIONING Model'!G4)) -> 4 | L4: =ROUND(K4*J4/365,2) -> 0.43 | M4: =VLOOKUP(D4,Parameters!$B$9:$C$11,2,FALSE) -> 0.93 | N4: =VLOOKUP(D4,Parameters!$B$9:$D$11,3,FALSE) -> 0.1 | O4: =IF(K4>N4,"Yes","No") -> Yes | P4: =IF(O4="Yes",IF(M4-ROUND(VLOOKUP(L4,'Poisson Distribution Table'!$A$4:$AO$2934,2,FALSE),2)>VLOOKUP(D4,Parameters!$F$1:$G$4,2,FALSE),1,0),0) -> 1 | Q4: =IF(M4-ROUND(POISSON(IF(O4="Yes",IF(M4-ROUND(VLOOKUP(L4,'Poisson Distribution Table'!$A$4:$AO$2934,2,FALSE),2)>VLOOKUP(D4,Parameters!$F$1:$G$4,2,FALSE),1,0),0),L4,TRUE),2)>VLOOKUP(D4,Parameters!$F$1:$G$4,2,FALSE),P4+1,P4) -> 1 | R4: =IF(IF(M4-ROUND(POISSON(Q4,L4,TRUE),2)>VLOOKUP(D4,Parameters!$F$1:$G$4,2,FALSE),"Re-calculate", "OK")="OK",Q4,Q4+1) -> 1 | S4: =IF(IF(M4-ROUND(POISSON(IF(IF(M4-ROUND(POISSON(Q4,L4,TRUE),2)>VLOOKUP(D4,Parameters!$F$1:$G$4,2,FALSE),"Re-calculate", "OK")="OK",Q4,Q4+1),L4,TRUE),2)>VLOOKUP(D4,Parameters!$F$1:$G$4,2,FALSE),"Re-calculate", "OK")="OK",R4,R4+1) -> 1 | T4: =IF(IF(M4-ROUND(POISSON(S4,L4,TRUE),2)>VLOOKUP(D4,Parameters!$F$1:$G$4,2,FALSE),"Re-calculate", "OK")="OK",S4,S4+1) -> 1 | U4: =IF(IF(M4-ROUND(POISSON(IF(IF(M4-ROUND(POISSON(S4,L4,TRUE),2)>VLOOKUP(D4,Parameters!$F$1:$G$4,2,FALSE),"Re-calculate", "OK")="OK",S4,S4+1),L4,TRUE),2)>VLOOKUP(D4,Parameters!$F$1:$G$4,2,FALSE),"Re-calculate", "OK")="OK",T4,T4+1) -> 1 | V4: =IF(IF(M4-ROUND(POISSON(U4,L4,TRUE),2)>VLOOKUP(D4,Parameters!$F$1:$G$4,2,FALSE),"Re-calculate", "OK")="OK",U4,U4+1) -> 1 | W4: =IF(IF(M4-ROUND(POISSON(IF(IF(M4-ROUND(POISSON(U4,L4,TRUE),2)>VLOOKUP(D4,Parameters!$F$1:$G$4,2,FALSE),"Re-calculate", "OK")="OK",U4,U4+1),L4,TRUE),2)>VLOOKUP(D4,Parameters!$F$1:$G$4,2,FALSE),"Re-calculate", "OK")="OK",V4,V4+1) -> 1 | X4: =IF(IF(M4-ROUND(POISSON(W4,L4,TRUE),2)>VLOOKUP(D4,Parameters!$F$1:$G$4,2,FALSE),"Re-calculate", "OK")="OK",W4,W4+1) -> 1 | Y4: =IF(IF(M4-ROUND(POISSON(X4,L4,TRUE),2)>VLOOKUP(D4,Parameters!$F$1:$G$4,2,FALSE),"Re-calculate", "OK")="OK",X4,X4+1) -> 1 | Z4: =IF(IF(M4-ROUND(POISSON(Y4,L4,TRUE),2)>VLOOKUP(D4,Parameters!$F$1:$G$4,2,FALSE),"Re-calculate", "OK")="OK",Y4,Y4+1) -> 1 | AA4: =IF(IF(M4-ROUND(POISSON(Z4,L4,TRUE),2)>VLOOKUP(D4,Parameters!$F$1:$G$4,2,FALSE),"Re-calculate", "OK")="OK",Z4,Z4+1) -> 1 | AB4: =IF(IF(M4-ROUND(POISSON(AA4,L4,TRUE),2)>VLOOKUP(D4,Parameters!$F$1:$G$4,2,FALSE),"Re-calculate", "OK")="OK",AA4,AA4+1) -> 1 | AC4: =IF(IF(M4-ROUND(POISSON(AB4,L4,TRUE),2)>VLOOKUP(D4,Parameters!$F$1:$G$4,2,FALSE),"Re-calculate", "OK")="OK",AB4,AB4+1) -> 1 | AD4: =IF(IF(M4-ROUND(POISSON(AC4,L4,TRUE),2)>VLOOKUP(D4,Parameters!$F$1:$G$4,2,FALSE),"Re-calculate", "OK")="OK",AC4,AC4+1) -> 1 | AE4: =IF(IF(M4-ROUND(POISSON(AD4,L4,TRUE),2)>VLOOKUP(D4,Parameters!$F$1:$G$4,2,FALSE),"Re-calculate", "OK")="OK",AD4,AD4+1) -> 1 | AF4: =IF(IF(M4-ROUND(POISSON(AE4,L4,TRUE),2)>VLOOKUP(D4,Parameters!$F$1:$G$4,2,FALSE),"Re-calculate", "OK")="OK",AE4,AE4+1) -> 1 | AG4: =IF(IF(M4-ROUND(POISSON(AF4,L4,TRUE),2)>VLOOKUP(D4,Parameters!$F$1:$G$4,2,FALSE),"Re-calculate", "OK")="OK",AF4,AF4+1) -> 1 | AH4: =IF(IF(M4-ROUND(POISSON(AG4,L4,TRUE),2)>VLOOKUP(D4,Parameters!$F$1:$G$4,2,FALSE),"Re-calculate", "OK")="OK",AG4,AG4+1) -> 1 | AI4: =IF(IF(M4-ROUND(POISSON(AH4,L4,TRUE),2)>VLOOKUP(D4,Parameters!$F$1:$G$4,2,FALSE),"Re-calculate", "OK")="OK",AH4,AH4+1) -> 1 | AJ4: =IF(IF(M4-ROUND(POISSON(AI4,L4,TRUE),2)>VLOOKUP(D4,Parameters!$F$1:$G$4,2,FALSE),"Re-calculate", "OK")="OK",AI4,AI4+1) -> 1 | AK4: =IF(IF(M4-ROUND(POISSON(AJ4,L4,TRUE),2)>VLOOKUP(D4,Parameters!$F$1:$G$4,2,FALSE),"Re-calculate", "OK")="OK",AJ4,AJ4+1) -> 1 | AL4: =IF(IF(M4-ROUND(POISSON(AK4,L4,TRUE),2)>VLOOKUP(D4,Parameters!$F$1:$G$4,2,FALSE),"Re-calculate", "OK")="OK",AK4,AK4+1) -> 1 | AM4: =IF(IF(M4-ROUND(POISSON(AL4,L4,TRUE),2)>VLOOKUP(D4,Parameters!$F$1:$G$4,2,FALSE),"Re-calculate", "OK")="OK",AL4,AL4+1) -> 1 | AN4: =IF(IF(M4-ROUND(POISSON(AM4,L4,TRUE),2)>VLOOKUP(D4,Parameters!$F$1:$G$4,2,FALSE),"Re-calculate", "OK")="OK",AM4,AM4+1) -> 1 | AO4: =IF(IF(M4-ROUND(POISSON(AN4,L4,TRUE),2)>VLOOKUP(D4,Parameters!$F$1:$G$4,2,FALSE),"Re-calculate", "OK")="OK",AN4,AN4+1) -> 1 | AP4: =IF(IF(M4-ROUND(POISSON(AO4,L4,TRUE),2)>VLOOKUP(D4,Parameters!$F$1:$G$4,2,FALSE),"Re-calculate", "OK")="OK",AO4,AO4+1) -> 1 | AQ4: =IF(IF(M4-ROUND(POISSON(AP4,L4,TRUE),2)>VLOOKUP(D4,Parameters!$F$1:$G$4,2,FALSE),"Re-calculate", "OK")="OK",AP4,AP4+1) -> 1 | AR4: =IF(IF(M4-ROUND(POISSON(AQ4,L4,TRUE),2)>VLOOKUP(D4,Parameters!$F$1:$G$4,2,FALSE),"Re-calculate", "OK")="OK",AQ4,AQ4+1) -> 1 | AS4: =IF(IF(M4-ROUND(POISSON(AR4,L4,TRUE),2)>VLOOKUP(D4,Parameters!$F$1:$G$4,2,FALSE),"Re-calculate", "OK")="OK",AR4,AR4+1) -> 1 | AT4: =IF(IF(M4-ROUND(POISSON(AS4,L4,TRUE),2)>VLOOKUP(D4,Parameters!$F$1:$G$4,2,FALSE),"Re-calculate", "OK")="OK",AS4,AS4+1) -> 1 | AU4: =IF(IF(M4-ROUND(POISSON(AT4,L4,TRUE),2)>VLOOKUP(D4,Parameters!$F$1:$G$4,2,FALSE),"Re-calculate", "OK")="OK",AT4,AT4+1) -> 1 | AV4: =IF(IF(M4-ROUND(POISSON(AU4,L4,TRUE),2)>VLOOKUP(D4,Parameters!$F$1:$G$4,2,FALSE),"Re-calculate", "OK")="OK",AU4,AU4+1) -> 1 | AW4: =IF(IF(M4-ROUND(POISSON(AV4,L4,TRUE),2)>VLOOKUP(D4,Parameters!$F$1:$G$4,2,FALSE),"Re-calculate", "OK")="OK",AV4,AV4+1) -> 1 | AX4: =IF(IF(M4-ROUND(POISSON(AW4,L4,TRUE),2)>VLOOKUP(D4,Parameters!$F$1:$G$4,2,FALSE),"Re-calculate", "OK")="OK",AW4,AW4+1) -> 1 | AY4: =IF(IF(M4-ROUND(POISSON(AX4,L4,TRUE),2)>VLOOKUP(D4,Parameters!$F$1:$G$4,2,FALSE),"Re-calculate", "OK")="OK",AX4,AX4+1) -> 1 | AZ4: =IF(IF(M4-ROUND(POISSON(AY4,L4,TRUE),2)>VLOOKUP(D4,Parameters!$F$1:$G$4,2,FALSE),"Re-calculate", "OK")="OK",AY4,AY4+1) -> 1 | BA4: =IF(IF(M4-ROUND(POISSON(AZ4,L4,TRUE),2)>VLOOKUP(D4,Parameters!$F$1:$G$4,2,FALSE),"Re-calculate", "OK")="OK",AZ4,AZ4+1) -> 1 | BB4: =IF(IF(M4-ROUND(POISSON(BA4,L4,TRUE),2)>VLOOKUP(D4,Parameters!$F$1:$G$4,2,FALSE),"Re-calculate", "OK")="OK",BA4,BA4+1) -> 1 | BC4: =IF(IF(M4-ROUND(POISSON(BB4,L4,TRUE),2)>VLOOKUP(D4,Parameters!$F$1:$G$4,2,FALSE),"Re-calculate", "OK")="OK",BB4,BB4+1) -> 1 | BD4: =IF(IF(M4-ROUND(POISSON(BC4,L4,TRUE),2)>VLOOKUP(D4,Parameters!$F$1:$G$4,2,FALSE),"Re-calculate", "OK")="OK",BC4,BC4+1) -> 1 | BE4: =IF(IF(M4-ROUND(POISSON(BD4,L4,TRUE),2)>VLOOKUP(D4,Parameters!$F$1:$G$4,2,FALSE),"Re-calculate", "OK")="OK",BD4,BD4+1) -> 1 | BF4: =POISSON(BE4,L4,TRUE) -> 0.93022801 | BG4: =ROUND(M4-BF4, 2) -> 0 | BH4: =IF(BG4>VLOOKUP(D4,Parameters!$F$1:$G$4,2,FALSE),"Re-Calculate","OK") -> OK | BI4: =IF(D4=1,L4," ") | BJ4: =IF(D4=2,L4," ") -> 0.43 | BK4: =IF(D4=3,L4," ") | BM4: =IF(D4=1,L4*BF4," ") | BN4: =IF(D4=2,L4*BF4," ") -> 0.39999804 | BO4: =IF(D4=3,L4*BF4," ") | BQ4: =IF(D4=1,K4," ") | BR4: =IF(D4=2,K4," ") -> 4 | BS4: =IF(D4=3,K4," ") | BU4: =IF(D4=1,K4*BF4," ") | BV4: =IF(D4=2,K4*BF4," ") -> 3.720912 | BW4: =IF(D4=3,K4*BF4," ")
A5: AR90122-5D605 | B5: 4000 | C5: 2 | D5: 3 | E5: 4 | F5: 75600 | G5: 0 | H5: 117680 | I5: 60 | J5: 48 | K5: =B5*' PROVISIONING Model'!I5*' PROVISIONING Model'!E5/(' PROVISIONING Model'!F5*POWER(10,' PROVISIONING Model'!G5)) -> 12.698413 | L5: =ROUND(K5*J5/365,2) -> 1.67 | M5: =VLOOKUP(D5,Parameters!$B$9:$C$11,2,FALSE) -> 0.91 | N5: =VLOOKUP(D5,Parameters!$B$9:$D$11,3,FALSE) -> 0.1 | O5: =IF(K5>N5,"Yes","No") -> Yes | P5: =IF(O5="Yes",IF(M5-ROUND(VLOOKUP(L5,'Poisson Distribution Table'!$A$4:$AO$2934,2,FALSE),2)>VLOOKUP(D5,Parameters!$F$1:$G$4,2,FALSE),1,0),0) -> 1 | Q5: =IF(M5-ROUND(POISSON(IF(O5="Yes",IF(M5-ROUND(VLOOKUP(L5,'Poisson Distribution Table'!$A$4:$AO$2934,2,FALSE),2)>VLOOKUP(D5,Parameters!$F$1:$G$4,2,FALSE),1,0),0),L5,TRUE),2)>VLOOKUP(D5,Parameters!$F$1:$G$4,2,FALSE),P5+1,P5) -> 2 | R5: =IF(IF(M5-ROUND(POISSON(Q5,L5,TRUE),2)>VLOOKUP(D5,Parameters!$F$1:$G$4,2,FALSE),"Re-calculate", "OK")="OK",Q5,Q5+1) -> 3 | S5: =IF(IF(M5-ROUND(POISSON(IF(IF(M5-ROUND(POISSON(Q5,L5,TRUE),2)>VLOOKUP(D5,Parameters!$F$1:$G$4,2,FALSE),"Re-calculate", "OK")="OK",Q5,Q5+1),L5,TRUE),2)>VLOOKUP(D5,Parameters!$F$1:$G$4,2,FALSE),"Re-calculate", "OK")="OK",R5,R5+1) -> 3 | T5: =IF(IF(M5-ROUND(POISSON(S5,L5,TRUE),2)>VLOOKUP(D5,Parameters!$F$1:$G$4,2,FALSE),"Re-calculate", "OK")="OK",S5,S5+1) -> 3 | U5: =IF(IF(M5-ROUND(POISSON(IF(IF(M5-ROUND(POISSON(S5,L5,TRUE),2)>VLOOKUP(D5,Parameters!$F$1:$G$4,2,FALSE),"Re-calculate", "OK")="OK",S5,S5+1),L5,TRUE),2)>VLOOKUP(D5,Parameters!$F$1:$G$4,2,FALSE),"Re-calculate", "OK")="OK",T5,T5+1) -> 3 | V5: =IF(IF(M5-ROUND(POISSON(U5,L5,TRUE),2)>VLOOKUP(D5,Parameters!$F$1:$G$4,2,FALSE),"Re-calculate", "OK")="OK",U5,U5+1) -> 3 | W5: =IF(IF(M5-ROUND(POISSON(IF(IF(M5-ROUND(POISSON(U5,L5,TRUE),2)>VLOOKUP(D5,Parameters!$F$1:$G$4,2,FALSE),"Re-calculate", "OK")="OK",U5,U5+1),L5,TRUE),2)>VLOOKUP(D5,Parameters!$F$1:$G$4,2,FALSE),"Re-calculate", "OK")="OK",V5,V5+1) -> 3 | X5: =IF(IF(M5-ROUND(POISSON(W5,L5,TRUE),2)>VLOOKUP(D5,Parameters!$F$1:$G$4,2,FALSE),"Re-calculate", "OK")="OK",W5,W5+1) -> 3 | Y5: =IF(IF(M5-ROUND(POISSON(X5,L5,TRUE),2)>VLOOKUP(D5,Parameters!$F$1:$G$4,2,FALSE),"Re-calculate", "OK")="OK",X5,X5+1) -> 3 | Z5: =IF(IF(M5-ROUND(POISSON(Y5,L5,TRUE),2)>VLOOKUP(D5,Parameters!$F$1:$G$4,2,FALSE),"Re-calculate", "OK")="OK",Y5,Y5+1) -> 3 | AA5: =IF(IF(M5-ROUND(POISSON(Z5,L5,TRUE),2)>VLOOKUP(D5,Parameters!$F$1:$G$4,2,FALSE),"Re-calculate", "OK")="OK",Z5,Z5+1) -> 3 | AB5: =IF(IF(M5-ROUND(POISSON(AA5,L5,TRUE),2)>VLOOKUP(D5,Parameters!$F$1:$G$4,2,FALSE),"Re-calculate", "OK")="OK",AA5,AA5+1) -> 3 | AC5: =IF(IF(M5-ROUND(POISSON(AB5,L5,TRUE),2)>VLOOKUP(D5,Parameters!$F$1:$G$4,2,FALSE),"Re-calculate", "OK")="OK",AB5,AB5+1) -> 3 | AD5: =IF(IF(M5-ROUND(POISSON(AC5,L5,TRUE),2)>VLOOKUP(D5,Parameters!$F$1:$G$4,2,FALSE),"Re-calculate", "OK")="OK",AC5,AC5+1) -> 3 | AE5: =IF(IF(M5-ROUND(POISSON(AD5,L5,TRUE),2)>VLOOKUP(D5,Parameters!$F$1:$G$4,2,FALSE),"Re-calculate", "OK")="OK",AD5,AD5+1) -> 3 | AF5: =IF(IF(M5-ROUND(POISSON(AE5,L5,TRUE),2)>VLOOKUP(D5,Parameters!$F$1:$G$4,2,FALSE),"Re-calculate", "OK")="OK",AE5,AE5+1) -> 3 | AG5: =IF(IF(M5-ROUND(POISSON(AF5,L5,TRUE),2)>VLOOKUP(D5,Parameters!$F$1:$G$4,2,FALSE),"Re-calculate", "OK")="OK",AF5,AF5+1) -> 3 | AH5: =IF(IF(M5-ROUND(POISSON(AG5,L5,TRUE),2)>VLOOKUP(D5,Parameters!$F$1:$G$4,2,FALSE),"Re-calculate", "OK")="OK",AG5,AG5+1) -> 3 | AI5: =IF(IF(M5-ROUND(POISSON(AH5,L5,TRUE),2)>VLOOKUP(D5,Parameters!$F$1:$G$4,2,FALSE),"Re-calculate", "OK")="OK",AH5,AH5+1) -> 3 | AJ5: =IF(IF(M5-ROUND(POISSON(AI5,L5,TRUE),2)>VLOOKUP(D5,Parameters!$F$1:$G$4,2,FALSE),"Re-calculate", "OK")="OK",AI5,AI5+1) -> 3 | AK5: =IF(IF(M5-ROUND(POISSON(AJ5,L5,TRUE),2)>VLOOKUP(D5,Parameters!$F$1:$G$4,2,FALSE),"Re-calculate", "OK")="OK",AJ5,AJ5+1) -> 3 | AL5: =IF(IF(M5-ROUND(POISSON(AK5,L5,TRUE),2)>VLOOKUP(D5,Parameters!$F$1:$G$4,2,FALSE),"Re-calculate", "OK")="OK",AK5,AK5+1) -> 3 | AM5: =IF(IF(M5-ROUND(POISSON(AL5,L5,TRUE),2)>VLOOKUP(D5,Parameters!$F$1:$G$4,2,FALSE),"Re-calculate", "OK")="OK",AL5,AL5+1) -> 3 | AN5: =IF(IF(M5-ROUND(POISSON(AM5,L5,TRUE),2)>VLOOKUP(D5,Parameters!$F$1:$G$4,2,FALSE),"Re-calculate", "OK")="OK",AM5,AM5+1) -> 3 | AO5: =IF(IF(M5-ROUND(POISSON(AN5,L5,TRUE),2)>VLOOKUP(D5,Parameters!$F$1:$G$4,2,FALSE),"Re-calculate", "OK")="OK",AN5,AN5+1) -> 3 | AP5: =IF(IF(M5-ROUND(POISSON(AO5,L5,TRUE),2)>VLOOKUP(D5,Parameters!$F$1:$G$4,2,FALSE),"Re-calculate", "OK")="OK",AO5,AO5+1) -> 3 | AQ5: =IF(IF(M5-ROUND(POISSON(AP5,L5,TRUE),2)>VLOOKUP(D5,Parameters!$F$1:$G$4,2,FALSE),"Re-calculate", "OK")="OK",AP5,AP5+1) -> 3 | AR5: =IF(IF(M5-ROUND(POISSON(AQ5,L5,TRUE),2)>VLOOKUP(D5,Parameters!$F$1:$G$4,2,FALSE),"Re-calculate", "OK")="OK",AQ5,AQ5+1) -> 3 | AS5: =IF(IF(M5-ROUND(POISSON(AR5,L5,TRUE),2)>VLOOKUP(D5,Parameters!$F$1:$G$4,2,FALSE),"Re-calculate", "OK")="OK",AR5,AR5+1) -> 3 | AT5: =IF(IF(M5-ROUND(POISSON(AS5,L5,TRUE),2)>VLOOKUP(D5,Parameters!$F$1:$G$4,2,FALSE),"Re-calculate", "OK")="OK",AS5,AS5+1) -> 3 | AU5: =IF(IF(M5-ROUND(POISSON(AT5,L5,TRUE),2)>VLOOKUP(D5,Parameters!$F$1:$G$4,2,FALSE),"Re-calculate", "OK")="OK",AT5,AT5+1) -> 3 | AV5: =IF(IF(M5-ROUND(POISSON(AU5,L5,TRUE),2)>VLOOKUP(D5,Parameters!$F$1:$G$4,2,FALSE),"Re-calculate", "OK")="OK",AU5,AU5+1) -> 3 | AW5: =IF(IF(M5-ROUND(POISSON(AV5,L5,TRUE),2)>VLOOKUP(D5,Parameters!$F$1:$G$4,2,FALSE),"Re-calculate", "OK")="OK",AV5,AV5+1) -> 3 | AX5: =IF(IF(M5-ROUND(POISSON(AW5,L5,TRUE),2)>VLOOKUP(D5,Parameters!$F$1:$G$4,2,FALSE),"Re-calculate", "OK")="OK",AW5,AW5+1) -> 3 | AY5: =IF(IF(M5-ROUND(POISSON(AX5,L5,TRUE),2)>VLOOKUP(D5,Parameters!$F$1:$G$4,2,FALSE),"Re-calculate", "OK")="OK",AX5,AX5+1) -> 3 | AZ5: =IF(IF(M5-ROUND(POISSON(AY5,L5,TRUE),2)>VLOOKUP(D5,Parameters!$F$1:$G$4,2,FALSE),"Re-calculate", "OK")="OK",AY5,AY5+1) -> 3 | BA5: =IF(IF(M5-ROUND(POISSON(AZ5,L5,TRUE),2)>VLOOKUP(D5,Parameters!$F$1:$G$4,2,FALSE),"Re-calculate", "OK")="OK",AZ5,AZ5+1) -> 3 | BB5: =IF(IF(M5-ROUND(POISSON(BA5,L5,TRUE),2)>VLOOKUP(D5,Parameters!$F$1:$G$4,2,FALSE),"Re-calculate", "OK")="OK",BA5,BA5+1) -> 3 | BC5: =IF(IF(M5-ROUND(POISSON(BB5,L5,TRUE),2)>VLOOKUP(D5,Parameters!$F$1:$G$4,2,FALSE),"Re-calculate", "OK")="OK",BB5,BB5+1) -> 3 | BD5: =IF(IF(M5-ROUND(POISSON(BC5,L5,TRUE),2)>VLOOKUP(D5,Parameters!$F$1:$G$4,2,FALSE),"Re-calculate", "OK")="OK",BC5,BC5+1) -> 3 | BE5: =IF(IF(M5-ROUND(POISSON(BD5,L5,TRUE),2)>VLOOKUP(D5,Parameters!$F$1:$G$4,2,FALSE),"Re-calculate", "OK")="OK",BD5,BD5+1) -> 3 | BF5: =POISSON(BE5,L5,TRUE) -> 0.91124641 | BG5: =ROUND(M5-BF5, 2) -> 0 | BH5: =IF(BG5>VLOOKUP(D5,Parameters!$F$1:$G$4,2,FALSE),"Re-Calculate","OK") -> OK | BI5: =IF(D5=1,L5," ") | BJ5: =IF(D5=2,L5," ") | BK5: =IF(D5=3,L5," ") -> 1.67 | BM5: =IF(D5=1,L5*BF5," ") | BN5: =IF(D5=2,L5*BF5," ") | BO5: =IF(D5=3,L5*BF5," ") -> 1.5217815 | BQ5: =IF(D5=1,K5," ") | BR5: =IF(D5=2,K5," ") | BS5: =IF(D5=3,K5," ") -> 12.698413 | BU5: =IF(D5=1,K5*BF5," ") | BV5: =IF(D5=2,K5*BF5," ") | BW5: =IF(D5=3,K5*BF5," ") -> 11.571383
A6: Z014H010035C | B6: 4000 | C6: 2 | D6: 2 | E6: 2 | F6: 7500 | G6: 0 | H6: 140502.45 | I6: 60 | J6: 48 | K6: =B6*' PROVISIONING Model'!I6*' PROVISIONING Model'!E6/(' PROVISIONING Model'!F6*POWER(10,' PROVISIONING Model'!G6)) -> 64 | L6: =ROUND(K6*J6/365,2) -> 8.42 | M6: =VLOOKUP(D6,Parameters!$B$9:$C$11,2,FALSE) -> 0.93 | N6: =VLOOKUP(D6,Parameters!$B$9:$D$11,3,FALSE) -> 0.1 | O6: =IF(K6>N6,"Yes","No") -> Yes | P6: =IF(O6="Yes",IF(M6-ROUND(VLOOKUP(L6,'Poisson Distribution Table'!$A$4:$AO$2934,2,FALSE),2)>VLOOKUP(D6,Parameters!$F$1:$G$4,2,FALSE),1,0),0) -> 1 | Q6: =IF(M6-ROUND(POISSON(IF(O6="Yes",IF(M6-ROUND(VLOOKUP(L6,'Poisson Distribution Table'!$A$4:$AO$2934,2,FALSE),2)>VLOOKUP(D6,Parameters!$F$1:$G$4,2,FALSE),1,0),0),L6,TRUE),2)>VLOOKUP(D6,Parameters!$F$1:$G$4,2,FALSE),P6+1,P6) -> 2 | R6: =IF(IF(M6-ROUND(POISSON(Q6,L6,TRUE),2)>VLOOKUP(D6,Parameters!$F$1:$G$4,2,FALSE),"Re-calculate", "OK")="OK",Q6,Q6+1) -> 3 | S6: =IF(IF(M6-ROUND(POISSON(IF(IF(M6-ROUND(POISSON(Q6,L6,TRUE),2)>VLOOKUP(D6,Parameters!$F$1:$G$4,2,FALSE),"Re-calculate", "OK")="OK",Q6,Q6+1),L6,TRUE),2)>VLOOKUP(D6,Parameters!$F$1:$G$4,2,FALSE),"Re-calculate", "OK")="OK",R6,R6+1) -> 4 | T6: =IF(IF(M6-ROUND(POISSON(S6,L6,TRUE),2)>VLOOKUP(D6,Parameters!$F$1:$G$4,2,FALSE),"Re-calculate", "OK")="OK",S6,S6+1) -> 5 | U6: =IF(IF(M6-ROUND(POISSON(IF(IF(M6-ROUND(POISSON(S6,L6,TRUE),2)>VLOOKUP(D6,Parameters!$F$1:$G$4,2,FALSE),"Re-calculate", "OK")="OK",S6,S6+1),L6,TRUE),2)>VLOOKUP(D6,Parameters!$F$1:$G$4,2,FALSE),"Re-calculate", "OK")="OK",T6,T6+1) -> 6 | V6: =IF(IF(M6-ROUND(POISSON(U6,L6,TRUE),2)>VLOOKUP(D6,Parameters!$F$1:$G$4,2,FALSE),"Re-calculate", "OK")="OK",U6,U6+1) -> 7 | W6: =IF(IF(M6-ROUND(POISSON(IF(IF(M6-ROUND(POISSON(U6,L6,TRUE),2)>VLOOKUP(D6,Parameters!$F$1:$G$4,2,FALSE),"Re-calculate", "OK")="OK",U6,U6+1),L6,TRUE),2)>VLOOKUP(D6,Parameters!$F$1:$G$4,2,FALSE),"Re-calculate", "OK")="OK",V6,V6+1) -> 8 | X6: =IF(IF(M6-ROUND(POISSON(W6,L6,TRUE),2)>VLOOKUP(D6,Parameters!$F$1:$G$4,2,FALSE),"Re-calculate", "OK")="OK",W6,W6+1) -> 9 | Y6: =IF(IF(M6-ROUND(POISSON(X6,L6,TRUE),2)>VLOOKUP(D6,Parameters!$F$1:$G$4,2,FALSE),"Re-calculate", "OK")="OK",X6,X6+1) -> 10 | Z6: =IF(IF(M6-ROUND(POISSON(Y6,L6,TRUE),2)>VLOOKUP(D6,Parameters!$F$1:$G$4,2,FALSE),"Re-calculate", "OK")="OK",Y6,Y6+1) -> 11 | AA6: =IF(IF(M6-ROUND(POISSON(Z6,L6,TRUE),2)>VLOOKUP(D6,Parameters!$F$1:$G$4,2,FALSE),"Re-calculate", "OK")="OK",Z6,Z6+1) -> 12 | AB6: =IF(IF(M6-ROUND(POISSON(AA6,L6,TRUE),2)>VLOOKUP(D6,Parameters!$F$1:$G$4,2,FALSE),"Re-calculate", "OK")="OK",AA6,AA6+1) -> 13 | AC6: =IF(IF(M6-ROUND(POISSON(AB6,L6,TRUE),2)>VLOOKUP(D6,Parameters!$F$1:$G$4,2,FALSE),"Re-calculate", "OK")="OK",AB6,AB6+1) -> 13 | AD6: =IF(IF(M6-ROUND(POISSON(AC6,L6,TRUE),2)>VLOOKUP(D6,Parameters!$F$1:$G$4,2,FALSE),"Re-calculate", "OK")="OK",AC6,AC6+1) -> 13 | AE6: =IF(IF(M6-ROUND(POISSON(AD6,L6,TRUE),2)>VLOOKUP(D6,Parameters!$F$1:$G$4,2,FALSE),"Re-calculate", "OK")="OK",AD6,AD6+1) -> 13 | AF6: =IF(IF(M6-ROUND(POISSON(AE6,L6,TRUE),2)>VLOOKUP(D6,Parameters!$F$1:$G$4,2,FALSE),"Re-calculate", "OK")="OK",AE6,AE6+1) -> 13 | AG6: =IF(IF(M6-ROUND(POISSON(AF6,L6,TRUE),2)>VLOOKUP(D6,Parameters!$F$1:$G$4,2,FALSE),"Re-calculate", "OK")="OK",AF6,AF6+1) -> 13 | AH6: =IF(IF(M6-ROUND(POISSON(AG6,L6,TRUE),2)>VLOOKUP(D6,Parameters!$F$1:$G$4,2,FALSE),"Re-calculate", "OK")="OK",AG6,AG6+1) -> 13 | AI6: =IF(IF(M6-ROUND(POISSON(AH6,L6,TRUE),2)>VLOOKUP(D6,Parameters!$F$1:$G$4,2,FALSE),"Re-calculate", "OK")="OK",AH6,AH6+1) -> 13 | AJ6: =IF(IF(M6-ROUND(POISSON(AI6,L6,TRUE),2)>VLOOKUP(D6,Parameters!$F$1:$G$4,2,FALSE),"Re-calculate", "OK")="OK",AI6,AI6+1) -> 13 | AK6: =IF(IF(M6-ROUND(POISSON(AJ6,L6,TRUE),2)>VLOOKUP(D6,Parameters!$F$1:$G$4,2,FALSE),"Re-calculate", "OK")="OK",AJ6,AJ6+1) -> 13 | AL6: =IF(IF(M6-ROUND(POISSON(AK6,L6,TRUE),2)>VLOOKUP(D6,Parameters!$F$1:$G$4,2,FALSE),"Re-calculate", "OK")="OK",AK6,AK6+1) -> 13 | AM6: =IF(IF(M6-ROUND(POISSON(AL6,L6,TRUE),2)>VLOOKUP(D6,Parameters!$F$1:$G$4,2,FALSE),"Re-calculate", "OK")="OK",AL6,AL6+1) -> 13 | AN6: =IF(IF(M6-ROUND(POISSON(AM6,L6,TRUE),2)>VLOOKUP(D6,Parameters!$F$1:$G$4,2,FALSE),"Re-calculate", "OK")="OK",AM6,AM6+1) -> 13 | AO6: =IF(IF(M6-ROUND(POISSON(AN6,L6,TRUE),2)>VLOOKUP(D6,Parameters!$F$1:$G$4,2,FALSE),"Re-calculate", "OK")="OK",AN6,AN6+1) -> 13 | AP6: =IF(IF(M6-ROUND(POISSON(AO6,L6,TRUE),2)>VLOOKUP(D6,Parameters!$F$1:$G$4,2,FALSE),"Re-calculate", "OK")="OK",AO6,AO6+1) -> 13 | AQ6: =IF(IF(M6-ROUND(POISSON(AP6,L6,TRUE),2)>VLOOKUP(D6,Parameters!$F$1:$G$4,2,FALSE),"Re-calculate", "OK")="OK",AP6,AP6+1) -> 13 | AR6: =IF(IF(M6-ROUND(POISSON(AQ6,L6,TRUE),2)>VLOOKUP(D6,Parameters!$F$1:$G$4,2,FALSE),"Re-calculate", "OK")="OK",AQ6,AQ6+1) -> 13 | AS6: =IF(IF(M6-ROUND(POISSON(AR6,L6,TRUE),2)>VLOOKUP(D6,Parameters!$F$1:$G$4,2,FALSE),"Re-calculate", "OK")="OK",AR6,AR6+1) -> 13 | AT6: =IF(IF(M6-ROUND(POISSON(AS6,L6,TRUE),2)>VLOOKUP(D6,Parameters!$F$1:$G$4,2,FALSE),"Re-calculate", "OK")="OK",AS6,AS6+1) -> 13 | AU6: =IF(IF(M6-ROUND(POISSON(AT6,L6,TRUE),2)>VLOOKUP(D6,Parameters!$F$1:$G$4,2,FALSE),"Re-calculate", "OK")="OK",AT6,AT6+1) -> 13 | AV6: =IF(IF(M6-ROUND(POISSON(AU6,L6,TRUE),2)>VLOOKUP(D6,Parameters!$F$1:$G$4,2,FALSE),"Re-calculate", "OK")="OK",AU6,AU6+1) -> 13 | AW6: =IF(IF(M6-ROUND(POISSON(AV6,L6,TRUE),2)>VLOOKUP(D6,Parameters!$F$1:$G$4,2,FALSE),"Re-calculate", "OK")="OK",AV6,AV6+1) -> 13 | AX6: =IF(IF(M6-ROUND(POISSON(AW6,L6,TRUE),2)>VLOOKUP(D6,Parameters!$F$1:$G$4,2,FALSE),"Re-calculate", "OK")="OK",AW6,AW6+1) -> 13 | AY6: =IF(IF(M6-ROUND(POISSON(AX6,L6,TRUE),2)>VLOOKUP(D6,Parameters!$F$1:$G$4,2,FALSE),"Re-calculate", "OK")="OK",AX6,AX6+1) -> 13 | AZ6: =IF(IF(M6-ROUND(POISSON(AY6,L6,TRUE),2)>VLOOKUP(D6,Parameters!$F$1:$G$4,2,FALSE),"Re-calculate", "OK")="OK",AY6,AY6+1) -> 13 | BA6: =IF(IF(M6-ROUND(POISSON(AZ6,L6,TRUE),2)>VLOOKUP(D6,Parameters!$F$1:$G$4,2,FALSE),"Re-calculate", "OK")="OK",AZ6,AZ6+1) -> 13 | BB6: =IF(IF(M6-ROUND(POISSON(BA6,L6,TRUE),2)>VLOOKUP(D6,Parameters!$F$1:$G$4,2,FALSE),"Re-calculate", "OK")="OK",BA6,BA6+1) -> 13 | BC6: =IF(IF(M6-ROUND(POISSON(BB6,L6,TRUE),2)>VLOOKUP(D6,Parameters!$F$1:$G$4,2,FALSE),"Re-calculate", "OK")="OK",BB6,BB6+1) -> 13 | BD6: =IF(IF(M6-ROUND(POISSON(BC6,L6,TRUE),2)>VLOOKUP(D6,Parameters!$F$1:$G$4,2,FALSE),"Re-calculate", "OK")="OK",BC6,BC6+1) -> 13 | BE6: =IF(IF(M6-ROUND(POISSON(BD6,L6,TRUE),2)>VLOOKUP(D6,Parameters!$F$1:$G$4,2,FALSE),"Re-calculate", "OK")="OK",BD6,BD6+1) -> 13 | BF6: =POISSON(BE6,L6,TRUE) -> 0.95168278 | BG6: =ROUND(M6-BF6, 2) -> -0.02 | BH6: =IF(BG6>VLOOKUP(D6,Parameters!$F$1:$G$4,2,FALSE),"Re-Calculate","OK") -> OK | BI6: =IF(D6=1,L6," ") | BJ6: =IF(D6=2,L6," ") -> 8.42 | BK6: =IF(D6=3,L6," ") | BM6: =IF(D6=1,L6*BF6," ") | BN6: =IF(D6=2,L6*BF6," ") -> 8.013169 | BO6: =IF(D6=3,L6*BF6," ") | BQ6: =IF(D6=1,K6," ") | BR6: =IF(D6=2,K6," ") -> 64 | BS6: =IF(D6=3,K6," ") | BU6: =IF(D6=1,K6*BF6," ") | BV6: =IF(D6=2,K6*BF6," ") -> 60.907698 | BW6: =IF(D6=3,K6*BF6," ")
A7: Z043H0101110 | B7: 4000 | C7: 2 | D7: 2 | E7: 5 | F7: 30000 | G7: 0 | H7: 7441.22 | I7: 60 | J7: 48 | K7: =B7*' PROVISIONING Model'!I7*' PROVISIONING Model'!E7/(' PROVISIONING Model'!F7*POWER(10,' PROVISIONING Model'!G7)) -> 40 | L7: =ROUND(K7*J7/365,2) -> 5.26 | M7: =VLOOKUP(D7,Parameters!$B$9:$C$11,2,FALSE) -> 0.93 | N7: =VLOOKUP(D7,Parameters!$B$9:$D$11,3,FALSE) -> 0.1 | O7: =IF(K7>N7,"Yes","No") -> Yes | P7: =IF(O7="Yes",IF(M7-ROUND(VLOOKUP(L7,'Poisson Distribution Table'!$A$4:$AO$2934,2,FALSE),2)>VLOOKUP(D7,Parameters!$F$1:$G$4,2,FALSE),1,0),0) -> 1 | Q7: =IF(M7-ROUND(POISSON(IF(O7="Yes",IF(M7-ROUND(VLOOKUP(L7,'Poisson Distribution Table'!$A$4:$AO$2934,2,FALSE),2)>VLOOKUP(D7,Parameters!$F$1:$G$4,2,FALSE),1,0),0),L7,TRUE),2)>VLOOKUP(D7,Parameters!$F$1:$G$4,2,FALSE),P7+1,P7) -> 2 | R7: =IF(IF(M7-ROUND(POISSON(Q7,L7,TRUE),2)>VLOOKUP(D7,Parameters!$F$1:$G$4,2,FALSE),"Re-calculate", "OK")="OK",Q7,Q7+1) -> 3 | S7: =IF(IF(M7-ROUND(POISSON(IF(IF(M7-ROUND(POISSON(Q7,L7,TRUE),2)>VLOOKUP(D7,Parameters!$F$1:$G$4,2,FALSE),"Re-calculate", "OK")="OK",Q7,Q7+1),L7,TRUE),2)>VLOOKUP(D7,Parameters!$F$1:$G$4,2,FALSE),"Re-calculate", "OK")="OK",R7,R7+1) -> 4 | T7: =IF(IF(M7-ROUND(POISSON(S7,L7,TRUE),2)>VLOOKUP(D7,Parameters!$F$1:$G$4,2,FALSE),"Re-calculate", "OK")="OK",S7,S7+1) -> 5 | U7: =IF(IF(M7-ROUND(POISSON(IF(IF(M7-ROUND(POISSON(S7,L7,TRUE),2)>VLOOKUP(D7,Parameters!$F$1:$G$4,2,FALSE),"Re-calculate", "OK")="OK",S7,S7+1),L7,TRUE),2)>VLOOKUP(D7,Parameters!$F$1:$G$4,2,FALSE),"Re-calculate", "OK")="OK",T7,T7+1) -> 6 | V7: =IF(IF(M7-ROUND(POISSON(U7,L7,TRUE),2)>VLOOKUP(D7,Parameters!$F$1:$G$4,2,FALSE),"Re-calculate", "OK")="OK",U7,U7+1) -> 7 | W7: =IF(IF(M7-ROUND(POISSON(IF(IF(M7-ROUND(POISSON(U7,L7,TRUE),2)>VLOOKUP(D7,Parameters!$F$1:$G$4,2,FALSE),"Re-calculate", "OK")="OK",U7,U7+1),L7,TRUE),2)>VLOOKUP(D7,Parameters!$F$1:$G$4,2,FALSE),"Re-calculate", "OK")="OK",V7,V7+1) -> 8 | X7: =IF(IF(M7-ROUND(POISSON(W7,L7,TRUE),2)>VLOOKUP(D7,Parameters!$F$1:$G$4,2,FALSE),"Re-calculate", "OK")="OK",W7,W7+1) -> 9 | Y7: =IF(IF(M7-ROUND(POISSON(X7,L7,TRUE),2)>VLOOKUP(D7,Parameters!$F$1:$G$4,2,FALSE),"Re-calculate", "OK")="OK",X7,X7+1) -> 9 | Z7: =IF(IF(M7-ROUND(POISSON(Y7,L7,TRUE),2)>VLOOKUP(D7,Parameters!$F$1:$G$4,2,FALSE),"Re-calculate", "OK")="OK",Y7,Y7+1) -> 9 | AA7: =IF(IF(M7-ROUND(POISSON(Z7,L7,TRUE),2)>VLOOKUP(D7,Parameters!$F$1:$G$4,2,FALSE),"Re-calculate", "OK")="OK",Z7,Z7+1) -> 9 | AB7: =IF(IF(M7-ROUND(POISSON(AA7,L7,TRUE),2)>VLOOKUP(D7,Parameters!$F$1:$G$4,2,FALSE),"Re-calculate", "OK")="OK",AA7,AA7+1) -> 9 | AC7: =IF(IF(M7-ROUND(POISSON(AB7,L7,TRUE),2)>VLOOKUP(D7,Parameters!$F$1:$G$4,2,FALSE),"Re-calculate", "OK")="OK",AB7,AB7+1) -> 9 | AD7: =IF(IF(M7-ROUND(POISSON(AC7,L7,TRUE),2)>VLOOKUP(D7,Parameters!$F$1:$G$4,2,FALSE),"Re-calculate", "OK")="OK",AC7,AC7+1) -> 9 | AE7: =IF(IF(M7-ROUND(POISSON(AD7,L7,TRUE),2)>VLOOKUP(D7,Parameters!$F$1:$G$4,2,FALSE),"Re-calculate", "OK")="OK",AD7,AD7+1) -> 9 | AF7: =IF(IF(M7-ROUND(POISSON(AE7,L7,TRUE),2)>VLOOKUP(D7,Parameters!$F$1:$G$4,2,FALSE),"Re-calculate", "OK")="OK",AE7,AE7+1) -> 9 | AG7: =IF(IF(M7-ROUND(POISSON(AF7,L7,TRUE),2)>VLOOKUP(D7,Parameters!$F$1:$G$4,2,FALSE),"Re-calculate", "OK")="OK",AF7,AF7+1) -> 9 | AH7: =IF(IF(M7-ROUND(POISSON(AG7,L7,TRUE),2)>VLOOKUP(D7,Parameters!$F$1:$G$4,2,FALSE),"Re-calculate", "OK")="OK",AG7,AG7+1) -> 9 | AI7: =IF(IF(M7-ROUND(POISSON(AH7,L7,TRUE),2)>VLOOKUP(D7,Parameters!$F$1:$G$4,2,FALSE),"Re-calculate", "OK")="OK",AH7,AH7+1) -> 9 | AJ7: =IF(IF(M7-ROUND(POISSON(AI7,L7,TRUE),2)>VLOOKUP(D7,Parameters!$F$1:$G$4,2,FALSE),"Re-calculate", "OK")="OK",AI7,AI7+1) -> 9 | AK7: =IF(IF(M7-ROUND(POISSON(AJ7,L7,TRUE),2)>VLOOKUP(D7,Parameters!$F$1:$G$4,2,FALSE),"Re-calculate", "OK")="OK",AJ7,AJ7+1) -> 9 | AL7: =IF(IF(M7-ROUND(POISSON(AK7,L7,TRUE),2)>VLOOKUP(D7,Parameters!$F$1:$G$4,2,FALSE),"Re-calculate", "OK")="OK",AK7,AK7+1) -> 9 | AM7: =IF(IF(M7-ROUND(POISSON(AL7,L7,TRUE),2)>VLOOKUP(D7,Parameters!$F$1:$G$4,2,FALSE),"Re-calculate", "OK")="OK",AL7,AL7+1) -> 9 | AN7: =IF(IF(M7-ROUND(POISSON(AM7,L7,TRUE),2)>VLOOKUP(D7,Parameters!$F$1:$G$4,2,FALSE),"Re-calculate", "OK")="OK",AM7,AM7+1) -> 9 | AO7: =IF(IF(M7-ROUND(POISSON(AN7,L7,TRUE),2)>VLOOKUP(D7,Parameters!$F$1:$G$4,2,FALSE),"Re-calculate", "OK")="OK",AN7,AN7+1) -> 9 | AP7: =IF(IF(M7-ROUND(POISSON(AO7,L7,TRUE),2)>VLOOKUP(D7,Parameters!$F$1:$G$4,2,FALSE),"Re-calculate", "OK")="OK",AO7,AO7+1) -> 9 | AQ7: =IF(IF(M7-ROUND(POISSON(AP7,L7,TRUE),2)>VLOOKUP(D7,Parameters!$F$1:$G$4,2,FALSE),"Re-calculate", "OK")="OK",AP7,AP7+1) -> 9 | AR7: =IF(IF(M7-ROUND(POISSON(AQ7,L7,TRUE),2)>VLOOKUP(D7,Parameters!$F$1:$G$4,2,FALSE),"Re-calculate", "OK")="OK",AQ7,AQ7+1) -> 9 | AS7: =IF(IF(M7-ROUND(POISSON(AR7,L7,TRUE),2)>VLOOKUP(D7,Parameters!$F$1:$G$4,2,FALSE),"Re-calculate", "OK")="OK",AR7,AR7+1) -> 9 | AT7: =IF(IF(M7-ROUND(POISSON(AS7,L7,TRUE),2)>VLOOKUP(D7,Parameters!$F$1:$G$4,2,FALSE),"Re-calculate", "OK")="OK",AS7,AS7+1) -> 9 | AU7: =IF(IF(M7-ROUND(POISSON(AT7,L7,TRUE),2)>VLOOKUP(D7,Parameters!$F$1:$G$4,2,FALSE),"Re-calculate", "OK")="OK",AT7,AT7+1) -> 9 | AV7: =IF(IF(M7-ROUND(POISSON(AU7,L7,TRUE),2)>VLOOKUP(D7,Parameters!$F$1:$G$4,2,FALSE),"Re-calculate", "OK")="OK",AU7,AU7+1) -> 9 | AW7: =IF(IF(M7-ROUND(POISSON(AV7,L7,TRUE),2)>VLOOKUP(D7,Parameters!$F$1:$G$4,2,FALSE),"Re-calculate", "OK")="OK",AV7,AV7+1) -> 9 | AX7: =IF(IF(M7-ROUND(POISSON(AW7,L7,TRUE),2)>VLOOKUP(D7,Parameters!$F$1:$G$4,2,FALSE),"Re-calculate", "OK")="OK",AW7,AW7+1) -> 9 | AY7: =IF(IF(M7-ROUND(POISSON(AX7,L7,TRUE),2)>VLOOKUP(D7,Parameters!$F$1:$G$4,2,FALSE),"Re-calculate", "OK")="OK",AX7,AX7+1) -> 9 | AZ7: =IF(IF(M7-ROUND(POISSON(AY7,L7,TRUE),2)>VLOOKUP(D7,Parameters!$F$1:$G$4,2,FALSE),"Re-calculate", "OK")="OK",AY7,AY7+1) -> 9 | BA7: =IF(IF(M7-ROUND(POISSON(AZ7,L7,TRUE),2)>VLOOKUP(D7,Parameters!$F$1:$G$4,2,FALSE),"Re-calculate", "OK")="OK",AZ7,AZ7+1) -> 9 | BB7: =IF(IF(M7-ROUND(POISSON(BA7,L7,TRUE),2)>VLOOKUP(D7,Parameters!$F$1:$G$4,2,FALSE),"Re-calculate", "OK")="OK",BA7,BA7+1) -> 9 | BC7: =IF(IF(M7-ROUND(POISSON(BB7,L7,TRUE),2)>VLOOKUP(D7,Parameters!$F$1:$G$4,2,FALSE),"Re-calculate", "OK")="OK",BB7,BB7+1) -> 9 | BD7: =IF(IF(M7-ROUND(POISSON(BC7,L7,TRUE),2)>VLOOKUP(D7,Parameters!$F$1:$G$4,2,FALSE),"Re-calculate", "OK")="OK",BC7,BC7+1) -> 9 | BE7: =IF(IF(M7-ROUND(POISSON(BD7,L7,TRUE),2)>VLOOKUP(D7,Parameters!$F$1:$G$4,2,FALSE),"Re-calculate", "OK")="OK",BD7,BD7+1) -> 9 | BF7: =POISSON(BE7,L7,TRUE) -> 0.95773403 | BG7: =ROUND(M7-BF7, 2) -> -0.03 | BH7: =IF(BG7>VLOOKUP(D7,Parameters!$F$1:$G$4,2,FALSE),"Re-Calculate","OK") -> OK | BI7: =IF(D7=1,L7," ") | BJ7: =IF(D7=2,L7," ") -> 5.26 | BK7: =IF(D7=3,L7," ") | BM7: =IF(D7=1,L7*BF7," ") | BN7: =IF(D7=2,L7*BF7," ") -> 5.037681 | BO7: =IF(D7=3,L7*BF7," ") | BQ7: =IF(D7=1,K7," ") | BR7: =IF(D7=2,K7," ") -> 40 | BS7: =IF(D7=3,K7," ") | BU7: =IF(D7=1,K7*BF7," ") | BV7: =IF(D7=2,K7*BF7," ") -> 38.309361 | BW7: =IF(D7=3,K7*BF7," ")
A8: Z111H0040131 | B8: 4000 | C8: 2 | D8: 3 | E8: 4 | F8: 15000 | G8: 0 | H8: 8029.07 | I8: 60 | J8: 48 | K8: =B8*' PROVISIONING Model'!I8*' PROVISIONING Model'!E8/(' PROVISIONING Model'!F8*POWER(10,' PROVISIONING Model'!G8)) -> 64 | L8: =ROUND(K8*J8/365,2) -> 8.42 | M8: =VLOOKUP(D8,Parameters!$B$9:$C$11,2,FALSE) -> 0.91 | N8: =VLOOKUP(D8,Parameters!$B$9:$D$11,3,FALSE) -> 0.1 | O8: =IF(K8>N8,"Yes","No") -> Yes | P8: =IF(O8="Yes",IF(M8-ROUND(VLOOKUP(L8,'Poisson Distribution Table'!$A$4:$AO$2934,2,FALSE),2)>VLOOKUP(D8,Parameters!$F$1:$G$4,2,FALSE),1,0),0) -> 1 | Q8: =IF(M8-ROUND(POISSON(IF(O8="Yes",IF(M8-ROUND(VLOOKUP(L8,'Poisson Distribution Table'!$A$4:$AO$2934,2,FALSE),2)>VLOOKUP(D8,Parameters!$F$1:$G$4,2,FALSE),1,0),0),L8,TRUE),2)>VLOOKUP(D8,Parameters!$F$1:$G$4,2,FALSE),P8+1,P8) -> 2 | R8: =IF(IF(M8-ROUND(POISSON(Q8,L8,TRUE),2)>VLOOKUP(D8,Parameters!$F$1:$G$4,2,FALSE),"Re-calculate", "OK")="OK",Q8,Q8+1) -> 3 | S8: =IF(IF(M8-ROUND(POISSON(IF(IF(M8-ROUND(POISSON(Q8,L8,TRUE),2)>VLOOKUP(D8,Parameters!$F$1:$G$4,2,FALSE),"Re-calculate", "OK")="OK",Q8,Q8+1),L8,TRUE),2)>VLOOKUP(D8,Parameters!$F$1:$G$4,2,FALSE),"Re-calculate", "OK")="OK",R8,R8+1) -> 4 | T8: =IF(IF(M8-ROUND(POISSON(S8,L8,TRUE),2)>VLOOKUP(D8,Parameters!$F$1:$G$4,2,FALSE),"Re-calculate", "OK")="OK",S8,S8+1) -> 5 | U8: =IF(IF(M8-ROUND(POISSON(IF(IF(M8-ROUND(POISSON(S8,L8,TRUE),2)>VLOOKUP(D8,Parameters!$F$1:$G$4,2,FALSE),"Re-calculate", "OK")="OK",S8,S8+1),L8,TRUE),2)>VLOOKUP(D8,Parameters!$F$1:$G$4,2,FALSE),"Re-calculate", "OK")="OK",T8,T8+1) -> 6 | V8: =IF(IF(M8-ROUND(POISSON(U8,L8,TRUE),2)>VLOOKUP(D8,Parameters!$F$1:$G$4,2,FALSE),"Re-calculate", "OK")="OK",U8,U8+1) -> 7 | W8: =IF(IF(M8-ROUND(POISSON(IF(IF(M8-ROUND(POISSON(U8,L8,TRUE),2)>VLOOKUP(D8,Parameters!$F$1:$G$4,2,FALSE),"Re-calculate", "OK")="OK",U8,U8+1),L8,TRUE),2)>VLOOKUP(D8,Parameters!$F$1:$G$4,2,FALSE),"Re-calculate", "OK")="OK",V8,V8+1) -> 8 | X8: =IF(IF(M8-ROUND(POISSON(W8,L8,TRUE),2)>VLOOKUP(D8,Parameters!$F$1:$G$4,2,FALSE),"Re-calculate", "OK")="OK",W8,W8+1) -> 9 | Y8: =IF(IF(M8-ROUND(POISSON(X8,L8,TRUE),2)>VLOOKUP(D8,Parameters!$F$1:$G$4,2,FALSE),"Re-calculate", "OK")="OK",X8,X8+1) -> 10 | Z8: =IF(IF(M8-ROUND(POISSON(Y8,L8,TRUE),2)>VLOOKUP(D8,Parameters!$F$1:$G$4,2,FALSE),"Re-calculate", "OK")="OK",Y8,Y8+1) -> 11 | AA8: =IF(IF(M8-ROUND(POISSON(Z8,L8,TRUE),2)>VLOOKUP(D8,Parameters!$F$1:$G$4,2,FALSE),"Re-calculate", "OK")="OK",Z8,Z8+1) -> 12 | AB8: =IF(IF(M8-ROUND(POISSON(AA8,L8,TRUE),2)>VLOOKUP(D8,Parameters!$F$1:$G$4,2,FALSE),"Re-calculate", "OK")="OK",AA8,AA8+1) -> 12 | AC8: =IF(IF(M8-ROUND(POISSON(AB8,L8,TRUE),2)>VLOOKUP(D8,Parameters!$F$1:$G$4,2,FALSE),"Re-calculate", "OK")="OK",AB8,AB8+1) -> 12 | AD8: =IF(IF(M8-ROUND(POISSON(AC8,L8,TRUE),2)>VLOOKUP(D8,Parameters!$F$1:$G$4,2,FALSE),"Re-calculate", "OK")="OK",AC8,AC8+1) -> 12 | AE8: =IF(IF(M8-ROUND(POISSON(AD8,L8,TRUE),2)>VLOOKUP(D8,Parameters!$F$1:$G$4,2,FALSE),"Re-calculate", "OK")="OK",AD8,AD8+1) -> 12 | AF8: =IF(IF(M8-ROUND(POISSON(AE8,L8,TRUE),2)>VLOOKUP(D8,Parameters!$F$1:$G$4,2,FALSE),"Re-calculate", "OK")="OK",AE8,AE8+1) -> 12 | AG8: =IF(IF(M8-ROUND(POISSON(AF8,L8,TRUE),2)>VLOOKUP(D8,Parameters!$F$1:$G$4,2,FALSE),"Re-calculate", "OK")="OK",AF8,AF8+1) -> 12 | AH8: =IF(IF(M8-ROUND(POISSON(AG8,L8,TRUE),2)>VLOOKUP(D8,Parameters!$F$1:$G$4,2,FALSE),"Re-calculate", "OK")="OK",AG8,AG8+1) -> 12 | AI8: =IF(IF(M8-ROUND(POISSON(AH8,L8,TRUE),2)>VLOOKUP(D8,Parameters!$F$1:$G$4,2,FALSE),"Re-calculate", "OK")="OK",AH8,AH8+1) -> 12 | AJ8: =IF(IF(M8-ROUND(POISSON(AI8,L8,TRUE),2)>VLOOKUP(D8,Parameters!$F$1:$G$4,2,FALSE),"Re-calculate", "OK")="OK",AI8,AI8+1) -> 12 | AK8: =IF(IF(M8-ROUND(POISSON(AJ8,L8,TRUE),2)>VLOOKUP(D8,Parameters!$F$1:$G$4,2,FALSE),"Re-calculate", "OK")="OK",AJ8,AJ8+1) -> 12 | AL8: =IF(IF(M8-ROUND(POISSON(AK8,L8,TRUE),2)>VLOOKUP(D8,Parameters!$F$1:$G$4,2,FALSE),"Re-calculate", "OK")="OK",AK8,AK8+1) -> 12 | AM8: =IF(IF(M8-ROUND(POISSON(AL8,L8,TRUE),2)>VLOOKUP(D8,Parameters!$F$1:$G$4,2,FALSE),"Re-calculate", "OK")="OK",AL8,AL8+1) -> 12 | AN8: =IF(IF(M8-ROUND(POISSON(AM8,L8,TRUE),2)>VLOOKUP(D8,Parameters!$F$1:$G$4,2,FALSE),"Re-calculate", "OK")="OK",AM8,AM8+1) -> 12 | AO8: =IF(IF(M8-ROUND(POISSON(AN8,L8,TRUE),2)>VLOOKUP(D8,Parameters!$F$1:$G$4,2,FALSE),"Re-calculate", "OK")="OK",AN8,AN8+1) -> 12 | AP8: =IF(IF(M8-ROUND(POISSON(AO8,L8,TRUE),2)>VLOOKUP(D8,Parameters!$F$1:$G$4,2,FALSE),"Re-calculate", "OK")="OK",AO8,AO8+1) -> 12 | AQ8: =IF(IF(M8-ROUND(POISSON(AP8,L8,TRUE),2)>VLOOKUP(D8,Parameters!$F$1:$G$4,2,FALSE),"Re-calculate", "OK")="OK",AP8,AP8+1) -> 12 | AR8: =IF(IF(M8-ROUND(POISSON(AQ8,L8,TRUE),2)>VLOOKUP(D8,Parameters!$F$1:$G$4,2,FALSE),"Re-calculate", "OK")="OK",AQ8,AQ8+1) -> 12 | AS8: =IF(IF(M8-ROUND(POISSON(AR8,L8,TRUE),2)>VLOOKUP(D8,Parameters!$F$1:$G$4,2,FALSE),"Re-calculate", "OK")="OK",AR8,AR8+1) -> 12 | AT8: =IF(IF(M8-ROUND(POISSON(AS8,L8,TRUE),2)>VLOOKUP(D8,Parameters!$F$1:$G$4,2,FALSE),"Re-calculate", "OK")="OK",AS8,AS8+1) -> 12 | AU8: =IF(IF(M8-ROUND(POISSON(AT8,L8,TRUE),2)>VLOOKUP(D8,Parameters!$F$1:$G$4,2,FALSE),"Re-calculate", "OK")="OK",AT8,AT8+1) -> 12 | AV8: =IF(IF(M8-ROUND(POISSON(AU8,L8,TRUE),2)>VLOOKUP(D8,Parameters!$F$1:$G$4,2,FALSE),"Re-calculate", "OK")="OK",AU8,AU8+1) -> 12 | AW8: =IF(IF(M8-ROUND(POISSON(AV8,L8,TRUE),2)>VLOOKUP(D8,Parameters!$F$1:$G$4,2,FALSE),"Re-calculate", "OK")="OK",AV8,AV8+1) -> 12 | AX8: =IF(IF(M8-ROUND(POISSON(AW8,L8,TRUE),2)>VLOOKUP(D8,Parameters!$F$1:$G$4,2,FALSE),"Re-calculate", "OK")="OK",AW8,AW8+1) -> 12 | AY8: =IF(IF(M8-ROUND(POISSON(AX8,L8,TRUE),2)>VLOOKUP(D8,Parameters!$F$1:$G$4,2,FALSE),"Re-calculate", "OK")="OK",AX8,AX8+1) -> 12 | AZ8: =IF(IF(M8-ROUND(POISSON(AY8,L8,TRUE),2)>VLOOKUP(D8,Parameters!$F$1:$G$4,2,FALSE),"Re-calculate", "OK")="OK",AY8,AY8+1) -> 12 | BA8: =IF(IF(M8-ROUND(POISSON(AZ8,L8,TRUE),2)>VLOOKUP(D8,Parameters!$F$1:$G$4,2,FALSE),"Re-calculate", "OK")="OK",AZ8,AZ8+1) -> 12 | BB8: =IF(IF(M8-ROUND(POISSON(BA8,L8,TRUE),2)>VLOOKUP(D8,Parameters!$F$1:$G$4,2,FALSE),"Re-calculate", "OK")="OK",BA8,BA8+1) -> 12 | BC8: =IF(IF(M8-ROUND(POISSON(BB8,L8,TRUE),2)>VLOOKUP(D8,Parameters!$F$1:$G$4,2,FALSE),"Re-calculate", "OK")="OK",BB8,BB8+1) -> 12 | BD8: =IF(IF(M8-ROUND(POISSON(BC8,L8,TRUE),2)>VLOOKUP(D8,Parameters!$F$1:$G$4,2,FALSE),"Re-calculate", "OK")="OK",BC8,BC8+1) -> 12 | BE8: =IF(IF(M8-ROUND(POISSON(BD8,L8,TRUE),2)>VLOOKUP(D8,Parameters!$F$1:$G$4,2,FALSE),"Re-calculate", "OK")="OK",BD8,BD8+1) -> 12 | BF8: =POISSON(BE8,L8,TRUE) -> 0.91383701 | BG8: =ROUND(M8-BF8, 2) -> 0 | BH8: =IF(BG8>VLOOKUP(D8,Parameters!$F$1:$G$4,2,FALSE),"Re-Calculate","OK") -> OK | BI8: =IF(D8=1,L8," ") | BJ8: =IF(D8=2,L8," ") | BK8: =IF(D8=3,L8," ") -> 8.42 | BM8: =IF(D8=1,L8*BF8," ") | BN8: =IF(D8=2,L8*BF8," ") | BO8: =IF(D8=3,L8*BF8," ") -> 7.6945076 | BQ8: =IF(D8=1,K8," ") | BR8: =IF(D8=2,K8," ") | BS8: =IF(D8=3,K8," ") -> 64 | BU8: =IF(D8=1,K8*BF8," ") | BV8: =IF(D8=2,K8*BF8," ") | BW8: =IF(D8=3,K8*BF8," ") -> 58.485569
A9: Z145HA452120 | B9: 4000 | C9: 2 | D9: 2 | E9: 1 | F9: 11250 | G9: 0 | H9: 76480 | I9: 60 | J9: 48 | K9: =B9*' PROVISIONING Model'!I9*' PROVISIONING Model'!E9/(' PROVISIONING Model'!F9*POWER(10,' PROVISIONING Model'!G9)) -> 21.333333 | L9: =ROUND(K9*J9/365,2) -> 2.81 | M9: =VLOOKUP(D9,Parameters!$B$9:$C$11,2,FALSE) -> 0.93 | N9: =VLOOKUP(D9,Parameters!$B$9:$D$11,3,FALSE) -> 0.1 | O9: =IF(K9>N9,"Yes","No") -> Yes | P9: =IF(O9="Yes",IF(M9-ROUND(VLOOKUP(L9,'Poisson Distribution Table'!$A$4:$AO$2934,2,FALSE),2)>VLOOKUP(D9,Parameters!$F$1:$G$4,2,FALSE),1,0),0) -> 1 | Q9: =IF(M9-ROUND(POISSON(IF(O9="Yes",IF(M9-ROUND(VLOOKUP(L9,'Poisson Distribution Table'!$A$4:$AO$2934,2,FALSE),2)>VLOOKUP(D9,Parameters!$F$1:$G$4,2,FALSE),1,0),0),L9,TRUE),2)>VLOOKUP(D9,Parameters!$F$1:$G$4,2,FALSE),P9+1,P9) -> 2 | R9: =IF(IF(M9-ROUND(POISSON(Q9,L9,TRUE),2)>VLOOKUP(D9,Parameters!$F$1:$G$4,2,FALSE),"Re-calculate", "OK")="OK",Q9,Q9+1) -> 3 | S9: =IF(IF(M9-ROUND(POISSON(IF(IF(M9-ROUND(POISSON(Q9,L9,TRUE),2)>VLOOKUP(D9,Parameters!$F$1:$G$4,2,FALSE),"Re-calculate", "OK")="OK",Q9,Q9+1),L9,TRUE),2)>VLOOKUP(D9,Parameters!$F$1:$G$4,2,FALSE),"Re-calculate", "OK")="OK",R9,R9+1) -> 4 | T9: =IF(IF(M9-ROUND(POISSON(S9,L9,TRUE),2)>VLOOKUP(D9,Parameters!$F$1:$G$4,2,FALSE),"Re-calculate", "OK")="OK",S9,S9+1) -> 5 | U9: =IF(IF(M9-ROUND(POISSON(IF(IF(M9-ROUND(POISSON(S9,L9,TRUE),2)>VLOOKUP(D9,Parameters!$F$1:$G$4,2,FALSE),"Re-calculate", "OK")="OK",S9,S9+1),L9,TRUE),2)>VLOOKUP(D9,Parameters!$F$1:$G$4,2,FALSE),"Re-calculate", "OK")="OK",T9,T9+1) -> 5 | V9: =IF(IF(M9-ROUND(POISSON(U9,L9,TRUE),2)>VLOOKUP(D9,Parameters!$F$1:$G$4,2,FALSE),"Re-calculate", "OK")="OK",U9,U9+1) -> 5 | W9: =IF(IF(M9-ROUND(POISSON(IF(IF(M9-ROUND(POISSON(U9,L9,TRUE),2)>VLOOKUP(D9,Parameters!$F$1:$G$4,2,FALSE),"Re-calculate", "OK")="OK",U9,U9+1),L9,TRUE),2)>VLOOKUP(D9,Parameters!$F$1:$G$4,2,FALSE),"Re-calculate", "OK")="OK",V9,V9+1) -> 5 | X9: =IF(IF(M9-ROUND(POISSON(W9,L9,TRUE),2)>VLOOKUP(D9,Parameters!$F$1:$G$4,2,FALSE),"Re-calculate", "OK")="OK",W9,W9+1) -> 5 | Y9: =IF(IF(M9-ROUND(POISSON(X9,L9,TRUE),2)>VLOOKUP(D9,Parameters!$F$1:$G$4,2,FALSE),"Re-calculate", "OK")="OK",X9,X9+1) -> 5 | Z9: =IF(IF(M9-ROUND(POISSON(Y9,L9,TRUE),2)>VLOOKUP(D9,Parameters!$F$1:$G$4,2,FALSE),"Re-calculate", "OK")="OK",Y9,Y9+1) -> 5 | AA9: =IF(IF(M9-ROUND(POISSON(Z9,L9,TRUE),2)>VLOOKUP(D9,Parameters!$F$1:$G$4,2,FALSE),"Re-calculate", "OK")="OK",Z9,Z9+1) -> 5 | AB9: =IF(IF(M9-ROUND(POISSON(AA9,L9,TRUE),2)>VLOOKUP(D9,Parameters!$F$1:$G$4,2,FALSE),"Re-calculate", "OK")="OK",AA9,AA9+1) -> 5 | AC9: =IF(IF(M9-ROUND(POISSON(AB9,L9,TRUE),2)>VLOOKUP(D9,Parameters!$F$1:$G$4,2,FALSE),"Re-calculate", "OK")="OK",AB9,AB9+1) -> 5 | AD9: =IF(IF(M9-ROUND(POISSON(AC9,L9,TRUE),2)>VLOOKUP(D9,Parameters!$F$1:$G$4,2,FALSE),"Re-calculate", "OK")="OK",AC9,AC9+1) -> 5 | AE9: =IF(IF(M9-ROUND(POISSON(AD9,L9,TRUE),2)>VLOOKUP(D9,Parameters!$F$1:$G$4,2,FALSE),"Re-calculate", "OK")="OK",AD9,AD9+1) -> 5 | AF9: =IF(IF(M9-ROUND(POISSON(AE9,L9,TRUE),2)>VLOOKUP(D9,Parameters!$F$1:$G$4,2,FALSE),"Re-calculate", "OK")="OK",AE9,AE9+1) -> 5 | AG9: =IF(IF(M9-ROUND(POISSON(AF9,L9,TRUE),2)>VLOOKUP(D9,Parameters!$F$1:$G$4,2,FALSE),"Re-calculate", "OK")="OK",AF9,AF9+1) -> 5 | AH9: =IF(IF(M9-ROUND(POISSON(AG9,L9,TRUE),2)>VLOOKUP(D9,Parameters!$F$1:$G$4,2,FALSE),"Re-calculate", "OK")="OK",AG9,AG9+1) -> 5 | AI9: =IF(IF(M9-ROUND(POISSON(AH9,L9,TRUE),2)>VLOOKUP(D9,Parameters!$F$1:$G$4,2,FALSE),"Re-calculate", "OK")="OK",AH9,AH9+1) -> 5 | AJ9: =IF(IF(M9-ROUND(POISSON(AI9,L9,TRUE),2)>VLOOKUP(D9,Parameters!$F$1:$G$4,2,FALSE),"Re-calculate", "OK")="OK",AI9,AI9+1) -> 5 | AK9: =IF(IF(M9-ROUND(POISSON(AJ9,L9,TRUE),2)>VLOOKUP(D9,Parameters!$F$1:$G$4,2,FALSE),"Re-calculate", "OK")="OK",AJ9,AJ9+1) -> 5 | AL9: =IF(IF(M9-ROUND(POISSON(AK9,L9,TRUE),2)>VLOOKUP(D9,Parameters!$F$1:$G$4,2,FALSE),"Re-calculate", "OK")="OK",AK9,AK9+1) -> 5 | AM9: =IF(IF(M9-ROUND(POISSON(AL9,L9,TRUE),2)>VLOOKUP(D9,Parameters!$F$1:$G$4,2,FALSE),"Re-calculate", "OK")="OK",AL9,AL9+1) -> 5 | AN9: =IF(IF(M9-ROUND(POISSON(AM9,L9,TRUE),2)>VLOOKUP(D9,Parameters!$F$1:$G$4,2,FALSE),"Re-calculate", "OK")="OK",AM9,AM9+1) -> 5 | AO9: =IF(IF(M9-ROUND(POISSON(AN9,L9,TRUE),2)>VLOOKUP(D9,Parameters!$F$1:$G$4,2,FALSE),"Re-calculate", "OK")="OK",AN9,AN9+1) -> 5 | AP9: =IF(IF(M9-ROUND(POISSON(AO9,L9,TRUE),2)>VLOOKUP(D9,Parameters!$F$1:$G$4,2,FALSE),"Re-calculate", "OK")="OK",AO9,AO9+1) -> 5 | AQ9: =IF(IF(M9-ROUND(POISSON(AP9,L9,TRUE),2)>VLOOKUP(D9,Parameters!$F$1:$G$4,2,FALSE),"Re-calculate", "OK")="OK",AP9,AP9+1) -> 5 | AR9: =IF(IF(M9-ROUND(POISSON(AQ9,L9,TRUE),2)>VLOOKUP(D9,Parameters!$F$1:$G$4,2,FALSE),"Re-calculate", "OK")="OK",AQ9,AQ9+1) -> 5 | AS9: =IF(IF(M9-ROUND(POISSON(AR9,L9,TRUE),2)>VLOOKUP(D9,Parameters!$F$1:$G$4,2,FALSE),"Re-calculate", "OK")="OK",AR9,AR9+1) -> 5 | AT9: =IF(IF(M9-ROUND(POISSON(AS9,L9,TRUE),2)>VLOOKUP(D9,Parameters!$F$1:$G$4,2,FALSE),"Re-calculate", "OK")="OK",AS9,AS9+1) -> 5 | AU9: =IF(IF(M9-ROUND(POISSON(AT9,L9,TRUE),2)>VLOOKUP(D9,Parameters!$F$1:$G$4,2,FALSE),"Re-calculate", "OK")="OK",AT9,AT9+1) -> 5 | AV9: =IF(IF(M9-ROUND(POISSON(AU9,L9,TRUE),2)>VLOOKUP(D9,Parameters!$F$1:$G$4,2,FALSE),"Re-calculate", "OK")="OK",AU9,AU9+1) -> 5 | AW9: =IF(IF(M9-ROUND(POISSON(AV9,L9,TRUE),2)>VLOOKUP(D9,Parameters!$F$1:$G$4,2,FALSE),"Re-calculate", "OK")="OK",AV9,AV9+1) -> 5 | AX9: =IF(IF(M9-ROUND(POISSON(AW9,L9,TRUE),2)>VLOOKUP(D9,Parameters!$F$1:$G$4,2,FALSE),"Re-calculate", "OK")="OK",AW9,AW9+1) -> 5 | AY9: =IF(IF(M9-ROUND(POISSON(AX9,L9,TRUE),2)>VLOOKUP(D9,Parameters!$F$1:$G$4,2,FALSE),"Re-calculate", "OK")="OK",AX9,AX9+1) -> 5 | AZ9: =IF(IF(M9-ROUND(POISSON(AY9,L9,TRUE),2)>VLOOKUP(D9,Parameters!$F$1:$G$4,2,FALSE),"Re-calculate", "OK")="OK",AY9,AY9+1) -> 5 | BA9: =IF(IF(M9-ROUND(POISSON(AZ9,L9,TRUE),2)>VLOOKUP(D9,Parameters!$F$1:$G$4,2,FALSE),"Re-calculate", "OK")="OK",AZ9,AZ9+1) -> 5 | BB9: =IF(IF(M9-ROUND(POISSON(BA9,L9,TRUE),2)>VLOOKUP(D9,Parameters!$F$1:$G$4,2,FALSE),"Re-calculate", "OK")="OK",BA9,BA9+1) -> 5 | BC9: =IF(IF(M9-ROUND(POISSON(BB9,L9,TRUE),2)>VLOOKUP(D9,Parameters!$F$1:$G$4,2,FALSE),"Re-calculate", "OK")="OK",BB9,BB9+1) -> 5 | BD9: =IF(IF(M9-ROUND(POISSON(BC9,L9,TRUE),2)>VLOOKUP(D9,Parameters!$F$1:$G$4,2,FALSE),"Re-calculate", "OK")="OK",BC9,BC9+1) -> 5 | BE9: =IF(IF(M9-ROUND(POISSON(BD9,L9,TRUE),2)>VLOOKUP(D9,Parameters!$F$1:$G$4,2,FALSE),"Re-calculate", "OK")="OK",BD9,BD9+1) -> 5 | BF9: =POISSON(BE9,L9,TRUE) -> 0.93401412 | BG9: =ROUND(M9-BF9, 2) -> 0 | BH9: =IF(BG9>VLOOKUP(D9,Parameters!$F$1:$G$4,2,FALSE),"Re-Calculate","OK") -> OK | BI9: =IF(D9=1,L9," ") | BJ9: =IF(D9=2,L9," ") -> 2.81 | BK9: =IF(D9=3,L9," ") | BM9: =IF(D9=1,L9*BF9," ") | BN9: =IF(D9=2,L9*BF9," ") -> 2.6245797 | BO9: =IF(D9=3,L9*BF9," ") | BQ9: =IF(D9=1,K9," ") | BR9: =IF(D9=2,K9," ") -> 21.333333 | BS9: =IF(D9=3,K9," ") | BU9: =IF(D9=1,K9*BF9," ") | BV9: =IF(D9=2,K9*BF9," ") -> 19.925635 | BW9: =IF(D9=3,K9*BF9," ")
