Workbook

Sheet ACRD-based Recommendation
A1: PN | B1: FAM Class | C1: Avail Pool Qty by FA PN | D1: Avail Pool Qty by FamClass Adj | E1: Adjusted Total Avail Pool based on Pool Std | F1: Pool Std
A2: AR4709-13 | B2: =VLOOKUP(A2, partNumbers!$A$1:$Z$5000, 6, FALSE) -> STEAS00138 | C2: =IFERROR(VLOOKUP(A2, inhousePoolInfo!$A$1:$D$8000, 4, FALSE), 0) -> 0 | D2: =IFERROR(VLOOKUP(B2, inhousePoolInfo!$I$1:$J$8000, 2, FALSE), 0) -> 6 | E2: 0
A3: AR4714-11 | B3: =VLOOKUP(A3, partNumbers!$A$1:$Z$5000, 6, FALSE) -> STEAS00454 | C3: =IFERROR(VLOOKUP(A3, inhousePoolInfo!$A$1:$D$8000, 4, FALSE), 0) -> 7 | D3: =IFERROR(VLOOKUP(B3, inhousePoolInfo!$I$1:$J$8000, 2, FALSE), 0) -> 8 | E3: 7
A4: AR4714-7 | B4: =VLOOKUP(A4, partNumbers!$A$1:$Z$5000, 6, FALSE) -> STEAS00453 | C4: =IFERROR(VLOOKUP(A4, inhousePoolInfo!$A$1:$D$8000, 4, FALSE), 0) -> 6 | D4: =IFERROR(VLOOKUP(B4, inhousePoolInfo!$I$1:$J$8000, 2, FALSE), 0) -> 8 | E4: 6
A5: AR90122-5D605 | B5: =VLOOKUP(A5, partNumbers!$A$1:$Z$5000, 6, FALSE) -> STEAS00218 | C5: =IFERROR(VLOOKUP(A5, inhousePoolInfo!$A$1:$D$8000, 4, FALSE), 0) -> 0 | D5: =IFERROR(VLOOKUP(B5, inhousePoolInfo!$I$1:$J$8000, 2, FALSE), 0) -> 17 | E5: 0
A6: Z014H010035C | B6: =VLOOKUP(A6, partNumbers!$A$1:$Z$5000, 6, FALSE) -> STEAS00179 | C6: =IFERROR(VLOOKUP(A6, inhousePoolInfo!$A$1:$D$8000, 4, FALSE), 0) -> 0 | D6: =IFERROR(VLOOKUP(B6, inhousePoolInfo!$I$1:$J$8000, 2, FALSE), 0) -> 16 | E6: 3 | F6: Z014H000131A
A7: Z043H0101110 | B7: =VLOOKUP(A7, partNumbers!$A$1:$Z$5000, 6, FALSE) -> STEAS00178 | C7: =IFERROR(VLOOKUP(A7, inhousePoolInfo!$A$1:$D$8000, 4, FALSE), 0) -> 0 | D7: =IFERROR(VLOOKUP(B7, inhousePoolInfo!$I$1:$J$8000, 2, FALSE), 0) -> 12 | E7: 4 | F7: Z043H0100110
A8: Z111H0040131 | B8: =VLOOKUP(A8, partNumbers!$A$1:$Z$5000, 6, FALSE) -> STEAS00052 | C8: =IFERROR(VLOOKUP(A8, inhousePoolInfo!$A$1:$D$8000, 4, FALSE), 0) -> 0 | D8: =IFERROR(VLOOKUP(B8, inhousePoolInfo!$I$1:$J$8000, 2, FALSE), 0) -> 9 | E8: 0
A9: Z145HA452120 | B9: =VLOOKUP(A9, partNumbers!$A$1:$Z$5000, 6, FALSE) -> STEAS00216 | C9: =IFERROR(VLOOKUP(A9, inhousePoolInfo!$A$1:$D$8000, 4, FALSE), 0) -> 0 | D9: =IFERROR(VLOOKUP(B9, inhousePoolInfo!$I$1:$J$8000, 2, FALSE), 0) -> 10 | E9: 0
A10: Z212H0001110 | B10: =VLOOKUP(A10, partNumbers!$A$1:$Z$5000, 6, FALSE) -> STEAS00127 | C10: =IFERROR(VLOOKUP(A10, inhousePoolInfo!$A$1:$D$8000, 4, FALSE), 0) -> 3 | D10: =IFERROR(VLOOKUP(B10, inhousePoolInfo!$I$1:$J$8000, 2, FALSE), 0) -> 9 | E10: 3
A11: Z212H0009110 | B11: =VLOOKUP(A11, partNumbers!$A$1:$Z$5000, 6, FALSE) -> A320-FAM027 | C11: =IFERROR(VLOOKUP(A11, inhousePoolInfo!$A$1:$D$8000, 4, FALSE), 0) -> 0 | D11: =IFERROR(VLOOKUP(B11, inhousePoolInfo!$I$1:$J$8000, 2, FALSE), 0) -> 0 | E11: 0
A12: Z213H0101111 | B12: =VLOOKUP(A12, partNumbers!$A$1:$Z$5000, 6, FALSE) -> A320-FAM028 | C12: =IFERROR(VLOOKUP(A12, inhousePoolInfo!$A$1:$D$8000, 4, FALSE), 0) -> 0 | D12: =IFERROR(VLOOKUP(B12, inhousePoolInfo!$I$1:$J$8000, 2, FALSE), 0) -> 0 | E12: 0
A13: Z233H0000110 | B13: =VLOOKUP(A13, partNumbers!$A$1:$Z$5000, 6, FALSE) -> STEAS00085 | C13: =IFERROR(VLOOKUP(A13, inhousePoolInfo!$A$1:$D$8000, 4, FALSE), 0) -> 1 | D13: =IFERROR(VLOOKUP(B13, inhousePoolInfo!$I$1:$J$8000, 2, FALSE), 0) -> 1 | E13: 1
A14: Z233H0010110 | B14: =VLOOKUP(A14, partNumbers!$A$1:$Z$5000, 6, FALSE) -> STEAS00086 | C14: =IFERROR(VLOOKUP(A14, inhousePoolInfo!$A$1:$D$8000, 4, FALSE), 0) -> 2 | D14: =IFERROR(VLOOKUP(B14, inhousePoolInfo!$I$1:$J$8000, 2, FALSE), 0) -> 2 | E14: 2
A15: Z315H0GA001E | B15: =VLOOKUP(A15, partNumbers!$A$1:$Z$5000, 6, FALSE) -> STEAS00332 | C15: =IFERROR(VLOOKUP(A15, inhousePoolInfo!$A$1:$D$8000, 4, FALSE), 0) -> 0 | D15: =IFERROR(VLOOKUP(B15, inhousePoolInfo!$I$1:$J$8000, 2, FALSE), 0) -> 0 | E15: 0
A16: Z318H015013E | B16: =VLOOKUP(A16, partNumbers!$A$1:$Z$5000, 6, FALSE) -> A320-FAM005 | C16: =IFERROR(VLOOKUP(A16, inhousePoolInfo!$A$1:$D$8000, 4, FALSE), 0) -> 0 | D16: =IFERROR(VLOOKUP(B16, inhousePoolInfo!$I$1:$J$8000, 2, FALSE), 0) -> 0 | E16: 0
A17: Z318H017013E | B17: =VLOOKUP(A17, partNumbers!$A$1:$Z$5000, 6, FALSE) -> A320-FAM006 | C17: =IFERROR(VLOOKUP(A17, inhousePoolInfo!$A$1:$D$8000, 4, FALSE), 0) -> 0 | D17: =IFERROR(VLOOKUP(B17, inhousePoolInfo!$I$1:$J$8000, 2, FALSE), 0) -> 0 | E17: 0
A18: Z318H037023E | B18: =VLOOKUP(A18, partNumbers!$A$1:$Z$5000, 6, FALSE) -> A320-FAM007 | C18: =IFERROR(VLOOKUP(A18, inhousePoolInfo!$A$1:$D$8000, 4, FALSE), 0) -> 0 | D18: =IFERROR(VLOOKUP(B18, inhousePoolInfo!$I$1:$J$8000, 2, FALSE), 0) -> 0 | E18: 0
A19: Z318H078031E | B19: =VLOOKUP(A19, partNumbers!$A$1:$Z$5000, 6, FALSE) -> A320-FAM004 | C19: =IFERROR(VLOOKUP(A19, inhousePoolInfo!$A$1:$D$8000, 4, FALSE), 0) -> 0 | D19: =IFERROR(VLOOKUP(B19, inhousePoolInfo!$I$1:$J$8000, 2, FALSE), 0) -> 0 | E19: 0
... A271: B372EAM0200 | B271: =VLOOKUP(A271, partNumbers!$A$1:$Z$5000, 6, FALSE) -> STEAS00398 | C271: =IFERROR(VLOOKUP(A271, inhousePoolInfo!$A$1:$D$8000, 4, FALSE), 0) -> 0 | D271: =IFERROR(VLOOKUP(B271, inhousePoolInfo!$I$1:$J$8000, 2, FALSE), 0) -> 9 | E271: 0
A272: C12850AC03 | B272: =VLOOKUP(A272, partNumbers!$A$1:$Z$5000, 6, FALSE) -> STEAS00221 | C272: =IFERROR(VLOOKUP(A272, inhousePoolInfo!$A$1:$D$8000, 4, FALSE), 0) -> 7 | D272: =IFERROR(VLOOKUP(B272, inhousePoolInfo!$I$1:$J$8000, 2, FALSE), 0) -> 22 | E272: 13 | F272: C12850AC02
A273: C12860AA08 | B273: =VLOOKUP(A273, partNumbers!$A$1:$Z$5000, 6, FALSE) -> STEAS00105 | C273: =IFERROR(VLOOKUP(A273, inhousePoolInfo!$A$1:$D$8000, 4, FALSE), 0) -> 0 | D273: =IFERROR(VLOOKUP(B273, inhousePoolInfo!$I$1:$J$8000, 2, FALSE), 0) -> 10 | E273: 0
A274: C13153EA02 | B274: =VLOOKUP(A274, partNumbers!$A$1:$Z$5000, 6, FALSE) -> STEAS04896 | C274: =IFERROR(VLOOKUP(A274, inhousePoolInfo!$A$1:$D$8000, 4, FALSE), 0) -> 0 | D274: =IFERROR(VLOOKUP(B274, inhousePoolInfo!$I$1:$J$8000, 2, FALSE), 0) -> 0 | E274: 0
A275: C18456AAA01 | B275: =VLOOKUP(A275, partNumbers!$A$1:$Z$5000, 6, FALSE) -> STEAS00257 | C275: =IFERROR(VLOOKUP(A275, inhousePoolInfo!$A$1:$D$8000, 4, FALSE), 0) -> 1 | D275: =IFERROR(VLOOKUP(B275, inhousePoolInfo!$I$1:$J$8000, 2, FALSE), 0) -> 7 | E275: 1
A276: C19625BA | B276: =VLOOKUP(A276, partNumbers!$A$1:$Z$5000, 6, FALSE) -> STEAS04897 | C276: =IFERROR(VLOOKUP(A276, inhousePoolInfo!$A$1:$D$8000, 4, FALSE), 0) -> 0 | D276: =IFERROR(VLOOKUP(B276, inhousePoolInfo!$I$1:$J$8000, 2, FALSE), 0) -> 1 | E276: 0
A277: C19628AD | B277: =VLOOKUP(A277, partNumbers!$A$1:$Z$5000, 6, FALSE) -> A320-FAM029 | C277: =IFERROR(VLOOKUP(A277, inhousePoolInfo!$A$1:$D$8000, 4, FALSE), 0) -> 0 | D277: =IFERROR(VLOOKUP(B277, inhousePoolInfo!$I$1:$J$8000, 2, FALSE), 0) -> 0 | E277: 0
A278: C19643AD | B278: =VLOOKUP(A278, partNumbers!$A$1:$Z$5000, 6, FALSE) -> A320-FAM030 | C278: =IFERROR(VLOOKUP(A278, inhousePoolInfo!$A$1:$D$8000, 4, FALSE), 0) -> 0 | D278: =IFERROR(VLOOKUP(B278, inhousePoolInfo!$I$1:$J$8000, 2, FALSE), 0) -> 0 | E278: 0
A279: C19755BA01 | B279: =VLOOKUP(A279, partNumbers!$A$1:$Z$5000, 6, FALSE) -> STEAS00186 | C279: =IFERROR(VLOOKUP(A279, inhousePoolInfo!$A$1:$D$8000, 4, FALSE), 0) -> 7 | D279: =IFERROR(VLOOKUP(B279, inhousePoolInfo!$I$1:$J$8000, 2, FALSE), 0) -> 24 | E279: 7
A280: C49AA0222 | B280: =VLOOKUP(A280, partNumbers!$A$1:$Z$5000, 6, FALSE) -> STEAS00715 | C280: =IFERROR(VLOOKUP(A280, inhousePoolInfo!$A$1:$D$8000, 4, FALSE), 0) -> 0 | D280: =IFERROR(VLOOKUP(B280, inhousePoolInfo!$I$1:$J$8000, 2, FALSE), 0) -> 0 | E280: 0
A281: MXP801-21 | B281: =VLOOKUP(A281, partNumbers!$A$1:$Z$5000, 6, FALSE) -> STEAS00452 | C281: =IFERROR(VLOOKUP(A281, inhousePoolInfo!$A$1:$D$8000, 4, FALSE), 0) -> 0 | D281: =IFERROR(VLOOKUP(B281, inhousePoolInfo!$I$1:$J$8000, 2, FALSE), 0) -> 8 | E281: 0
A282: RCF6717 | B282: =VLOOKUP(A282, partNumbers!$A$1:$Z$5000, 6, FALSE) -> STEAS00382 | C282: =IFERROR(VLOOKUP(A282, inhousePoolInfo!$A$1:$D$8000, 4, FALSE), 0) -> 2 | D282: =IFERROR(VLOOKUP(B282, inhousePoolInfo!$I$1:$J$8000, 2, FALSE), 0) -> 18 | E282: 2

Sheet partNumbers
A1: PN | B1: Annual FH | C1: RRI | D1: Buy Price (USD) | E1: Aircraft Count | F1: FAM Class
A2: AR4709-13 | B2: 4000 | C2: 0 | D2: 19380 | E2: 60 | F2: STEAS00138
A3: AR4714-11 | B3: 4000 | C3: 0 | D3: 5877.3333 | E3: 60 | F3: STEAS00454
A4: AR4714-7 | B4: 4000 | C4: 0 | D4: 6100 | E4: 60 | F4: STEAS00453
A5: AR90122-5D605 | B5: 4000 | C5: 0 | D5: 117680 | E5: 60 | F5: STEAS00218
A6: Z014H010035C | B6: 4000 | C6: 0 | D6: 140502.45 | E6: 60 | F6: STEAS00179
A7: Z043H0101110 | B7: 4000 | C7: 0 | D7: 7441.22 | E7: 60 | F7: STEAS00178
A8: Z111H0040131 | B8: 4000 | C8: 0 | D8: 8029.07 | E8: 60 | F8: STEAS00052
A9: Z145HA452120 | B9: 4000 | C9: 0 | D9: 76480 | E9: 60 | F9: STEAS00216
A10: Z212H0001110 | B10: 4000 | C10: 0 | D10: 2968.04 | E10: 60 | F10: STEAS00127
A11: Z212H0009110 | B11: 4000 | C11: 0 | D11: 4550 | E11: 60 | F11: A320-FAM027
A12: Z213H0101111 | B12: 4000 | C12: 0 | D12: 8990 | E12: 60 | F12: A320-FAM028
A13: Z233H0000110 | B13: 4000 | C13: 0 | D13: 1124.21 | E13: 60 | F13: STEAS00085
... A282: RCF6717 | B282: 4000 | C282: 0 | D282: 9474.51 | E282: 60 | F282: STEAS00382

Sheet inhousePoolInfo
A1: To update below info MONTHLY based on latest FA report | I1: If PN is A320neo unique or B737MAX unique, do not consider famclass qty, only use Available Pool Qty by PN; Pool Qty by Famclass will include Pool Qty by FA PN, so do not double-count
E2: Mar 2026 data | K2: Mar 2026 data
A3: FA PN | B3: Famclass | C3: 1 Mar 2026 - FA Qty | D3: Available Pool Qty | E3: Highest NBV (SGD) | F3: Highest Monthly Depreciation (SGD) | I3: Available Pool Qty by Famclass | J3: Available Pool Qty | K3: Highest NBV (SGD) | L3: Highest Monthly Depreciation (SGD)
A4: 003CM00-0200 | B4: STEAS01324 | C4: 2 | D4: 1 | E4: 22542.61 | F4: 86.370133 | I4: STEAS00001 | J4: 8 | K4: 8087.62 | L4: 38.1492
A5: 003-CM-00-0200 | B5: STEAS01324 | C5: 1 | D5: 1 | E5: 24511.22 | F5: 87.85 | I5: STEAS00002 | J5: 4 | K5: 15980.86 | L5: 75.027533
A6: 003CM00-0400 | B6: STEAS01326 | C6: 1 | D6: 1 | E6: 15224.95 | F6: 72.8459 | I6: STEAS00003 | J6: 8 | K6: 15350.46 | L6: 60.197867
A7: 005RL03 | B7: STEAS00832 | C7: 2 | D7: 2 | E7: 323.08 | F7: 1.56 | I7: STEAS00004 | J7: 8 | K7: 5669.68 | L7: 30.157833
A8: 005RL05 | B8: STEAS00832 | C8: 1 | D8: 1 | E8: 15223.66 | F8: 67.07 | I8: STEAS00005 | J8: 4 | K8: 4376.66 | L8: 19.5386
A9: 0102ME2GE | B9: STEAS00415 | C9: 7 | D9: 7 | E9: 17995.16 | F9: 66.158667 | I9: STEAS00006 | J9: 20 | K9: 10650.99 | L9: 70.54
A10: 0123FA2 | B10: STEAS02237 | C10: 7 | D10: 4 | E10: 3956.76 | F10: 41.22 | I10: STEAS00008 | J10: 8 | K10: 11530.69 | L10: 62.328167
A11: 0154GL5 | B11: STEAS00418 | C11: 1 | D11: 1 | E11: 0 | F11: 0 | I11: STEAS00009 | J11: 1 | K11: 7737.16 | L11: 113.78
A12: 0154JU | B12: STEAS00975 | C12: 1 | D12: 1 | E12: 0 | F12: 0 | I12: STEAS00010 | J12: 10 | K12: 10181.36 | L12: 73.778056
A13: 0154MW-CLB | B13: STEAS06258 | C13: 2 | D13: 1 | E13: 40206.62 | F13: 134.92153 | I13: STEAS00012 | J13: 1 | K13: 3001.19 | L13: 14.024267
A14: 0154NE2 | B14: STEAS06257 | C14: 1 | D14: 1 | E14: 22468.63 | F14: 84.15 | I14: STEAS00015 | J14: 2 | K14: 0 | L14: 0
A15: 01N65900 | B15: STEAS00196 | C15: 7 | D15: 7 | E15: 1746.21 | F15: 20.0715 | I15: STEAS00016 | J15: 1 | K15: 37605.4 | L15: 139.797
... A32: 066-1093-11 | B32: STEAS02433 | C32: 1 | D32: 1 | E32: 0 | F32: 0 | I32: STEAS00034 | J32: 3 | K32: 7692.79 | L32: 36.458667
A33: 066-50000-1508 | C33: 1 | D33: 1 | E33: 0 | F33: 0 | I33: STEAS00035 | J33: 6 | K33: 22898.71 | L33: 107.00333
A34: 066-50000-2220 | B34: STEAS00113 | C34: 4 | D34: 4 | E34: 1802.1 | F34: 64.36 | I34: STEAS00036 | J34: 9 | K34: 40874.61 | L34: 158.42867
A35: 066-50000-2221 | B35: STEAS00113 | C35: 2 | D35: 1 | E35: 1588.42 | F35: 33.1 | I35: STEAS00037 | J35: 2 | K35: 1016.88 | L35: 19.55
A36: 066-50006-1202 | B36: STEAS00380 | C36: 1 | D36: 1 | E36: 0 | F36: 0 | I36: STEAS00038 | J36: 4 | K36: 5034.76 | L36: 16.838667
A37: 066-50007-0101 | B37: STEAS02438 | C37: 3 | D37: 0 | E37: 22932.52 | F37: 138.15 | I37: STEAS00040 | J37: 17 | K37: 36651.65 | L37: 349.06333
A38: 066-50007-0212 | B38: STEAS00481 | C38: 2 | D38: 2 | E38: 0 | F38: 0 | I38: STEAS00041 | J38: 6 | K38: 10076.58 | L38: 132.58
A39: 066-50007-0222 | B39: STEAS00481 | C39: 1 | D39: 1 | E39: 3044.1 | F39: 304.41 | I39: STEAS00043 | J39: 7 | K39: 274428 | L39: 1016.4
A40: 066-50007-0432 | B40: STEAS00481 | C40: 2 | D40: 2 | E40: 18767.95 | F40: 312.8 | I40: STEAS00044 | J40: 11 | K40: 2015.33 | L40: 28.79
A41: 066-50007-0531 | B41: STEAS02438 | C41: 1 | D41: 0 | E41: 11402.63 | F41: 44.89 | I41: STEAS00045 | J41: 3 | K41: 22622.93 | L41: 84.1001
A42: 066-50007-1531 | B42: STEAS01330 | C42: 4 | D42: 2 | E42: 106441.44 | F42: 403.18727 | I42: STEAS00046 | J42: 10 | K42: 4097.27 | L42: 15.1191
A43: 066-50008-0405 | B43: STEAS00483 | C43: 1 | D43: 1 | E43: 28561.13 | F43: 328.29 | I43: STEAS00047 | J43: 7 | K43: 3346.24 | L43: 39.37
A44: 066-50008-0406 | B44: STEAS00483 | C44: 3 | D44: 1 | E44: 0 | F44: 0 | I44: STEAS00048 | J44: 2 | K44: 0 | L44: 0
A45: 066-50008-0407 | B45: STEAS00483 | C45: 2 | D45: 2 | E45: 13487.18 | F45: 236.62 | I45: STEAS00049 | J45: 18 | K45: 445802.75 | L45: 1714.63
... A110: 1019439-1-001 | B110: STEAS02244 | C110: 3 | D110: 1 | E110: 55016.94 | F110: 221.84 | I110: STEAS00146 | J110: 12 | K110: 38573.61 | L110: 258.88333
A111: 1019439-2-001 | B111: STEAS02244 | C111: 1 | D111: 1 | E111: 76167.65 | F111: 337.025 | I111: STEAS00147 | J111: 0
A112: 1020420-2-114 | B112: STEAS00192 | C112: 1 | D112: 1 | E112: 1059331.2 | F112: 4996.8451 | I112: STEAS00148 | J112: 3 | K112: 76934.73 | L112: 289.22833
A113: 1020420-3-118 | B113: STEAS00192 | C113: 1 | D113: 1 | E113: 1184816.1 | F113: 4628.1879 | I113: STEAS00149 | J113: 6 | K113: 1282.96 | L113: 32.9
A114: 1020896-1 | B114: STEAS01265 | C114: 2 | D114: 2 | E114: 29471.04 | F114: 115.1212 | I114: STEAS00150 | J114: 2 | K114: 6410.33 | L114: 59.36
A115: 1020901-2 | B115: STEAS01266 | C115: 2 | D115: 1 | E115: 25082.87 | F115: 118.31543 | I115: STEAS00151 | J115: 4 | K115: 45862.62 | L115: 179.15087
A116: 1020902-1 | B116: STEAS01267 | C116: 1 | D116: 1 | E116: 5476.68 | F116: 25.712033 | I116: STEAS00154 | J116: 1 | K116: 17778.33 | L116: 67.088067
A117: 1020903-1 | B117: STEAS01268 | C117: 1 | D117: 1 | E117: 47700.02 | F117: 223.94 | I117: STEAS00155 | J117: 9 | K117: 20560.58 | L117: 147.92
A118: 1020923-1 | B118: STEAS01269 | C118: 2 | D118: 1 | E118: 99099.07 | F118: 387.10573 | I118: STEAS00156 | J118: 2 | K118: 704.78 | L118: 8.92
A119: 1020924-1 | B119: STEAS01270 | C119: 2 | D119: 1 | E119: 40012.28 | F119: 156.29803 | I119: STEAS00159 | J119: 1 | K119: 21270.34 | L119: 82.76
A120: 1020925-3 | B120: STEAS01271 | C120: 1 | D120: 1 | E120: 29430.3 | F120: 114.96207 | I120: STEAS00160 | J120: 10 | K120: 5584.72 | L120: 20.532
...

Sheet acrdData
A1: Requested PN | B1: Requested FAM Class | C1: Replacement PN | D1: Replacement FAM Class
A2: Z014H010035C | B2: STEAS00179 | C2: Z014H000131A | D2: STEAS00179
A3: Z043H0101110 | B3: STEAS00178 | C3: Z043H0100110 | D3: STEAS00178
A4: C12850AC03 | B4: STEAS00221 | C4: C12850AC02 | D4: STEAS00221
