Workbook

Sheet Pool Buy Scenarios
A1: PN | B1: Group: A- Inhouse Cap B- OEMs C- Others | C1: IP1- Standalone | D1: Standalone IP1 Qty | E1: IP3- Adj Current Fleet only | F1: IP3 Qty | G1: IP2 - Current Fleet+ Skymark | H1: IP2 Qty | I1: Adjusted Total Avail Pool based on Pool Std | J1: IP2 less Inhouse Pool | K1: IP Qty (Difference Model), considering inhouse pool | L1: 2026 MLP w Tariff (USD) | M1: Manual Top-up for zero stock items | N1: Pool Buy Qty | O1: Pool Buy (USD)
A2: AR4709-13 | B2: =VLOOKUP(A2, partCapability!$B$1:$Q$8000, 16, FALSE) -> Grp C (Others) | C2: =IFERROR(VLOOKUP(A2, partNumbers!$A$1:$E$8000, 5, FALSE), 0) -> 60 | D2: 1 | E2: =IFERROR(VLOOKUP(A2, currentMbhFleet!$S$1:$AO$8000, 17, FALSE), 0) -> 66 | F2: 1 | G2: =C2+E2 -> 126 | H2: 2 | I2: 0 | J2: =H2-I2 -> 2 | K2: =IF(J2<0, 0, IF(E2>0, H2-F2, MAX(0, D2-I2))) -> 1 | L2: =IFERROR(VLOOKUP(A2, partNumbers!$A$1:$Z$5000, 7, FALSE), 0) -> 19380 | M2: 0 | N2: =K2+M2 -> 1 | O2: =N2*L2 -> 19380
A3: AR4714-11 | B3: =VLOOKUP(A3, partCapability!$B$1:$Q$8000, 16, FALSE) -> Grp C (Others) | C3: =IFERROR(VLOOKUP(A3, partNumbers!$A$1:$E$8000, 5, FALSE), 0) -> 60 | D3: 1 | E3: =IFERROR(VLOOKUP(A3, currentMbhFleet!$S$1:$AO$8000, 17, FALSE), 0) -> 105 | F3: 2 | G3: =C3+E3 -> 165 | H3: 2 | I3: 7 | J3: =H3-I3 -> -5 | K3: =IF(J3<0, 0, IF(E3>0, H3-F3, MAX(0, D3-I3))) -> 0 | L3: =IFERROR(VLOOKUP(A3, partNumbers!$A$1:$Z$5000, 7, FALSE), 0) -> 6210 | M3: 0 | N3: =K3+M3 -> 0 | O3: =N3*L3 -> 0
A4: AR4714-7 | B4: =VLOOKUP(A4, partCapability!$B$1:$Q$8000, 16, FALSE) -> Grp C (Others) | C4: =IFERROR(VLOOKUP(A4, partNumbers!$A$1:$E$8000, 5, FALSE), 0) -> 60 | D4: 1 | E4: =IFERROR(VLOOKUP(A4, currentMbhFleet!$S$1:$AO$8000, 17, FALSE), 0) -> 105 | F4: 2 | G4: =C4+E4 -> 165 | H4: 3 | I4: 6 | J4: =H4-I4 -> -3 | K4: =IF(J4<0, 0, IF(E4>0, H4-F4, MAX(0, D4-I4))) -> 0 | L4: =IFERROR(VLOOKUP(A4, partNumbers!$A$1:$Z$5000, 7, FALSE), 0) -> 6100 | M4: 0 | N4: =K4+M4 -> 0 | O4: =N4*L4 -> 0
A5: AR90122-5D605 | B5: =VLOOKUP(A5, partCapability!$B$1:$Q$8000, 16, FALSE) -> Grp C (Others) | C5: =IFERROR(VLOOKUP(A5, partNumbers!$A$1:$E$8000, 5, FALSE), 0) -> 60 | D5: 3 | E5: =IFERROR(VLOOKUP(A5, currentMbhFleet!$S$1:$AO$8000, 17, FALSE), 0) -> 0 | F5: 0 | G5: =C5+E5 -> 60 | H5: 3 | I5: 0 | J5: =H5-I5 -> 3 | K5: =IF(J5<0, 0, IF(E5>0, H5-F5, MAX(0, D5-I5))) -> 3 | L5: =IFERROR(VLOOKUP(A5, partNumbers!$A$1:$Z$5000, 7, FALSE), 0) -> 117680 | M5: 0 | N5: =K5+M5 -> 3 | O5: =N5*L5 -> 353040
A6: Z014H010035C | B6: =VLOOKUP(A6, partCapability!$B$1:$Q$8000, 16, FALSE) -> Grp C (Others) | C6: =IFERROR(VLOOKUP(A6, partNumbers!$A$1:$E$8000, 5, FALSE), 0) -> 60 | D6: 13 | E6: =IFERROR(VLOOKUP(A6, currentMbhFleet!$S$1:$AO$8000, 17, FALSE), 0) -> 66 | F6: 14 | G6: =C6+E6 -> 126 | H6: 24 | I6: 3 | J6: =H6-I6 -> 21 | K6: =IF(J6<0, 0, IF(E6>0, H6-F6, MAX(0, D6-I6))) -> 10 | L6: =IFERROR(VLOOKUP(A6, partNumbers!$A$1:$Z$5000, 7, FALSE), 0) -> 140502 | M6: 0 | N6: =K6+M6 -> 10 | O6: =N6*L6 -> 1405020
A7: Z043H0101110 | B7: =VLOOKUP(A7, partCapability!$B$1:$Q$8000, 16, FALSE) -> Grp C (Others) | C7: =IFERROR(VLOOKUP(A7, partNumbers!$A$1:$E$8000, 5, FALSE), 0) -> 60 | D7: 9 | E7: =IFERROR(VLOOKUP(A7, currentMbhFleet!$S$1:$AO$8000, 17, FALSE), 0) -> 0 | F7: 0 | G7: =C7+E7 -> 60 | H7: 9 | I7: 4 | J7: =H7-I7 -> 5 | K7: =IF(J7<0, 0, IF(E7>0, H7-F7, MAX(0, D7-I7))) -> 5 | L7: =IFERROR(VLOOKUP(A7, partNumbers!$A$1:$Z$5000, 7, FALSE), 0) -> 7441 | M7: 0 | N7: =K7+M7 -> 5 | O7: =N7*L7 -> 37205
A8: Z111H0040131 | B8: =VLOOKUP(A8, partCapability!$B$1:$Q$8000, 16, FALSE) -> Grp C (Others) | C8: =IFERROR(VLOOKUP(A8, partNumbers!$A$1:$E$8000, 5, FALSE), 0) -> 60 | D8: 12 | E8: =IFERROR(VLOOKUP(A8, currentMbhFleet!$S$1:$AO$8000, 17, FALSE), 0) -> 0 | F8: 0 | G8: =C8+E8 -> 60 | H8: 12 | I8: 0 | J8: =H8-I8 -> 12 | K8: =IF(J8<0, 0, IF(E8>0, H8-F8, MAX(0, D8-I8))) -> 12 | L8: =IFERROR(VLOOKUP(A8, partNumbers!$A$1:$Z$5000, 7, FALSE), 0) -> 8029 | M8: 0 | N8: =K8+M8 -> 12 | O8: =N8*L8 -> 96348
A9: Z145HA452120 | B9: =VLOOKUP(A9, partCapability!$B$1:$Q$8000, 16, FALSE) -> Grp C (Others) | C9: =IFERROR(VLOOKUP(A9, partNumbers!$A$1:$E$8000, 5, FALSE), 0) -> 60 | D9: 5 | E9: =IFERROR(VLOOKUP(A9, currentMbhFleet!$S$1:$AO$8000, 17, FALSE), 0) -> 0 | F9: 0 | G9: =C9+E9 -> 60 | H9: 6 | I9: 0 | J9: =H9-I9 -> 6 | K9: =IF(J9<0, 0, IF(E9>0, H9-F9, MAX(0, D9-I9))) -> 5 | L9: =IFERROR(VLOOKUP(A9, partNumbers!$A$1:$Z$5000, 7, FALSE), 0) -> 76480 | M9: 0 | N9: =K9+M9 -> 5 | O9: =N9*L9 -> 382400
A10: Z212H0001110 | B10: =VLOOKUP(A10, partCapability!$B$1:$Q$8000, 16, FALSE) -> Grp C (Others) | C10: =IFERROR(VLOOKUP(A10, partNumbers!$A$1:$E$8000, 5, FALSE), 0) -> 60 | D10: 13 | E10: =IFERROR(VLOOKUP(A10, currentMbhFleet!$S$1:$AO$8000, 17, FALSE), 0) -> 89 | F10: 19 | G10: =C10+E10 -> 149 | H10: 30 | I10: 3 | J10: =H10-I10 -> 27 | K10: =IF(J10<0, 0, IF(E10>0, H10-F10, MAX(0, D10-I10))) -> 11 | L10: =IFERROR(VLOOKUP(A10, partNumbers!$A$1:$Z$5000, 7, FALSE), 0) -> 2968 | M10: 0 | N10: =K10+M10 -> 11 | O10: =N10*L10 -> 32648
A11: Z212H0009110 | B11: =VLOOKUP(A11, partCapability!$B$1:$Q$8000, 16, FALSE) -> Grp C (Others) | C11: =IFERROR(VLOOKUP(A11, partNumbers!$A$1:$E$8000, 5, FALSE), 0) -> 60 | D11: 2 | E11: =IFERROR(VLOOKUP(A11, currentMbhFleet!$S$1:$AO$8000, 17, FALSE), 0) -> 0 | F11: 0 | G11: =C11+E11 -> 60 | H11: 2 | I11: 0 | J11: =H11-I11 -> 2 | K11: =IF(J11<0, 0, IF(E11>0, H11-F11, MAX(0, D11-I11))) -> 2 | L11: =IFERROR(VLOOKUP(A11, partNumbers!$A$1:$Z$5000, 7, FALSE), 0) -> 4550 | M11: 0 | N11: =K11+M11 -> 2 | O11: =N11*L11 -> 9100
A12: Z213H0101111 | B12: =VLOOKUP(A12, partCapability!$B$1:$Q$8000, 16, FALSE) -> Grp C (Others) | C12: =IFERROR(VLOOKUP(A12, partNumbers!$A$1:$E$8000, 5, FALSE), 0) -> 60 | D12: 7 | E12: =IFERROR(VLOOKUP(A12, currentMbhFleet!$S$1:$AO$8000, 17, FALSE), 0) -> 0 | F12: 0 | G12: =C12+E12 -> 60 | H12: 7 | I12: 0 | J12: =H12-I12 -> 7 | K12: =IF(J12<0, 0, IF(E12>0, H12-F12, MAX(0, D12-I12))) -> 7 | L12: =IFERROR(VLOOKUP(A12, partNumbers!$A$1:$Z$5000, 7, FALSE), 0) -> 8990 | M12: 0 | N12: =K12+M12 -> 7 | O12: =N12*L12 -> 62930
A13: Z233H0000110 | B13: =VLOOKUP(A13, partCapability!$B$1:$Q$8000, 16, FALSE) -> Grp C (Others) | C13: =IFERROR(VLOOKUP(A13, partNumbers!$A$1:$E$8000, 5, FALSE), 0) -> 60 | D13: 11 | E13: =IFERROR(VLOOKUP(A13, currentMbhFleet!$S$1:$AO$8000, 17, FALSE), 0) -> 66 | F13: 12 | G13: =C13+E13 -> 126 | H13: 21 | I13: 1 | J13: =H13-I13 -> 20 | K13: =IF(J13<0, 0, IF(E13>0, H13-F13, MAX(0, D13-I13))) -> 9 | L13: =IFERROR(VLOOKUP(A13, partNumbers!$A$1:$Z$5000, 7, FALSE), 0) -> 1124 | M13: 0 | N13: =K13+M13 -> 9 | O13: =N13*L13 -> 10116
... A282: RCF6717 | B282: =VLOOKUP(A282, partCapability!$B$1:$Q$8000, 16, FALSE) -> Grp A (CRO) | C282: =IFERROR(VLOOKUP(A282, partNumbers!$A$1:$E$8000, 5, FALSE), 0) -> 60 | D282: 6 | E282: =IFERROR(VLOOKUP(A282, currentMbhFleet!$S$1:$AO$8000, 17, FALSE), 0) -> 93 | F282: 8 | G282: =C282+E282 -> 153 | H282: 11 | I282: 2 | J282: =H282-I282 -> 9 | K282: =IF(J282<0, 0, IF(E282>0, H282-F282, MAX(0, D282-I282))) -> 3 | L282: =IFERROR(VLOOKUP(A282, partNumbers!$A$1:$Z$5000, 7, FALSE), 0) -> 9475 | M282: 0 | N282: =K282+M282 -> 3 | O282: =N282*L282 -> 28425

Sheet partNumbers
A1: PN | B1: Annual FH | C1: RRI | D1: Buy Price (USD) | E1: Aircraft Count | F1: FAM Class | G1: 2026 MLP w Tariff (USD)
A2: AR4709-13 | B2: 4000 | C2: 0 | D2: 19380 | E2: 60 | F2: STEAS00138 | G2: 19380
A3: AR4714-11 | B3: 4000 | C3: 0 | D3: 5877.3333 | E3: 60 | F3: STEAS00454 | G3: 6210
A4: AR4714-7 | B4: 4000 | C4: 0 | D4: 6100 | E4: 60 | F4: STEAS00453 | G4: 6100
A5: AR90122-5D605 | B5: 4000 | C5: 0 | D5: 117680 | E5: 60 | F5: STEAS00218 | G5: 117680
A6: Z014H010035C | B6: 4000 | C6: 0 | D6: 140502.45 | E6: 60 | F6: STEAS00179 | G6: 140502
A7: Z043H0101110 | B7: 4000 | C7: 0 | D7: 7441.22 | E7: 60 | F7: STEAS00178 | G7: 7441
A8: Z111H0040131 | B8: 4000 | C8: 0 | D8: 8029.07 | E8: 60 | F8: STEAS00052 | G8: 8029
A9: Z145HA452120 | B9: 4000 | C9: 0 | D9: 76480 | E9: 60 | F9: STEAS00216 | G9: 76480
A10: Z212H0001110 | B10: 4000 | C10: 0 | D10: 2968.04 | E10: 60 | F10: STEAS00127 | G10: 2968
A11: Z212H0009110 | B11: 4000 | C11: 0 | D11: 4550 | E11: 60 | F11: A320-FAM027 | G11: 4550
A12: Z213H0101111 | B12: 4000 | C12: 0 | D12: 8990 | E12: 60 | F12: A320-FAM028 | G12: 8990
A13: Z233H0000110 | B13: 4000 | C13: 0 | D13: 1124.21 | E13: 60 | F13: STEAS00085 | G13: 1124
... A282: RCF6717 | B282: 4000 | C282: 0 | D282: 9474.51 | E282: 60 | F282: STEAS00382 | G282: 9475

Sheet partCapability
A1: No | B1: PNR | C1: OEM | D1: ATA | E1: ADT | F1: SPC | G1: ESS | H1: MTBUR | I1: QPA | J1: MLP | K1: MLP Source | L1: Buy Price | M1: Buy Price Source | N1: Buy price/MLP % | O1: Include/Exclude from Repair Run | P1: Include/Exclude from IP Run | Q1: Grp A,B,C | R1: SPT | S1: To support MBH? (Bo Rong) | T1: Remarks (Bo Rong) | U1: FAM Class | V1: FAM Class Count | W1: Can you provide repair suport for this part? (YES/NO) | X1: Can you repair it internally within your own MRO, or external subcontracor? | Y1: MRO Cage Code | Z1: MRO Location
A2: 155 | B2: 25225-01 | C2: NORD-MICRO GMBH & CO OHG | D2: 21 | E2: HEATER-DUCT | F2: 2 | G2: 3 | H2: 48000 | I2: 2 | J2: 19030 | K2: Airbus web 23/3/26 | L2: 19030 | M2: Airbus web 23/3/26 | N2: 1 | O2: Include | P2: Include | Q2: Grp C (Others) | R2: 30 | U2: A320-FAM001 | V2: 1
A3: 158 | B3: 405005-00000 | C3: THALES AEROSPACE COMMUNICATIONS | D3: 23 | E3: ANTENNA-LOW GAIN | F3: 6 | G3: 2 | H3: 99750 | I3: 1 | J3: 72640 | K3: Airbus web 23/3/26 | L3: 72640 | M3: Airbus web 23/3/26 | N3: 1 | O3: Exclude | P3: Exclude | S3: No | T3: Reference to JAL experience | U3: A320-FAM002 | V3: 1
A4: 276 | B4: Z934H0503110 | C4: KID SYSTEME GMBH | D4: 23 | E4: CAMERA-CDSS | F4: 2 | G4: 3 | H4: 86400 | I4: 1 | J4: 7780 | K4: Airbus web 23/3/26 | L4: 7780 | M4: Airbus web 23/3/26 | N4: 1 | O4: Include | P4: Include | Q4: Grp C (Others) | R4: 30 | U4: A320-FAM003 | V4: 1
A5: 307 | B5: Z318H078031E | C5: AIRBUS OPERATIONS GMBH | D5: 23 | E5: PANEL-INFORMATION | F5: 2 | G5: 3 | H5: 90000 | I5: 1 | J5: 4770 | K5: Airbus web 23/3/26 | L5: 4770 | M5: Airbus web 23/3/26 | N5: 1 | O5: Include | P5: Include | Q5: Grp C (Others) | R5: 30 | U5: A320-FAM004 | V5: 1
A6: 92 | B6: Z318H015013E | C6: AIRBUS OPERATIONS GMBH | D6: 23 | E6: PSU-PASSENGER SERVICE UNIT | F6: 2 | G6: 3 | H6: 90000 | I6: 10 | J6: 7527.7 | K6: Airbus C9072 Catalogue 2026 | L6: 7527.7 | M6: Airbus C9072 Catalogue 2026 | N6: 1 | O6: Include | P6: Include | Q6: Grp C (Others) | R6: 30 | U6: A320-FAM005 | V6: 1
A7: 52 | B7: Z318H017013E | C7: AIRBUS OPERATIONS GMBH | D7: 23 | E7: PSU-PASSENGER SERVICE UNIT | F7: 2 | G7: 3 | H7: 90000 | I7: 36 | J7: 7527.7 | K7: Airbus C9072 Catalogue 2026 | L7: 7527.7 | M7: Airbus C9072 Catalogue 2026 | N7: 1 | O7: Include | P7: Include | Q7: Grp C (Others) | R7: 30 | U7: A320-FAM006 | V7: 1
A8: 83 | B8: Z318H037023E | C8: AIRBUS OPERATIONS GMBH | D8: 23 | E8: PSU-PASSENGER SERVICE UNIT | F8: 2 | G8: 3 | H8: 90000 | I8: 22 | J8: 9610 | K8: Airbus web 23/3/26 | L8: 9610 | M8: Airbus web 23/3/26 | N8: 1 | O8: Include | P8: Include | Q8: Grp C (Others) | R8: 30 | U8: A320-FAM007 | V8: 1
A9: 49 | B9: RMP4381AA110101 | C9: THALES AEROSPACE COMMUNICATIONS | D9: 23 | E9: RMP-RADIO MANAGEMENT PANEL | F9: 2 | G9: 1 | H9: 23400 | I9: 2 | J9: 52010 | K9: Airbus web 23/3/26 | L9: 52010 | M9: Airbus web 23/3/26 | N9: 1 | O9: Exclude (BTB with Thales) | P9: Include | Q9: Grp B (OEM) | R9: 30 | T9: Thales | U9: A320-FAM008 | V9: 1
A10: 61 | B10: 405045-00001 | C10: THALES AEROSPACE COMMUNICATIONS | D10: 23 | E10: SDU-SATELLITE DATA UNIT | F10: 6 | G10: 2 | H10: 29925 | I10: 1 | J10: 112260 | K10: Airbus web 23/3/26 | L10: 112260 | M10: Airbus web 23/3/26 | N10: 1 | O10: Include | P10: Include | Q10: Grp C (Others) | R10: 30 | U10: A320-FAM009 | V10: 1
A11: 313 | B11: 1J520-10140-000 | C11: DIEHL AEROSPACE GMBH | D11: 25 | E11: CLEDU-CABIN LED UNIT | F11: 2 | G11: 3 | H11: 57600 | I11: 1 | J11: 2020 | K11: Airbus web 23/3/26 | L11: 2020 | M11: Airbus web 23/3/26 | N11: 1 | O11: Exclude | P11: Exclude | S11: No | T11: High BER Rate | U11: A320-FAM010 | V11: 1
A12: 279 | B12: 1J520-10180-000 | C12: DIEHL AEROSPACE GMBH | D12: 25 | E12: CLEDU-CABIN LED UNIT | F12: 2 | G12: 3 | H12: 57600 | I12: 3 | J12: 1520 | K12: Airbus web 23/3/26 | L12: 1520 | M12: Airbus web 23/3/26 | N12: 1 | O12: Exclude | P12: Exclude | S12: No | T12: High BER Rate | U12: A320-FAM011 | V12: 1
A13: 374 | B13: 1J520-10260-000 | C13: DIEHL AEROSPACE GMBH | D13: 25 | E13: CLEDU-CABIN LED UNIT | F13: 2 | G13: 3 | H13: 999999 | I13: 3 | J13: 1520 | K13: Airbus web 23/3/26 | L13: 1520 | M13: Airbus web 23/3/26 | N13: 1 | O13: Exclude | P13: Exclude | S13: No | T13: High BER Rate | U13: A320-FAM012 | V13: 1
A14: 384 | B14: T900200 | C14: SAFRAN CABIN GERMANY GMBH | D14: 25 | E14: COMPACTOR-TRASH | F14: 2 | G14: 3 | H14: 11250 | I14: 1 | J14: 0 | K14: 0 | L14: 0 | M14: 0 | N14: 0 | O14: Exclude | P14: Exclude | S14: No | T14: High Removal | U14: A320-FAM013 | V14: 2
A15: 385 | B15: T900501 | C15: SAFRAN CABIN GERMANY GMBH | D15: 25 | E15: COMPACTOR-TRASH | F15: 2 | G15: 3 | H15: 11250 | I15: 1 | J15: 0 | K15: 0 | L15: 0 | M15: 0 | N15: 0 | O15: Exclude | P15: Exclude | S15: No | T15: High Removal | U15: A320-FAM013 | V15: 2
A16: 329 | B16: 22C15L120700009 | C16: BE AEROSPACE SYSTEMS GMBH | D16: 25 | E16: CONTAINER ASSY-CHEMICAL OXYGEN,TWO MASK | F16: 2 | G16: 2 | H16: 194400 | I16: 3 | J16: 1830 | K16: Airbus web 23/3/26 | L16: 1830 | M16: Airbus web 23/3/26 | N16: 1 | O16: Exclude | P16: Exclude | S16: No | T16: Typically not supported under MBH | U16: A320-FAM014 | V16: 2
A17: 340 | B17: 22C15L150700009 | C17: BE AEROSPACE SYSTEMS GMBH | D17: 25 | E17: CONTAINER ASSY-CHEMICAL OXYGEN,TWO MASK | F17: 2 | G17: 2 | H17: 390000 | I17: 4 | J17: 1830 | K17: Airbus web 23/3/26 | L17: 1830 | M17: Airbus web 23/3/26 | N17: 1 | O17: Exclude | P17: Exclude | S17: No | T17: Typically not supported under MBH | U17: A320-FAM014 | V17: 2
A18: 170 | B18: 25226-01AA | C18: NORD-MICRO GMBH & CO OHG | D18: 21 | E18: CONTROLLER-HEAT | F18: 2 | G18: 2 | H18: 60000 | I18: 2 | J18: 19370 | K18: Airbus web 23/3/26 | L18: 19370 | M18: Airbus web 23/3/26 | N18: 1 | O18: Include | P18: Include | Q18: Grp C (Others) | R18: 30 | U18: A320-FAM016 | V18: 1
A19: 391 | B19: FE459100002 | C19: RATIER-FIGEAC | D19: 27 | E19: RBPU-RUDDER AND BRAKE PEDAL UNIT,CAPT | F19: 2 | G19: 2 | H19: 37800 | I19: 1 | J19: 107810 | K19: Airbus web 23/3/26 | L19: 107810 | M19: Airbus web 23/3/26 | N19: 1 | O19: Include | P19: Include | Q19: Grp C (Others) | R19: 30 | U19: A320-FAM017 | V19: 1
A20: 392 | B20: FE459200002 | C20: RATIER-FIGEAC | D20: 27 | E20: RBPU-RUDDER AND BRAKE PEDAL UNIT,F0 | F20: 2 | G20: 2 | H20: 86400 | I20: 1 | J20: 68100 | K20: Airbus web 23/3/26 | L20: 68100 | M20: Airbus web 23/3/26 | N20: 1 | O20: Include | P20: Include | Q20: Grp C (Others) | R20: 30 | U20: A320-FAM018 | V20: 1
A21: 183 | B21: 812A0001-01 | C21: LIEBHERR-AEROSPACE LINDENBERG | D21: 27 | E21: SERVOVALVE | F21: 2 | G21: 2 | H21: 98336 | I21: 3 | J21: 14990 | K21: Airbus web 23/3/26 | L21: 14990 | M21: Airbus web 23/3/26 | N21: 1 | O21: Exclude (BTB with Liebherr) | P21: Include | Q21: Grp B (OEM) | R21: 30 | T21: Liebherr | U21: A320-FAM019 | V21: 1
A22: 227 | B22: 3863D0000-01 | C22: LIEBHERR-AEROSPACE LINDENBERG | D22: 27 | E22: TRANSDUCER,PRESSURE,FLUID-HYDRAULIC | F22: 2 | G22: 3 | H22: 152000 | I22: 6 | J22: 6130 | K22: Airbus web 23/3/26 | L22: 6130 | M22: Airbus web 23/3/26 | N22: 1 | O22: Exclude (BTB with Liebherr) | P22: Include | Q22: Grp B (OEM) | R22: 30 | T22: Liebherr | U22: A320-FAM020 | V22: 1
A23: 267 | B23: 12M0172 | C23: EATON LIMITED | D23: 28 | E23: FUEL-TRANSFER VALVE | F23: 2 | G23: 2 | H23: 210000 | I23: 2 | J23: 12770 | K23: Airbus web 23/3/26 | L23: 12770 | M23: Airbus web 23/3/26 | N23: 1 | O23: Include | P23: Include | Q23: Grp C (Others) | R23: 30 | U23: A320-FAM021 | V23: 1
A24: 305 | B24: 59127-0101 | C24: SIMMONDS PRECISION PRODUCTS INC | D24: 28 | E24: HARNESS 4S | F24: 6 | G24: 1 | H24: 117345 | I24: 1 | J24: 6230 | K24: Airbus web 23/3/26 | L24: 6230 | M24: Airbus web 23/3/26 | N24: 1 | O24: Include | P24: Include | Q24: Grp C (Others) | R24: 30 | U24: A320-FAM022 | V24: 1
A25: 306 | B25: 59128-0101 | C25: SIMMONDS PRECISION PRODUCTS INC | D25: 28 | E25: HARNESS 5S | F25: 6 | G25: 1 | H25: 117345 | I25: 1 | J25: 6230 | K25: Airbus web 23/3/26 | L25: 6230 | M25: Airbus web 23/3/26 | N25: 1 | O25: Include | P25: Include | Q25: Grp C (Others) | R25: 30 | U25: A320-FAM023 | V25: 1
A26: 343 | B26: 25K0037-1200 | C26: EATON LIMITED | D26: 28 | E26: REFUEL VALVE CANISTER | F26: 2 | G26: 2 | H26: 630882 | I26: 1 | J26: 9470 | K26: Airbus web 23/3/26 | L26: 9470 | M26: Airbus web 23/3/26 | N26: 1 | O26: Include | P26: Include | Q26: Grp C (Others) | R26: 30 | U26: A320-FAM024 | V26: 1
A27: 393 | B27: 12M0172-1100 | C27: EATON LIMITED | D27: 28 | E27: VALVE FUEL, TRANSFER | F27: 2 | G27: 2 | H27: 210000 | I27: 2 | J27: 12770 | K27: Airbus web 24/3/26 12M0172 | L27: 12770 | M27: Airbus web 24/3/26 12M0172 | N27: 1 | O27: Include | P27: Include | Q27: Grp C (Others) | R27: 30 | U27: A320-FAM025 | V27: 1
A28: 277 | B28: 12M0134-1100 | C28: EATON LIMITED | D28: 28 | E28: VALVE-LP FUEL | F28: 2 | G28: 1 | H28: 190391 | I28: 3 | J28: 6460 | K28: Airbus web 23/3/26 | L28: 6460 | M28: Airbus web 23/3/26 | N28: 1 | O28: Include | P28: Include | Q28: Grp C (Others) | R28: 30 | U28: A320-FAM026 | V28: 1
A29: 254 | B29: Z212H0009110 | C29: AIRBUS OPERATIONS GMBH | D29: 30 | E29: CONTROL UNIT | F29: 2 | G29: 3 | H29: 30000 | I29: 1 | J29: 4550 | K29: Airbus web 23/3/26 | L29: 4550 | M29: Airbus web 23/3/26 | N29: 1 | O29: Include | P29: Include | Q29: Grp C (Others) | R29: 30 | U29: A320-FAM027 | V29: 1
A30: 131 | B30: Z213H0101111 | C30: AIRBUS OPERATIONS GMBH | D30: 30 | E30: UNIT-CONTROL | F30: 2 | G30: 3 | H30: 30000 | I30: 4 | J30: 8990 | K30: Airbus web 23/3/26 | L30: 8990 | M30: Airbus web 23/3/26 | N30: 1 | O30: Include | P30: Include | Q30: Grp C (Others) | R30: 30 | U30: A320-FAM028 | V30: 1
A31: 120 | B31: C19628AD | C31: THALES AVS FRANCE SAS | D31: 31 | E31: HCU-HEAD UP COMBINIER UNIT CAPTAIN | F31: 6 | G31: 2 | H31: 86535 | I31: 1 | J31: 107200 | K31: Airbus web 23/3/26 | L31: 107200 | M31: Airbus web 23/3/26 | N31: 1 | O31: Exclude (BTB with Thales) | P31: Include | Q31: Grp B (OEM) | R31: 30 | T31: Thales | U31: A320-FAM029 | V31: 1
A32: 121 | B32: C19643AD | C32: THALES AVS FRANCE SAS | D32: 31 | E32: HCU-HEAD-UP COMBINER UNIT FIRST OFFICER | F32: 6 | G32: 2 | H32: 86535 | I32: 1 | J32: 107200 | K32: Airbus web 23/3/26 | L32: 107200 | M32: Airbus web 23/3/26 | N32: 1 | O32: Exclude (BTB with Thales) | P32: Include | Q32: Grp B (OEM) | R32: 30 | T32: Thales | U32: A320-FAM030 | V32: 1
A33: 341 | B33: 10-458301-000 | C33: SAFRAN LANDING SYSTEMS (SAS) | D33: 32 | E33: HARNESS, 1M AXLE | F33: 2 | G33: 1 | H33: 500000 | I33: 2 | J33: 5230 | K33: Airbus web 23/3/26 | L33: 5230 | M33: Airbus web 23/3/26 | N33: 1 | O33: Include | P33: Include | Q33: Grp C (Others) | R33: 30 | U33: A320-FAM031 | V33: 1
A34: 337 | B34: 10-458501-000 | C34: SAFRAN LANDING SYSTEMS (SAS) | D34: 32 | E34: HARNESS, 2M AXLE | F34: 2 | G34: 1 | H34: 500000 | I34: 2 | J34: 6540 | K34: Airbus web 23/3/26 | L34: 6540 | M34: Airbus web 23/3/26 | N34: 1 | O34: Include | P34: Include | Q34: Grp C (Others) | R34: 30 | U34: A320-FAM032 | V34: 1
A35: 296 | B35: 10-385401-001 | C35: SAFRAN LANDING SYSTEMS (SAS) | D35: 32 | E35: HARNESS-2M ELECTRICAL | F35: 2 | G35: 3 | H35: 297900 | I35: 1 | J35: 18500 | K35: Airbus web 23/3/26 | L35: 18500 | M35: Airbus web 23/3/26 | N35: 1 | O35: Include | P35: Include | Q35: Grp C (Others) | R35: 30 | U35: A320-FAM033 | V35: 1
A36: 93 | B36: 10-386001-001 | C36: SAFRAN LANDING SYSTEMS (SAS) | D36: 32 | E36: RETRACTION ACTUATOR COMPLETE | F36: 2 | G36: 1 | H36: 37500 | I36: 1 | J36: 64160 | K36: Airbus web 23/3/26 | L36: 64160 | M36: Airbus web 23/3/26 | N36: 1 | O36: Include | P36: Include | Q36: Grp C (Others) | R36: 30 | U36: A320-FAM038 | V36: 1
A37: 247 | B37: 2A522-10000-000 | C37: DIEHL AEROSPACE GMBH | D37: 33 | E37: PSU-MINI EMERGENCY POWER SUPPLY UNIT,LIGHT | F37: 2 | G37: 3 | H37: 90000 | I37: 4 | J37: 3780 | K37: Airbus web 23/3/26 | L37: 3780 | M37: Airbus web 23/3/26 | N37: 1 | O37: Include | P37: Include | Q37: Grp C (Others) | R37: 30 | U37: A320-FAM039 | V37: 1
A38: 159 | B38: 2LA456884-01 | C38: GOODRICH LIGHTING SYSTEMS GMBH | D38: 33 | F38: 2 | G38: 3 | H38: 24881 | I38: 1 | J38: 21230 | K38: Airbus web 23/3/26 | L38: 21230 | M38: Airbus web 23/3/26 | N38: 1 | O38: Include | P38: Include | Q38: Grp C (Others) | R38: 30 | U38: A320-FAM040 | V38: 1
A39: 141 | B39: 2LA456884-02 | C39: GOODRICH LIGHTING SYSTEMS GMBH | D39: 33 | F39: 2 | G39: 3 | H39: 24881 | I39: 1 | J39: 21230 | K39: Airbus web 23/3/26 | L39: 21230 | M39: Airbus web 23/3/26 | N39: 1 | O39: Include | P39: Include | Q39: Grp C (Others) | R39: 30 | U39: A320-FAM041 | V39: 1
A40: 78 | B40: 822-3150-301 | C40: ROCKWELL COLLINS INC | D40: 34 | E40: TRANSCEIVER-WEATHER RADAR | F40: 2 | G40: 2 | H40: 36000 | I40: 1 | J40: 95370 | K40: Airbus web 23/3/26 | L40: 95370 | M40: Airbus web 23/3/26 | N40: 1 | O40: Include | P40: Include | Q40: Grp C (Others) | R40: 30 | T40: Rockwell Collins | U40: A320-FAM042 | V40: 1
...

Sheet parameters
A1: Supported Fleet Statistics | F1: ESS CODE | G1: Tolerance Level
A2: Annual Flying Hours (per aircraft) | C2: see Column B in Provisioning Model tab | F2: 1 | G2: 0
A3: Total Repair Time (Including Freight) | C3: see Column J in Provisioning Model tab | F3: 2 | G3: 0
A4: CRF | B4: 0 | C4: 0-1 | F4: 3 | G4: 0
A8: Provisioning Criteria | B8: ESS | C8: Protection Level | D8: Minimum Annual Demand (MAD) | E8: Arisings TRT | F8: Actual TRT Demand | G8: Actual Fill Rate (TAT) | H8: Arisings TRT (Annual) | I8: Actual TRT Demand (Annual) | J8: Actual Fill Rate (Annual) | L8: Desired SL%
A9: Target Fill Rate % Ess 1 | B9: 1 | C9: 0.98 | D9: 0.1 | L9: 98
A10: Target Fill Rate % Ess 2 | B10: 2 | C10: 0.93 | D10: 0.1 | L10: 95
A11: Target Fill Rate % Ess 3 | B11: 3 | C11: 0.9 | D11: 0.1 | L11: 92
C12: Vary the Protection Level in Column C such that the "Actual Fill Rate" in Column G meets the Desired Service Level% in Column L
A16: PNs with #N/A output issues - record data if applicable
A17: Prt Number | B17: Selected MTBUR | C17: amended MTBUR

Sheet inhousePoolInfo
A1: To update below info MONTHLY based on latest FA report | I1: If PN is A320neo unique or B737MAX unique, do not consider famclass qty, only use Available Pool Qty by PN; Pool Qty by Famclass will include Pool Qty by FA PN, so do not double-count
E2: Mar 2026 data | K2: Mar 2026 data
A3: FA PN | B3: Famclass | C3: 1 Mar 2026 - FA Qty | D3: Available Pool Qty | E3: Highest NBV (SGD) | F3: Highest Monthly Depreciation (SGD) | I3: Available Pool Qty by Famclass | J3: Available Pool Qty | K3: Highest NBV (SGD) | L3: Highest Monthly Depreciation (SGD)
A4: 003CM00-0200 | B4: STEAS01324 | C4: 2 | D4: 1 | E4: 22542.61 | F4: 86.370133 | I4: STEAS00001 | J4: 8 | K4: 8087.62 | L4: 38.1492
A5: 003-CM-00-0200 | B5: STEAS01324 | C5: 1 | D5: 1 | E5: 24511.22 | F5: 87.85 | I5: STEAS00002 | J5: 4 | K5: 15980.86 | L5: 75.027533
A6: 003CM00-0400 | B6: STEAS01326 | C6: 1 | D6: 1 | E6: 15224.95 | F6: 72.8459 | I6: STEAS00003 | J6: 8 | K6: 15350.46 | L6: 60.197867
A7: 005RL03 | B7: STEAS00832 | C7: 2 | D7: 2 | E7: 323.08 | F7: 1.56 | I7: STEAS00004 | J7: 8 | K7: 5669.68 | L7: 30.157833
A8: 005RL05 | B8: STEAS00832 | C8: 1 | D8: 1 | E8: 15223.66 | F8: 67.07 | I8: STEAS00005 | J8: 4 | K8: 4376.66 | L8: 19.5386
A9: 0102ME2GE | B9: STEAS00415 | C9: 7 | D9: 7 | E9: 17995.16 | F9: 66.158667 | I9: STEAS00006 | J9: 20 | K9: 10650.99 | L9: 70.54
A10: 0123FA2 | B10: STEAS02237 | C10: 7 | D10: 4 | E10: 3956.76 | F10: 41.22 | I10: STEAS00008 | J10: 8 | K10: 11530.69 | L10: 62.328167
A11: 0154GL5 | B11: STEAS00418 | C11: 1 | D11: 1 | E11: 0 | F11: 0 | I11: STEAS00009 | J11: 1 | K11: 7737.16 | L11: 113.78
A12: 0154JU | B12: STEAS00975 | C12: 1 | D12: 1 | E12: 0 | F12: 0 | I12: STEAS00010 | J12: 10 | K12: 10181.36 | L12: 73.778056
A13: 0154MW-CLB | B13: STEAS06258 | C13: 2 | D13: 1 | E13: 40206.62 | F13: 134.92153 | I13: STEAS00012 | J13: 1 | K13: 3001.19 | L13: 14.024267
A14: 0154NE2 | B14: STEAS06257 | C14: 1 | D14: 1 | E14: 22468.63 | F14: 84.15 | I14: STEAS00015 | J14: 2 | K14: 0 | L14: 0
A15: 01N65900 | B15: STEAS00196 | C15: 7 | D15: 7 | E15: 1746.21 | F15: 20.0715 | I15: STEAS00016 | J15: 1 | K15: 37605.4 | L15: 139.797
... A32: 066-1093-11 | B32: STEAS02433 | C32: 1 | D32: 1 | E32: 0 | F32: 0 | I32: STEAS00034 | J32: 3 | K32: 7692.79 | L32: 36.458667
A33: 066-50000-1508 | C33: 1 | D33: 1 | E33: 0 | F33: 0 | I33: STEAS00035 | J33: 6 | K33: 22898.71 | L33: 107.00333
A34: 066-50000-2220 | B34: STEAS00113 | C34: 4 | D34: 4 | E34: 1802.1 | F34: 64.36 | I34: STEAS00036 | J34: 9 | K34: 40874.61 | L34: 158.42867
A35: 066-50000-2221 | B35: STEAS00113 | C35: 2 | D35: 1 | E35: 1588.42 | F35: 33.1 | I35: STEAS00037 | J35: 2 | K35: 1016.88 | L35: 19.55
A36: 066-50006-1202 | B36: STEAS00380 | C36: 1 | D36: 1 | E36: 0 | F36: 0 | I36: STEAS00038 | J36: 4 | K36: 5034.76 | L36: 16.838667
A37: 066-50007-0101 | B37: STEAS02438 | C37: 3 | D37: 0 | E37: 22932.52 | F37: 138.15 | I37: STEAS00040 | J37: 17 | K37: 36651.65 | L37: 349.06333
A38: 066-50007-0212 | B38: STEAS00481 | C38: 2 | D38: 2 | E38: 0 | F38: 0 | I38: STEAS00041 | J38: 6 | K38: 10076.58 | L38: 132.58
A39: 066-50007-0222 | B39: STEAS00481 | C39: 1 | D39: 1 | E39: 3044.1 | F39: 304.41 | I39: STEAS00043 | J39: 7 | K39: 274428 | L39: 1016.4
A40: 066-50007-0432 | B40: STEAS00481 | C40: 2 | D40: 2 | E40: 18767.95 | F40: 312.8 | I40: STEAS00044 | J40: 11 | K40: 2015.33 | L40: 28.79
A41: 066-50007-0531 | B41: STEAS02438 | C41: 1 | D41: 0 | E41: 11402.63 | F41: 44.89 | I41: STEAS00045 | J41: 3 | K41: 22622.93 | L41: 84.1001
A42: 066-50007-1531 | B42: STEAS01330 | C42: 4 | D42: 2 | E42: 106441.44 | F42: 403.18727 | I42: STEAS00046 | J42: 10 | K42: 4097.27 | L42: 15.1191
A43: 066-50008-0405 | B43: STEAS00483 | C43: 1 | D43: 1 | E43: 28561.13 | F43: 328.29 | I43: STEAS00047 | J43: 7 | K43: 3346.24 | L43: 39.37
A44: 066-50008-0406 | B44: STEAS00483 | C44: 3 | D44: 1 | E44: 0 | F44: 0 | I44: STEAS00048 | J44: 2 | K44: 0 | L44: 0
A45: 066-50008-0407 | B45: STEAS00483 | C45: 2 | D45: 2 | E45: 13487.18 | F45: 236.62 | I45: STEAS00049 | J45: 18 | K45: 445802.75 | L45: 1714.63
... A110: 1019439-1-001 | B110: STEAS02244 | C110: 3 | D110: 1 | E110: 55016.94 | F110: 221.84 | I110: STEAS00146 | J110: 12 | K110: 38573.61 | L110: 258.88333
A111: 1019439-2-001 | B111: STEAS02244 | C111: 1 | D111: 1 | E111: 76167.65 | F111: 337.025 | I111: STEAS00147 | J111: 0
A112: 1020420-2-114 | B112: STEAS00192 | C112: 1 | D112: 1 | E112: 1059331.2 | F112: 4996.8451 | I112: STEAS00148 | J112: 3 | K112: 76934.73 | L112: 289.22833
A113: 1020420-3-118 | B113: STEAS00192 | C113: 1 | D113: 1 | E113: 1184816.1 | F113: 4628.1879 | I113: STEAS00149 | J113: 6 | K113: 1282.96 | L113: 32.9
A114: 1020896-1 | B114: STEAS01265 | C114: 2 | D114: 2 | E114: 29471.04 | F114: 115.1212 | I114: STEAS00150 | J114: 2 | K114: 6410.33 | L114: 59.36
A115: 1020901-2 | B115: STEAS01266 | C115: 2 | D115: 1 | E115: 25082.87 | F115: 118.31543 | I115: STEAS00151 | J115: 4 | K115: 45862.62 | L115: 179.15087
A116: 1020902-1 | B116: STEAS01267 | C116: 1 | D116: 1 | E116: 5476.68 | F116: 25.712033 | I116: STEAS00154 | J116: 1 | K116: 17778.33 | L116: 67.088067
A117: 1020903-1 | B117: STEAS01268 | C117: 1 | D117: 1 | E117: 47700.02 | F117: 223.94 | I117: STEAS00155 | J117: 9 | K117: 20560.58 | L117: 147.92
A118: 1020923-1 | B118: STEAS01269 | C118: 2 | D118: 1 | E118: 99099.07 | F118: 387.10573 | I118: STEAS00156 | J118: 2 | K118: 704.78 | L118: 8.92
A119: 1020924-1 | B119: STEAS01270 | C119: 2 | D119: 1 | E119: 40012.28 | F119: 156.29803 | I119: STEAS00159 | J119: 1 | K119: 21270.34 | L119: 82.76
A120: 1020925-3 | B120: STEAS01271 | C120: 1 | D120: 1 | E120: 29430.3 | F120: 114.96207 | I120: STEAS00160 | J120: 10 | K120: 5584.72 | L120: 20.532
...

Sheet currentMbhFleet
A1: Backup Raw Data | C1: A320 | D1: A320 | E1: A320 | F1: A320 | G1: A320 | H1: A330 | I1: B787 | J1: B737 | K1: B737 | L1: B737 | M1: B737 | N1: B737 | O1: B737 | S1: vlookup & adjust data | U1: A320 | V1: A320 | W1: A320 | X1: A320 | Y1: A320 | Z1: A330 | AA1: B787 | AB1: B737 | AC1: B737 | AD1: B737 | AE1: B737 | AF1: B737 | AG1: B737 | AK1: Current MBH Fleet info (to check with Program team regularly)
S2: origin | T2: In-Service AC Count | U2: 12 | V2: 8 | W2: 17 | X2: 3 | Y2: 66 | Z2: 16 | AA2: 53 | AB2: 62 | AC2: 44 | AD2: 10 | AE2: 11 | AF2: 30 | AG2: 98
B3: In-Service AC Count | C3: 12 | D3: 8 | E3: 17 | F3: 3 | G3: 66 | H3: 16 | I3: 53 | J3: 62 | K3: 44 | L3: 10 | M3: 11 | N3: 30 | O3: 98 | S3: adjusted | T3: In-Service AC Count | U3: 12 | V3: 8 | W3: 19 | X3: 3 | Y3: 66 | Z3: 13 | AA3: 53 | AB3: 62 | AC3: 44 | AD3: 6 | AE3: 11 | AF3: 33 | AG3: 100 | AK3: Info as of 8 Dec 2025
A4: PN | B4: Commonality (to be updated) | C4: RAYA AIRWAYS A321CEO MBH | D4: TIGERAIR TAIWAN A320NEO | E4: China Airlines A321MBH | F4: JAL A321MBH | G4: Vietnam Air A321MBH VA2 | H4: China Airlines A330MBH | I4: JAL 787MBH | J4: JAL 737MBH | K4: Jeju 737Max MBH | L4: China Airlines | M4: Nok Air 737 (2025) | N4: T'way 737Max MBH | O4: Virgin Australia 737 MBH | P4: Program Count | Q4: Total AC Count | S4: PN | T4: Commonality (to be updated) | U4: RAYA AIRWAYS A321CEO MBH | V4: TIGERAIR TAIWAN A320NEO | W4: China Airlines A321MBH | X4: JAL A321MBH | Y4: Vietnam Air A321MBH VA2 | Z4: China Airlines A330MBH | AA4: JAL 787MBH | AB4: JAL 737MBH | AC4: Jeju 737Max MBH | AD4: China Airlines | AE4: Nok Air 737 (2025) | AF4: T'way 737Max MBH | AG4: Virgin Australia 737 MBH | AH4: Program Count | AI4: Total AC Count | AK4: A320 | AL4: In service | AM4: Contracted | AN4: In service | AO4: Contracted
A5: 00-5071-01 | E5: 1 | P5: 1 | S5: 00-5071-01 | U5: 0 | V5: 0 | W5: 19 | X5: 0 | Y5: 0 | Z5: 0 | AA5: 0 | AB5: 0 | AC5: 0 | AD5: 0 | AE5: 0 | AF5: 0 | AG5: 0 | AH5: 1 | AI5: 19 | AK5: Programme | AL5: CEO Fleet | AM5: CEO Fleet | AN5: NEO Fleet | AO5: NEO Fleet
A6: 005-RL-03 | G6: 1 | P6: 2 | S6: 005-RL-03 | U6: 0 | V6: 0 | W6: 0 | X6: 0 | Y6: 66 | Z6: 0 | AA6: 0 | AB6: 0 | AC6: 0 | AD6: 0 | AE6: 0 | AF6: 0 | AG6: 0 | AH6: 2 | AI6: 66 | AK6: China Airlines A321MBH | AL6: 0 | AM6: 0 | AN6: 19 | AO6: 19
A7: 005-RL-05 | C7: 1 | G7: 1 | P7: 3 | S7: 005-RL-05 | U7: 12 | V7: 0 | W7: 0 | X7: 0 | Y7: 66 | Z7: 0 | AA7: 0 | AB7: 0 | AC7: 0 | AD7: 0 | AE7: 0 | AF7: 0 | AG7: 0 | AH7: 3 | AI7: 78 | AK7: China Airlines A330MBH | AL7: 13 | AM7: 13 | AN7: 0 | AO7: 0
A8: 005-RL-05-0000 | G8: 1 | P8: 2 | S8: 005-RL-05-0000 | U8: 0 | V8: 0 | W8: 0 | X8: 0 | Y8: 66 | Z8: 0 | AA8: 0 | AB8: 0 | AC8: 0 | AD8: 0 | AE8: 0 | AF8: 0 | AG8: 0 | AH8: 2 | AI8: 66 | AK8: JAL A321MBH | AL8: 3 | AM8: 3
A9: 0102ME2GE | B9: A320-Common | D9: 1 | F9: 1 | P9: 5 | S9: 0102ME2GE | T9: A320-Common | U9: 0 | V9: 8 | W9: 0 | X9: 3 | Y9: 0 | Z9: 0 | AA9: 0 | AB9: 0 | AC9: 0 | AD9: 0 | AE9: 0 | AF9: 0 | AG9: 0 | AH9: 5 | AI9: 11 | AK9: RAYA AIRWAYS A321CEO MBH | AL9: 3 | AM9: 12 | AN9: 0 | AO9: 0
A10: 0123FA2 | B10: B737-Common | J10: 1 | K10: 1 | M10: 1 | N10: 1 | O10: 1 | P10: 5 | S10: 0123FA2 | T10: B737-Common | U10: 0 | V10: 0 | W10: 0 | X10: 0 | Y10: 0 | Z10: 0 | AA10: 0 | AB10: 62 | AC10: 44 | AD10: 0 | AE10: 11 | AF10: 33 | AG10: 100 | AH10: 5 | AI10: 250 | AK10: TIGERAIR TAIWAN A320NEO MBH | AL10: 0 | AM10: 0 | AN10: 8 | AO10: 8
A11: 0123FA2A | J11: 1 | K11: 1 | O11: 1 | P11: 3 | S11: 0123FA2A | U11: 0 | V11: 0 | W11: 0 | X11: 0 | Y11: 0 | Z11: 0 | AA11: 0 | AB11: 62 | AC11: 44 | AD11: 0 | AE11: 0 | AF11: 0 | AG11: 100 | AH11: 3 | AI11: 206 | AK11: Vietnam Air A321MBH | AL11: 43 | AM11: 43 | AN11: 23 | AO11: 23
A12: 0154JU | B12: A320-CEO | P12: 1 | S12: 0154JU | T12: A320-CEO | U12: 0 | V12: 0 | W12: 0 | X12: 0 | Y12: 0 | Z12: 0 | AA12: 0 | AB12: 0 | AC12: 0 | AD12: 0 | AE12: 0 | AF12: 0 | AG12: 0 | AH12: 1 | AI12: 0
A13: 01N65900 | B13: A320-Common | G13: 1 | K13: 1 | N13: 1 | P13: 4 | S13: 01N65900 | T13: A320-Common | U13: 0 | V13: 0 | W13: 0 | X13: 0 | Y13: 66 | Z13: 0 | AA13: 0 | AB13: 0 | AC13: 44 | AD13: 0 | AE13: 0 | AF13: 33 | AG13: 0 | AH13: 4 | AI13: 143
A14: 01N65910 | B14: B737-NG | M14: 1 | N14: 1 | P14: 2 | S14: 01N65910 | T14: B737-NG | U14: 0 | V14: 0 | W14: 0 | X14: 0 | Y14: 0 | Z14: 0 | AA14: 0 | AB14: 0 | AC14: 0 | AD14: 0 | AE14: 11 | AF14: 33 | AG14: 0 | AH14: 2 | AI14: 44 | AK14: B737 | AL14: In service | AM14: Contracted | AN14: In service | AO14: Contracted
A15: 01N65920 | B15: B787-Common | G15: 1 | N15: 1 | P15: 3 | S15: 01N65920 | T15: B787-Common | U15: 0 | V15: 0 | W15: 0 | X15: 0 | Y15: 66 | Z15: 0 | AA15: 0 | AB15: 0 | AC15: 0 | AD15: 0 | AE15: 0 | AF15: 33 | AG15: 0 | AH15: 3 | AI15: 99 | AK15: Programme | AL15: NG Fleet | AM15: NG Fleet | AN15: MAX Fleet | AO15: MAX Fleet
A16: 01N65920SKY | K16: 1 | P16: 1 | S16: 01N65920SKY | U16: 0 | V16: 0 | W16: 0 | X16: 0 | Y16: 0 | Z16: 0 | AA16: 0 | AB16: 0 | AC16: 44 | AD16: 0 | AE16: 0 | AF16: 0 | AG16: 0 | AH16: 1 | AI16: 44 | AK16: China Airlines 737 MBH | AL16: 6 | AM16: 6 | AN16: 0 | AO16: 0
A17: 0212KTU01 | P17: 2 | S17: 0212KTU01 | U17: 0 | V17: 0 | W17: 0 | X17: 0 | Y17: 0 | Z17: 0 | AA17: 0 | AB17: 0 | AC17: 0 | AD17: 0 | AE17: 0 | AF17: 0 | AG17: 0 | AH17: 2 | AI17: 0 | AK17: JAL 737MBH | AL17: 62 | AM17: 62
A18: 0212KTU03 | P18: 1 | S18: 0212KTU03 | U18: 0 | V18: 0 | W18: 0 | X18: 0 | Y18: 0 | Z18: 0 | AA18: 0 | AB18: 0 | AC18: 0 | AD18: 0 | AE18: 0 | AF18: 0 | AG18: 0 | AH18: 1 | AI18: 0 | AK18: Jeju 737Max MBH | AL18: 35 | AM18: 37 | AN18: 7 | AO18: 7
A19: 0212KTU04 | P19: 1 | S19: 0212KTU04 | U19: 0 | V19: 0 | W19: 0 | X19: 0 | Y19: 0 | Z19: 0 | AA19: 0 | AB19: 0 | AC19: 0 | AD19: 0 | AE19: 0 | AF19: 0 | AG19: 0 | AH19: 1 | AI19: 0 | AK19: Nok Air 737 (2025) MBH | AL19: 11 | AM19: 11 | AN19: 0 | AO19: 0
A20: 0212KTU05 | P20: 1 | S20: 0212KTU05 | U20: 0 | V20: 0 | W20: 0 | X20: 0 | Y20: 0 | Z20: 0 | AA20: 0 | AB20: 0 | AC20: 0 | AD20: 0 | AE20: 0 | AF20: 0 | AG20: 0 | AH20: 1 | AI20: 0 | AK20: T'way 737Max MBH | AL20: 28 | AM20: 28 | AN20: 5 | AO20: 5
A21: 0212KTU06 | P21: 1 | S21: 0212KTU06 | U21: 0 | V21: 0 | W21: 0 | X21: 0 | Y21: 0 | Z21: 0 | AA21: 0 | AB21: 0 | AC21: 0 | AD21: 0 | AE21: 0 | AF21: 0 | AG21: 0 | AH21: 1 | AI21: 0 | AK21: Virgin Australia 737 MBH | AL21: 86 | AM21: 86 | AN21: 14 | AO21: 14
A22: 0212KTU07 | P22: 1 | S22: 0212KTU07 | U22: 0 | V22: 0 | W22: 0 | X22: 0 | Y22: 0 | Z22: 0 | AA22: 0 | AB22: 0 | AC22: 0 | AD22: 0 | AE22: 0 | AF22: 0 | AG22: 0 | AH22: 1 | AI22: 0
A23: 0212KTU08 | P23: 1 | S23: 0212KTU08 | U23: 0 | V23: 0 | W23: 0 | X23: 0 | Y23: 0 | Z23: 0 | AA23: 0 | AB23: 0 | AC23: 0 | AD23: 0 | AE23: 0 | AF23: 0 | AG23: 0 | AH23: 1 | AI23: 0
A24: 0212KTU09 | P24: 2 | S24: 0212KTU09 | U24: 0 | V24: 0 | W24: 0 | X24: 0 | Y24: 0 | Z24: 0 | AA24: 0 | AB24: 0 | AC24: 0 | AD24: 0 | AE24: 0 | AF24: 0 | AG24: 0 | AH24: 2 | AI24: 0 | AK24: B787 | AL24: In service | AM24: Contracted | AN24: In service | AO24: Contracted
A25: 0212KTU10 | P25: 1 | S25: 0212KTU10 | U25: 0 | V25: 0 | W25: 0 | X25: 0 | Y25: 0 | Z25: 0 | AA25: 0 | AB25: 0 | AC25: 0 | AD25: 0 | AE25: 0 | AF25: 0 | AG25: 0 | AH25: 1 | AI25: 0 | AK25: Programme | AL25: B787-8 | AM25: B787-8 | AN25: B787-9 | AO25: B787-9
A26: 0212KTU11 | P26: 1 | S26: 0212KTU11 | U26: 0 | V26: 0 | W26: 0 | X26: 0 | Y26: 0 | Z26: 0 | AA26: 0 | AB26: 0 | AC26: 0 | AD26: 0 | AE26: 0 | AF26: 0 | AG26: 0 | AH26: 1 | AI26: 0 | AK26: JAL B787 | AL26: 22 | AM26: 22 | AN26: 31 | AO26: 31
A27: 0212KTU13 | P27: 2 | S27: 0212KTU13 | U27: 0 | V27: 0 | W27: 0 | X27: 0 | Y27: 0 | Z27: 0 | AA27: 0 | AB27: 0 | AC27: 0 | AD27: 0 | AE27: 0 | AF27: 0 | AG27: 0 | AH27: 2 | AI27: 0
A28: 0212KTU14 | P28: 1 | S28: 0212KTU14 | U28: 0 | V28: 0 | W28: 0 | X28: 0 | Y28: 0 | Z28: 0 | AA28: 0 | AB28: 0 | AC28: 0 | AD28: 0 | AE28: 0 | AF28: 0 | AG28: 0 | AH28: 1 | AI28: 0
A29: 0212KTU15 | P29: 1 | S29: 0212KTU15 | U29: 0 | V29: 0 | W29: 0 | X29: 0 | Y29: 0 | Z29: 0 | AA29: 0 | AB29: 0 | AC29: 0 | AD29: 0 | AE29: 0 | AF29: 0 | AG29: 0 | AH29: 1 | AI29: 0
A30: 0212KTU16 | P30: 2 | S30: 0212KTU16 | U30: 0 | V30: 0 | W30: 0 | X30: 0 | Y30: 0 | Z30: 0 | AA30: 0 | AB30: 0 | AC30: 0 | AD30: 0 | AE30: 0 | AF30: 0 | AG30: 0 | AH30: 2 | AI30: 0
A31: 0212KTU17 | P31: 1 | S31: 0212KTU17 | U31: 0 | V31: 0 | W31: 0 | X31: 0 | Y31: 0 | Z31: 0 | AA31: 0 | AB31: 0 | AC31: 0 | AD31: 0 | AE31: 0 | AF31: 0 | AG31: 0 | AH31: 1 | AI31: 0
A32: 024116 | B32: B737-Common | J32: 1 | P32: 1 | S32: 024116 | T32: B737-Common | U32: 0 | V32: 0 | W32: 0 | X32: 0 | Y32: 0 | Z32: 0 | AA32: 0 | AB32: 62 | AC32: 0 | AD32: 0 | AE32: 0 | AF32: 0 | AG32: 0 | AH32: 1 | AI32: 62
A33: 0270-0012-2 | B33: B787-Common | I33: 1 | P33: 1 | S33: 0270-0012-2 | T33: B787-Common | U33: 0 | V33: 0 | W33: 0 | X33: 0 | Y33: 0 | Z33: 0 | AA33: 53 | AB33: 0 | AC33: 0 | AD33: 0 | AE33: 0 | AF33: 0 | AG33: 0 | AH33: 1 | AI33: 53
A34: 0270-0014-3 | B34: B787-Common | I34: 1 | P34: 1 | S34: 0270-0014-3 | T34: B787-Common | U34: 0 | V34: 0 | W34: 0 | X34: 0 | Y34: 0 | Z34: 0 | AA34: 53 | AB34: 0 | AC34: 0 | AD34: 0 | AE34: 0 | AF34: 0 | AG34: 0 | AH34: 1 | AI34: 53
A35: 0270-0015-5 | I35: 1 | P35: 1 | S35: 0270-0015-5 | U35: 0 | V35: 0 | W35: 0 | X35: 0 | Y35: 0 | Z35: 0 | AA35: 53 | AB35: 0 | AC35: 0 | AD35: 0 | AE35: 0 | AF35: 0 | AG35: 0 | AH35: 1 | AI35: 53
A36: 0270-0016-4 | I36: 1 | P36: 1 | S36: 0270-0016-4 | U36: 0 | V36: 0 | W36: 0 | X36: 0 | Y36: 0 | Z36: 0 | AA36: 53 | AB36: 0 | AC36: 0 | AD36: 0 | AE36: 0 | AF36: 0 | AG36: 0 | AH36: 1 | AI36: 53
A37: 0600LS-04-00 | J37: 1 | P37: 1 | S37: 0600LS-04-00 | U37: 0 | V37: 0 | W37: 0 | X37: 0 | Y37: 0 | Z37: 0 | AA37: 0 | AB37: 62 | AC37: 0 | AD37: 0 | AE37: 0 | AF37: 0 | AG37: 0 | AH37: 1 | AI37: 62
A38: 06282 | G38: 1 | P38: 2 | S38: 06282 | U38: 0 | V38: 0 | W38: 0 | X38: 0 | Y38: 66 | Z38: 0 | AA38: 0 | AB38: 0 | AC38: 0 | AD38: 0 | AE38: 0 | AF38: 0 | AG38: 0 | AH38: 2 | AI38: 66
A39: 06283 | G39: 1 | P39: 2 | S39: 06283 | U39: 0 | V39: 0 | W39: 0 | X39: 0 | Y39: 66 | Z39: 0 | AA39: 0 | AB39: 0 | AC39: 0 | AD39: 0 | AE39: 0 | AF39: 0 | AG39: 0 | AH39: 2 | AI39: 66
A40: 064-50000-0110 | B40: B737-NG | K40: 1 | M40: 1 | N40: 1 | P40: 3 | S40: 064-50000-0110 | T40: B737-NG | U40: 0 | V40: 0 | W40: 0 | X40: 0 | Y40: 0 | Z40: 0 | AA40: 0 | AB40: 0 | AC40: 44 | AD40: 0 | AE40: 11 | AF40: 33 | AG40: 0 | AH40: 3 | AI40: 88
...
