Workbook

Sheet Provisioning
A1: PNR | B1: Annual FH | C1: SPC | D1: ESS | E1: QPA | F1: MTBUR for IP | G1: RRI | H1: Buy Price (USD) | I1: Aircraft Count | J1: TAT | K1: Annual Demand - Dann | L1: Expected Demand during Re-supply Time | M1: Protection Level (P.L) | N1: MAD | O1: Does part qualify as spare? | P1: Qty | Q1: Actual P.L. | R1: Deviation | S1: Calculation Status | T1: ESS1 Arising TRT | U1: ESS2 Arising TRT | V1: ESS3 Arising TRT | W1: ESS1 Actual TRT Demand | X1: ESS2 Actual TRT Demand | Y1: ESS3 Actual TRT Demand | Z1: ESS1 Arising Years | AA1: ESS2 Arising Years | AB1: ESS3 Arising Years | AC1: ESS1 Actual annual Demand | AD1: ESS2 Actual annual Demand | AE1: ESS3 Actual annual Demand
A2: AR4709-13 | B2: =VLOOKUP(A2, partNumbers!$A$1:$Z$5000, 2, FALSE) -> 4000 | C2: =VLOOKUP(A2, partCapability!$B$1:$Z$5000, 5, FALSE) -> 6 | D2: =INT(VLOOKUP(A2, partCapability!$B$1:$Z$5000, 6, FALSE)) -> 2 | E2: =VLOOKUP(A2, partCapability!$B$1:$Z$5000, 8, FALSE) -> 1 | F2: =VLOOKUP(A2, partCapability!$B$1:$Z$5000, 7, FALSE) -> 120000 | G2: =VLOOKUP(A2, partNumbers!$A$1:$Z$5000, 3, FALSE) -> 0 | H2: =VLOOKUP(A2, partNumbers!$A$1:$Z$5000, 4, FALSE) -> 19380 | I2: =VLOOKUP(A2, partNumbers!$A$1:$Z$5000, 5, FALSE) -> 126 | J2: =VLOOKUP(A2, partCapability!$B$1:$Z$5000, 17, FALSE)+11+7 -> 48 | K2: =B2*E2*I2/(F2*POWER(10,G2)) -> 4.2 | L2: =ROUND(K2*J2/365, 2) -> 0.55 | M2: =VLOOKUP(D2, parameters!$B$1:$C$8000, 2, FALSE) -> 0.93 | N2: =VLOOKUP(D2, parameters!$B$1:$D$8000, 3, FALSE) -> 0.1 | O2: =IF(L2>N2, "Yes", "No") -> Yes | P2: {=_xlfn.LET(_xlpm.lambda,L2,_xlpm.target,M2-VLOOKUP(D2,parameters!$F$1:$G$4,2,FALSE),_xlpm.n,_xlfn.SEQUENCE(100,1,0,1),INDEX(_xlpm.n,MATCH(TRUE,ROUND(POISSON(_xlpm.n,_xlpm.lambda,TRUE),2)>=_xlpm.target,0)))} -> 2 | Q2: =POISSON(P2, L2, TRUE) -> 0.98153586 | R2: =ROUND(M2-Q2, 2) -> -0.05 | S2: =IF(R2>VLOOKUP(D2, parameters!$F$1:$G$4, 2, FALSE), "Re-Calculate", "OK") -> OK | T2: =IF(D2=1, L2, " ") | U2: =IF(D2=2, L2, " ") -> 0.55 | V2: =IF(D2=3, L2, " ") | W2: =IF(D2=1, L2*Q2, " ") | X2: =IF(D2=2, L2*Q2, " ") -> 0.53984473 | Y2: =IF(D2=3, L2*Q2, " ") | Z2: =IF(D2=1, K2, " ") | AA2: =IF(D2=2, K2, " ") -> 4.2 | AB2: =IF(D2=3, K2, " ") | AC2: =IF(D2=1, K2*Q2, " ") | AD2: =IF(D2=2, K2*Q2, " ") -> 4.1224506 | AE2: =IF(D2=3, K2*Q2, " ")
A3: AR4714-11 | B3: =VLOOKUP(A3, partNumbers!$A$1:$Z$5000, 2, FALSE) -> 4000 | C3: =VLOOKUP(A3, partCapability!$B$1:$Z$5000, 5, FALSE) -> 2 | D3: =INT(VLOOKUP(A3, partCapability!$B$1:$Z$5000, 6, FALSE)) -> 2 | E3: =VLOOKUP(A3, partCapability!$B$1:$Z$5000, 8, FALSE) -> 1 | F3: =VLOOKUP(A3, partCapability!$B$1:$Z$5000, 7, FALSE) -> 120000 | G3: =VLOOKUP(A3, partNumbers!$A$1:$Z$5000, 3, FALSE) -> 0 | H3: =VLOOKUP(A3, partNumbers!$A$1:$Z$5000, 4, FALSE) -> 5877.3333 | I3: =VLOOKUP(A3, partNumbers!$A$1:$Z$5000, 5, FALSE) -> 165 | J3: =VLOOKUP(A3, partCapability!$B$1:$Z$5000, 17, FALSE)+11+7 -> 48 | K3: =B3*E3*I3/(F3*POWER(10,G3)) -> 5.5 | L3: =ROUND(K3*J3/365, 2) -> 0.72 | M3: =VLOOKUP(D3, parameters!$B$1:$C$8000, 2, FALSE) -> 0.93 | N3: =VLOOKUP(D3, parameters!$B$1:$D$8000, 3, FALSE) -> 0.1 | O3: =IF(L3>N3, "Yes", "No") -> Yes | P3: {=_xlfn.LET(_xlpm.lambda,L3,_xlpm.target,M3-VLOOKUP(D3,parameters!$F$1:$G$4,2,FALSE),_xlpm.n,_xlfn.SEQUENCE(100,1,0,1),INDEX(_xlpm.n,MATCH(TRUE,ROUND(POISSON(_xlpm.n,_xlpm.lambda,TRUE),2)>=_xlpm.target,0)))} -> 2 | Q3: =POISSON(P3, L3, TRUE) -> 0.96338006 | R3: =ROUND(M3-Q3, 2) -> -0.03 | S3: =IF(R3>VLOOKUP(D3, parameters!$F$1:$G$4, 2, FALSE), "Re-Calculate", "OK") -> OK | T3: =IF(D3=1, L3, " ") | U3: =IF(D3=2, L3, " ") -> 0.72 | V3: =IF(D3=3, L3, " ") | W3: =IF(D3=1, L3*Q3, " ") | X3: =IF(D3=2, L3*Q3, " ") -> 0.69363365 | Y3: =IF(D3=3, L3*Q3, " ") | Z3: =IF(D3=1, K3, " ") | AA3: =IF(D3=2, K3, " ") -> 5.5 | AB3: =IF(D3=3, K3, " ") | AC3: =IF(D3=1, K3*Q3, " ") | AD3: =IF(D3=2, K3*Q3, " ") -> 5.2985904 | AE3: =IF(D3=3, K3*Q3, " ")
A4: AR4714-7 | B4: =VLOOKUP(A4, partNumbers!$A$1:$Z$5000, 2, FALSE) -> 4000 | C4: =VLOOKUP(A4, partCapability!$B$1:$Z$5000, 5, FALSE) -> 2 | D4: =INT(VLOOKUP(A4, partCapability!$B$1:$Z$5000, 6, FALSE)) -> 2 | E4: =VLOOKUP(A4, partCapability!$B$1:$Z$5000, 8, FALSE) -> 2 | F4: =VLOOKUP(A4, partCapability!$B$1:$Z$5000, 7, FALSE) -> 120000 | G4: =VLOOKUP(A4, partNumbers!$A$1:$Z$5000, 3, FALSE) -> 0 | H4: =VLOOKUP(A4, partNumbers!$A$1:$Z$5000, 4, FALSE) -> 6100 | I4: =VLOOKUP(A4, partNumbers!$A$1:$Z$5000, 5, FALSE) -> 165 | J4: =VLOOKUP(A4, partCapability!$B$1:$Z$5000, 17, FALSE)+11+7 -> 39 | K4: =B4*E4*I4/(F4*POWER(10,G4)) -> 11 | L4: =ROUND(K4*J4/365, 2) -> 1.18 | M4: =VLOOKUP(D4, parameters!$B$1:$C$8000, 2, FALSE) -> 0.93 | N4: =VLOOKUP(D4, parameters!$B$1:$D$8000, 3, FALSE) -> 0.1 | O4: =IF(L4>N4, "Yes", "No") -> Yes | P4: {=_xlfn.LET(_xlpm.lambda,L4,_xlpm.target,M4-VLOOKUP(D4,parameters!$F$1:$G$4,2,FALSE),_xlpm.n,_xlfn.SEQUENCE(100,1,0,1),INDEX(_xlpm.n,MATCH(TRUE,ROUND(POISSON(_xlpm.n,_xlpm.lambda,TRUE),2)>=_xlpm.target,0)))} -> 3 | Q4: =POISSON(P4, L4, TRUE) -> 0.96793991 | R4: =ROUND(M4-Q4, 2) -> -0.04 | S4: =IF(R4>VLOOKUP(D4, parameters!$F$1:$G$4, 2, FALSE), "Re-Calculate", "OK") -> OK | T4: =IF(D4=1, L4, " ") | U4: =IF(D4=2, L4, " ") -> 1.18 | V4: =IF(D4=3, L4, " ") | W4: =IF(D4=1, L4*Q4, " ") | X4: =IF(D4=2, L4*Q4, " ") -> 1.1421691 | Y4: =IF(D4=3, L4*Q4, " ") | Z4: =IF(D4=1, K4, " ") | AA4: =IF(D4=2, K4, " ") -> 11 | AB4: =IF(D4=3, K4, " ") | AC4: =IF(D4=1, K4*Q4, " ") | AD4: =IF(D4=2, K4*Q4, " ") -> 10.647339 | AE4: =IF(D4=3, K4*Q4, " ")
A5: AR90122-5D605 | B5: =VLOOKUP(A5, partNumbers!$A$1:$Z$5000, 2, FALSE) -> 4000 | C5: =VLOOKUP(A5, partCapability!$B$1:$Z$5000, 5, FALSE) -> 2 | D5: =INT(VLOOKUP(A5, partCapability!$B$1:$Z$5000, 6, FALSE)) -> 3 | E5: =VLOOKUP(A5, partCapability!$B$1:$Z$5000, 8, FALSE) -> 4 | F5: =VLOOKUP(A5, partCapability!$B$1:$Z$5000, 7, FALSE) -> 75600 | G5: =VLOOKUP(A5, partNumbers!$A$1:$Z$5000, 3, FALSE) -> 0 | H5: =VLOOKUP(A5, partNumbers!$A$1:$Z$5000, 4, FALSE) -> 117680 | I5: =VLOOKUP(A5, partNumbers!$A$1:$Z$5000, 5, FALSE) -> 60 | J5: =VLOOKUP(A5, partCapability!$B$1:$Z$5000, 17, FALSE)+11+7 -> 48 | K5: =B5*E5*I5/(F5*POWER(10,G5)) -> 12.698413 | L5: =ROUND(K5*J5/365, 2) -> 1.67 | M5: =VLOOKUP(D5, parameters!$B$1:$C$8000, 2, FALSE) -> 0.9 | N5: =VLOOKUP(D5, parameters!$B$1:$D$8000, 3, FALSE) -> 0.1 | O5: =IF(L5>N5, "Yes", "No") -> Yes | P5: {=_xlfn.LET(_xlpm.lambda,L5,_xlpm.target,M5-VLOOKUP(D5,parameters!$F$1:$G$4,2,FALSE),_xlpm.n,_xlfn.SEQUENCE(100,1,0,1),INDEX(_xlpm.n,MATCH(TRUE,ROUND(POISSON(_xlpm.n,_xlpm.lambda,TRUE),2)>=_xlpm.target,0)))} -> 3 | Q5: =POISSON(P5, L5, TRUE) -> 0.91124641 | R5: =ROUND(M5-Q5, 2) -> -0.01 | S5: =IF(R5>VLOOKUP(D5, parameters!$F$1:$G$4, 2, FALSE), "Re-Calculate", "OK") -> OK | T5: =IF(D5=1, L5, " ") | U5: =IF(D5=2, L5, " ") | V5: =IF(D5=3, L5, " ") -> 1.67 | W5: =IF(D5=1, L5*Q5, " ") | X5: =IF(D5=2, L5*Q5, " ") | Y5: =IF(D5=3, L5*Q5, " ") -> 1.5217815 | Z5: =IF(D5=1, K5, " ") | AA5: =IF(D5=2, K5, " ") | AB5: =IF(D5=3, K5, " ") -> 12.698413 | AC5: =IF(D5=1, K5*Q5, " ") | AD5: =IF(D5=2, K5*Q5, " ") | AE5: =IF(D5=3, K5*Q5, " ") -> 11.571383
A6: Z014H010035C | B6: =VLOOKUP(A6, partNumbers!$A$1:$Z$5000, 2, FALSE) -> 4000 | C6: =VLOOKUP(A6, partCapability!$B$1:$Z$5000, 5, FALSE) -> 2 | D6: =INT(VLOOKUP(A6, partCapability!$B$1:$Z$5000, 6, FALSE)) -> 2 | E6: =VLOOKUP(A6, partCapability!$B$1:$Z$5000, 8, FALSE) -> 2 | F6: =VLOOKUP(A6, partCapability!$B$1:$Z$5000, 7, FALSE) -> 7500 | G6: =VLOOKUP(A6, partNumbers!$A$1:$Z$5000, 3, FALSE) -> 0 | H6: =VLOOKUP(A6, partNumbers!$A$1:$Z$5000, 4, FALSE) -> 140502.45 | I6: =VLOOKUP(A6, partNumbers!$A$1:$Z$5000, 5, FALSE) -> 126 | J6: =VLOOKUP(A6, partCapability!$B$1:$Z$5000, 17, FALSE)+11+7 -> 48 | K6: =B6*E6*I6/(F6*POWER(10,G6)) -> 134.4 | L6: =ROUND(K6*J6/365, 2) -> 17.67 | M6: =VLOOKUP(D6, parameters!$B$1:$C$8000, 2, FALSE) -> 0.93 | N6: =VLOOKUP(D6, parameters!$B$1:$D$8000, 3, FALSE) -> 0.1 | O6: =IF(L6>N6, "Yes", "No") -> Yes | P6: {=_xlfn.LET(_xlpm.lambda,L6,_xlpm.target,M6-VLOOKUP(D6,parameters!$F$1:$G$4,2,FALSE),_xlpm.n,_xlfn.SEQUENCE(100,1,0,1),INDEX(_xlpm.n,MATCH(TRUE,ROUND(POISSON(_xlpm.n,_xlpm.lambda,TRUE),2)>=_xlpm.target,0)))} -> 24 | Q6: =POISSON(P6, L6, TRUE) -> 0.94199177 | R6: =ROUND(M6-Q6, 2) -> -0.01 | S6: =IF(R6>VLOOKUP(D6, parameters!$F$1:$G$4, 2, FALSE), "Re-Calculate", "OK") -> OK | T6: =IF(D6=1, L6, " ") | U6: =IF(D6=2, L6, " ") -> 17.67 | V6: =IF(D6=3, L6, " ") | W6: =IF(D6=1, L6*Q6, " ") | X6: =IF(D6=2, L6*Q6, " ") -> 16.644994 | Y6: =IF(D6=3, L6*Q6, " ") | Z6: =IF(D6=1, K6, " ") | AA6: =IF(D6=2, K6, " ") -> 134.4 | AB6: =IF(D6=3, K6, " ") | AC6: =IF(D6=1, K6*Q6, " ") | AD6: =IF(D6=2, K6*Q6, " ") -> 126.60369 | AE6: =IF(D6=3, K6*Q6, " ")
A7: Z043H0101110 | B7: =VLOOKUP(A7, partNumbers!$A$1:$Z$5000, 2, FALSE) -> 4000 | C7: =VLOOKUP(A7, partCapability!$B$1:$Z$5000, 5, FALSE) -> 2 | D7: =INT(VLOOKUP(A7, partCapability!$B$1:$Z$5000, 6, FALSE)) -> 2 | E7: =VLOOKUP(A7, partCapability!$B$1:$Z$5000, 8, FALSE) -> 5 | F7: =VLOOKUP(A7, partCapability!$B$1:$Z$5000, 7, FALSE) -> 30000 | G7: =VLOOKUP(A7, partNumbers!$A$1:$Z$5000, 3, FALSE) -> 0 | H7: =VLOOKUP(A7, partNumbers!$A$1:$Z$5000, 4, FALSE) -> 7441.22 | I7: =VLOOKUP(A7, partNumbers!$A$1:$Z$5000, 5, FALSE) -> 60 | J7: =VLOOKUP(A7, partCapability!$B$1:$Z$5000, 17, FALSE)+11+7 -> 48 | K7: =B7*E7*I7/(F7*POWER(10,G7)) -> 40 | L7: =ROUND(K7*J7/365, 2) -> 5.26 | M7: =VLOOKUP(D7, parameters!$B$1:$C$8000, 2, FALSE) -> 0.93 | N7: =VLOOKUP(D7, parameters!$B$1:$D$8000, 3, FALSE) -> 0.1 | O7: =IF(L7>N7, "Yes", "No") -> Yes | P7: {=_xlfn.LET(_xlpm.lambda,L7,_xlpm.target,M7-VLOOKUP(D7,parameters!$F$1:$G$4,2,FALSE),_xlpm.n,_xlfn.SEQUENCE(100,1,0,1),INDEX(_xlpm.n,MATCH(TRUE,ROUND(POISSON(_xlpm.n,_xlpm.lambda,TRUE),2)>=_xlpm.target,0)))} -> 9 | Q7: =POISSON(P7, L7, TRUE) -> 0.95773403 | R7: =ROUND(M7-Q7, 2) -> -0.03 | S7: =IF(R7>VLOOKUP(D7, parameters!$F$1:$G$4, 2, FALSE), "Re-Calculate", "OK") -> OK | T7: =IF(D7=1, L7, " ") | U7: =IF(D7=2, L7, " ") -> 5.26 | V7: =IF(D7=3, L7, " ") | W7: =IF(D7=1, L7*Q7, " ") | X7: =IF(D7=2, L7*Q7, " ") -> 5.037681 | Y7: =IF(D7=3, L7*Q7, " ") | Z7: =IF(D7=1, K7, " ") | AA7: =IF(D7=2, K7, " ") -> 40 | AB7: =IF(D7=3, K7, " ") | AC7: =IF(D7=1, K7*Q7, " ") | AD7: =IF(D7=2, K7*Q7, " ") -> 38.309361 | AE7: =IF(D7=3, K7*Q7, " ")
A8: Z111H0040131 | B8: =VLOOKUP(A8, partNumbers!$A$1:$Z$5000, 2, FALSE) -> 4000 | C8: =VLOOKUP(A8, partCapability!$B$1:$Z$5000, 5, FALSE) -> 2 | D8: =INT(VLOOKUP(A8, partCapability!$B$1:$Z$5000, 6, FALSE)) -> 3 | E8: =VLOOKUP(A8, partCapability!$B$1:$Z$5000, 8, FALSE) -> 4 | F8: =VLOOKUP(A8, partCapability!$B$1:$Z$5000, 7, FALSE) -> 15000 | G8: =VLOOKUP(A8, partNumbers!$A$1:$Z$5000, 3, FALSE) -> 0 | H8: =VLOOKUP(A8, partNumbers!$A$1:$Z$5000, 4, FALSE) -> 8029.07 | I8: =VLOOKUP(A8, partNumbers!$A$1:$Z$5000, 5, FALSE) -> 60 | J8: =VLOOKUP(A8, partCapability!$B$1:$Z$5000, 17, FALSE)+11+7 -> 48 | K8: =B8*E8*I8/(F8*POWER(10,G8)) -> 64 | L8: =ROUND(K8*J8/365, 2) -> 8.42 | M8: =VLOOKUP(D8, parameters!$B$1:$C$8000, 2, FALSE) -> 0.9 | N8: =VLOOKUP(D8, parameters!$B$1:$D$8000, 3, FALSE) -> 0.1 | O8: =IF(L8>N8, "Yes", "No") -> Yes | P8: {=_xlfn.LET(_xlpm.lambda,L8,_xlpm.target,M8-VLOOKUP(D8,parameters!$F$1:$G$4,2,FALSE),_xlpm.n,_xlfn.SEQUENCE(100,1,0,1),INDEX(_xlpm.n,MATCH(TRUE,ROUND(POISSON(_xlpm.n,_xlpm.lambda,TRUE),2)>=_xlpm.target,0)))} -> 12 | Q8: =POISSON(P8, L8, TRUE) -> 0.91383701 | R8: =ROUND(M8-Q8, 2) -> -0.01 | S8: =IF(R8>VLOOKUP(D8, parameters!$F$1:$G$4, 2, FALSE), "Re-Calculate", "OK") -> OK | T8: =IF(D8=1, L8, " ") | U8: =IF(D8=2, L8, " ") | V8: =IF(D8=3, L8, " ") -> 8.42 | W8: =IF(D8=1, L8*Q8, " ") | X8: =IF(D8=2, L8*Q8, " ") | Y8: =IF(D8=3, L8*Q8, " ") -> 7.6945076 | Z8: =IF(D8=1, K8, " ") | AA8: =IF(D8=2, K8, " ") | AB8: =IF(D8=3, K8, " ") -> 64 | AC8: =IF(D8=1, K8*Q8, " ") | AD8: =IF(D8=2, K8*Q8, " ") | AE8: =IF(D8=3, K8*Q8, " ") -> 58.485569
A9: Z145HA452120 | B9: =VLOOKUP(A9, partNumbers!$A$1:$Z$5000, 2, FALSE) -> 4000 | C9: =VLOOKUP(A9, partCapability!$B$1:$Z$5000, 5, FALSE) -> 2 | D9: =INT(VLOOKUP(A9, partCapability!$B$1:$Z$5000, 6, FALSE)) -> 2 | E9: =VLOOKUP(A9, partCapability!$B$1:$Z$5000, 8, FALSE) -> 1 | F9: =VLOOKUP(A9, partCapability!$B$1:$Z$5000, 7, FALSE) -> 11250 | G9: =VLOOKUP(A9, partNumbers!$A$1:$Z$5000, 3, FALSE) -> 0 | H9: =VLOOKUP(A9, partNumbers!$A$1:$Z$5000, 4, FALSE) -> 76480 | I9: =VLOOKUP(A9, partNumbers!$A$1:$Z$5000, 5, FALSE) -> 60 | J9: =VLOOKUP(A9, partCapability!$B$1:$Z$5000, 17, FALSE)+11+7 -> 48 | K9: =B9*E9*I9/(F9*POWER(10,G9)) -> 21.333333 | L9: =ROUND(K9*J9/365, 2) -> 2.81 | M9: =VLOOKUP(D9, parameters!$B$1:$C$8000, 2, FALSE) -> 0.93 | N9: =VLOOKUP(D9, parameters!$B$1:$D$8000, 3, FALSE) -> 0.1 | O9: =IF(L9>N9, "Yes", "No") -> Yes | P9: {=_xlfn.LET(_xlpm.lambda,L9,_xlpm.target,M9-VLOOKUP(D9,parameters!$F$1:$G$4,2,FALSE),_xlpm.n,_xlfn.SEQUENCE(100,1,0,1),INDEX(_xlpm.n,MATCH(TRUE,ROUND(POISSON(_xlpm.n,_xlpm.lambda,TRUE),2)>=_xlpm.target,0)))} -> 5 | Q9: =POISSON(P9, L9, TRUE) -> 0.93401412 | R9: =ROUND(M9-Q9, 2) -> 0 | S9: =IF(R9>VLOOKUP(D9, parameters!$F$1:$G$4, 2, FALSE), "Re-Calculate", "OK") -> OK | T9: =IF(D9=1, L9, " ") | U9: =IF(D9=2, L9, " ") -> 2.81 | V9: =IF(D9=3, L9, " ") | W9: =IF(D9=1, L9*Q9, " ") | X9: =IF(D9=2, L9*Q9, " ") -> 2.6245797 | Y9: =IF(D9=3, L9*Q9, " ") | Z9: =IF(D9=1, K9, " ") | AA9: =IF(D9=2, K9, " ") -> 21.333333 | AB9: =IF(D9=3, K9, " ") | AC9: =IF(D9=1, K9*Q9, " ") | AD9: =IF(D9=2, K9*Q9, " ") -> 19.925635 | AE9: =IF(D9=3, K9*Q9, " ")
A10: Z212H0001110 | B10: =VLOOKUP(A10, partNumbers!$A$1:$Z$5000, 2, FALSE) -> 4000 | C10: =VLOOKUP(A10, partCapability!$B$1:$Z$5000, 5, FALSE) -> 2 | D10: =INT(VLOOKUP(A10, partCapability!$B$1:$Z$5000, 6, FALSE)) -> 3 | E10: =VLOOKUP(A10, partCapability!$B$1:$Z$5000, 8, FALSE) -> 9 | F10: =VLOOKUP(A10, partCapability!$B$1:$Z$5000, 7, FALSE) -> 30000 | G10: =VLOOKUP(A10, partNumbers!$A$1:$Z$5000, 3, FALSE) -> 0 | H10: =VLOOKUP(A10, partNumbers!$A$1:$Z$5000, 4, FALSE) -> 2968.04 | I10: =VLOOKUP(A10, partNumbers!$A$1:$Z$5000, 5, FALSE) -> 149 | J10: =VLOOKUP(A10, partCapability!$B$1:$Z$5000, 17, FALSE)+11+7 -> 48 | K10: =B10*E10*I10/(F10*POWER(10,G10)) -> 178.8 | L10: =ROUND(K10*J10/365, 2) -> 23.51 | M10: =VLOOKUP(D10, parameters!$B$1:$C$8000, 2, FALSE) -> 0.9 | N10: =VLOOKUP(D10, parameters!$B$1:$D$8000, 3, FALSE) -> 0.1 | O10: =IF(L10>N10, "Yes", "No") -> Yes | P10: {=_xlfn.LET(_xlpm.lambda,L10,_xlpm.target,M10-VLOOKUP(D10,parameters!$F$1:$G$4,2,FALSE),_xlpm.n,_xlfn.SEQUENCE(100,1,0,1),INDEX(_xlpm.n,MATCH(TRUE,ROUND(POISSON(_xlpm.n,_xlpm.lambda,TRUE),2)>=_xlpm.target,0)))} -> 30 | Q10: =POISSON(P10, L10, TRUE) -> 0.92084677 | R10: =ROUND(M10-Q10, 2) -> -0.02 | S10: =IF(R10>VLOOKUP(D10, parameters!$F$1:$G$4, 2, FALSE), "Re-Calculate", "OK") -> OK | T10: =IF(D10=1, L10, " ") | U10: =IF(D10=2, L10, " ") | V10: =IF(D10=3, L10, " ") -> 23.51 | W10: =IF(D10=1, L10*Q10, " ") | X10: =IF(D10=2, L10*Q10, " ") | Y10: =IF(D10=3, L10*Q10, " ") -> 21.649108 | Z10: =IF(D10=1, K10, " ") | AA10: =IF(D10=2, K10, " ") | AB10: =IF(D10=3, K10, " ") -> 178.8 | AC10: =IF(D10=1, K10*Q10, " ") | AD10: =IF(D10=2, K10*Q10, " ") | AE10: =IF(D10=3, K10*Q10, " ") -> 164.6474
A11: Z212H0009110 | B11: =VLOOKUP(A11, partNumbers!$A$1:$Z$5000, 2, FALSE) -> 4000 | C11: =VLOOKUP(A11, partCapability!$B$1:$Z$5000, 5, FALSE) -> 2 | D11: =INT(VLOOKUP(A11, partCapability!$B$1:$Z$5000, 6, FALSE)) -> 3 | E11: =VLOOKUP(A11, partCapability!$B$1:$Z$5000, 8, FALSE) -> 1 | F11: =VLOOKUP(A11, partCapability!$B$1:$Z$5000, 7, FALSE) -> 30000 | G11: =VLOOKUP(A11, partNumbers!$A$1:$Z$5000, 3, FALSE) -> 0 | H11: =VLOOKUP(A11, partNumbers!$A$1:$Z$5000, 4, FALSE) -> 4550 | I11: =VLOOKUP(A11, partNumbers!$A$1:$Z$5000, 5, FALSE) -> 60 | J11: =VLOOKUP(A11, partCapability!$B$1:$Z$5000, 17, FALSE)+11+7 -> 48 | K11: =B11*E11*I11/(F11*POWER(10,G11)) -> 8 | L11: =ROUND(K11*J11/365, 2) -> 1.05 | M11: =VLOOKUP(D11, parameters!$B$1:$C$8000, 2, FALSE) -> 0.9 | N11: =VLOOKUP(D11, parameters!$B$1:$D$8000, 3, FALSE) -> 0.1 | O11: =IF(L11>N11, "Yes", "No") -> Yes | P11: {=_xlfn.LET(_xlpm.lambda,L11,_xlpm.target,M11-VLOOKUP(D11,parameters!$F$1:$G$4,2,FALSE),_xlpm.n,_xlfn.SEQUENCE(100,1,0,1),INDEX(_xlpm.n,MATCH(TRUE,ROUND(POISSON(_xlpm.n,_xlpm.lambda,TRUE),2)>=_xlpm.target,0)))} -> 2 | Q11: =POISSON(P11, L11, TRUE) -> 0.91027557 | R11: =ROUND(M11-Q11, 2) -> -0.01 | S11: =IF(R11>VLOOKUP(D11, parameters!$F$1:$G$4, 2, FALSE), "Re-Calculate", "OK") -> OK | T11: =IF(D11=1, L11, " ") | U11: =IF(D11=2, L11, " ") | V11: =IF(D11=3, L11, " ") -> 1.05 | W11: =IF(D11=1, L11*Q11, " ") | X11: =IF(D11=2, L11*Q11, " ") | Y11: =IF(D11=3, L11*Q11, " ") -> 0.95578935 | Z11: =IF(D11=1, K11, " ") | AA11: =IF(D11=2, K11, " ") | AB11: =IF(D11=3, K11, " ") -> 8 | AC11: =IF(D11=1, K11*Q11, " ") | AD11: =IF(D11=2, K11*Q11, " ") | AE11: =IF(D11=3, K11*Q11, " ") -> 7.2822046
A12: Z213H0101111 | B12: =VLOOKUP(A12, partNumbers!$A$1:$Z$5000, 2, FALSE) -> 4000 | C12: =VLOOKUP(A12, partCapability!$B$1:$Z$5000, 5, FALSE) -> 2 | D12: =INT(VLOOKUP(A12, partCapability!$B$1:$Z$5000, 6, FALSE)) -> 3 | E12: =VLOOKUP(A12, partCapability!$B$1:$Z$5000, 8, FALSE) -> 4 | F12: =VLOOKUP(A12, partCapability!$B$1:$Z$5000, 7, FALSE) -> 30000 | G12: =VLOOKUP(A12, partNumbers!$A$1:$Z$5000, 3, FALSE) -> 0 | H12: =VLOOKUP(A12, partNumbers!$A$1:$Z$5000, 4, FALSE) -> 8990 | I12: =VLOOKUP(A12, partNumbers!$A$1:$Z$5000, 5, FALSE) -> 60 | J12: =VLOOKUP(A12, partCapability!$B$1:$Z$5000, 17, FALSE)+11+7 -> 48 | K12: =B12*E12*I12/(F12*POWER(10,G12)) -> 32 | L12: =ROUND(K12*J12/365, 2) -> 4.21 | M12: =VLOOKUP(D12, parameters!$B$1:$C$8000, 2, FALSE) -> 0.9 | N12: =VLOOKUP(D12, parameters!$B$1:$D$8000, 3, FALSE) -> 0.1 | O12: =IF(L12>N12, "Yes", "No") -> Yes | P12: {=_xlfn.LET(_xlpm.lambda,L12,_xlpm.target,M12-VLOOKUP(D12,parameters!$F$1:$G$4,2,FALSE),_xlpm.n,_xlfn.SEQUENCE(100,1,0,1),INDEX(_xlpm.n,MATCH(TRUE,ROUND(POISSON(_xlpm.n,_xlpm.lambda,TRUE),2)>=_xlpm.target,0)))} -> 7 | Q12: =POISSON(P12, L12, TRUE) -> 0.93536845 | R12: =ROUND(M12-Q12, 2) -> -0.04 | S12: =IF(R12>VLOOKUP(D12, parameters!$F$1:$G$4, 2, FALSE), "Re-Calculate", "OK") -> OK | T12: =IF(D12=1, L12, " ") | U12: =IF(D12=2, L12, " ") | V12: =IF(D12=3, L12, " ") -> 4.21 | W12: =IF(D12=1, L12*Q12, " ") | X12: =IF(D12=2, L12*Q12, " ") | Y12: =IF(D12=3, L12*Q12, " ") -> 3.9379012 | Z12: =IF(D12=1, K12, " ") | AA12: =IF(D12=2, K12, " ") | AB12: =IF(D12=3, K12, " ") -> 32 | AC12: =IF(D12=1, K12*Q12, " ") | AD12: =IF(D12=2, K12*Q12, " ") | AE12: =IF(D12=3, K12*Q12, " ") -> 29.93179
A13: Z233H0000110 | B13: =VLOOKUP(A13, partNumbers!$A$1:$Z$5000, 2, FALSE) -> 4000 | C13: =VLOOKUP(A13, partCapability!$B$1:$Z$5000, 5, FALSE) -> 2 | D13: =INT(VLOOKUP(A13, partCapability!$B$1:$Z$5000, 6, FALSE)) -> 3 | E13: =VLOOKUP(A13, partCapability!$B$1:$Z$5000, 8, FALSE) -> 18 | F13: =VLOOKUP(A13, partCapability!$B$1:$Z$5000, 7, FALSE) -> 75000 | G13: =VLOOKUP(A13, partNumbers!$A$1:$Z$5000, 3, FALSE) -> 0 | H13: =VLOOKUP(A13, partNumbers!$A$1:$Z$5000, 4, FALSE) -> 1124.21 | I13: =VLOOKUP(A13, partNumbers!$A$1:$Z$5000, 5, FALSE) -> 126 | J13: =VLOOKUP(A13, partCapability!$B$1:$Z$5000, 17, FALSE)+11+7 -> 48 | K13: =B13*E13*I13/(F13*POWER(10,G13)) -> 120.96 | L13: =ROUND(K13*J13/365, 2) -> 15.91 | M13: =VLOOKUP(D13, parameters!$B$1:$C$8000, 2, FALSE) -> 0.9 | N13: =VLOOKUP(D13, parameters!$B$1:$D$8000, 3, FALSE) -> 0.1 | O13: =IF(L13>N13, "Yes", "No") -> Yes | P13: {=_xlfn.LET(_xlpm.lambda,L13,_xlpm.target,M13-VLOOKUP(D13,parameters!$F$1:$G$4,2,FALSE),_xlpm.n,_xlfn.SEQUENCE(100,1,0,1),INDEX(_xlpm.n,MATCH(TRUE,ROUND(POISSON(_xlpm.n,_xlpm.lambda,TRUE),2)>=_xlpm.target,0)))} -> 21 | Q13: =POISSON(P13, L13, TRUE) -> 0.91455402 | R13: =ROUND(M13-Q13, 2) -> -0.01 | S13: =IF(R13>VLOOKUP(D13, parameters!$F$1:$G$4, 2, FALSE), "Re-Calculate", "OK") -> OK | T13: =IF(D13=1, L13, " ") | U13: =IF(D13=2, L13, " ") | V13: =IF(D13=3, L13, " ") -> 15.91 | W13: =IF(D13=1, L13*Q13, " ") | X13: =IF(D13=2, L13*Q13, " ") | Y13: =IF(D13=3, L13*Q13, " ") -> 14.550554 | Z13: =IF(D13=1, K13, " ") | AA13: =IF(D13=2, K13, " ") | AB13: =IF(D13=3, K13, " ") -> 120.96 | AC13: =IF(D13=1, K13*Q13, " ") | AD13: =IF(D13=2, K13*Q13, " ") | AE13: =IF(D13=3, K13*Q13, " ") -> 110.62445
... A282: RCF6717 | B282: =VLOOKUP(A282, partNumbers!$A$1:$Z$5000, 2, FALSE) -> 4000 | C282: =VLOOKUP(A282, partCapability!$B$1:$Z$5000, 5, FALSE) -> 2 | D282: =INT(VLOOKUP(A282, partCapability!$B$1:$Z$5000, 6, FALSE)) -> 1 | E282: =VLOOKUP(A282, partCapability!$B$1:$Z$5000, 8, FALSE) -> 2 | F282: =VLOOKUP(A282, partCapability!$B$1:$Z$5000, 7, FALSE) -> 18750 | G282: =VLOOKUP(A282, partNumbers!$A$1:$Z$5000, 3, FALSE) -> 0 | H282: =VLOOKUP(A282, partNumbers!$A$1:$Z$5000, 4, FALSE) -> 9474.51 | I282: =VLOOKUP(A282, partNumbers!$A$1:$Z$5000, 5, FALSE) -> 153 | J282: =VLOOKUP(A282, partCapability!$B$1:$Z$5000, 17, FALSE)+11+7 -> 32 | K282: =B282*E282*I282/(F282*POWER(10,G282)) -> 65.28 | L282: =ROUND(K282*J282/365, 2) -> 5.72 | M282: =VLOOKUP(D282, parameters!$B$1:$C$8000, 2, FALSE) -> 0.98 | N282: =VLOOKUP(D282, parameters!$B$1:$D$8000, 3, FALSE) -> 0.1 | O282: =IF(L282>N282, "Yes", "No") -> Yes | P282: {=_xlfn.LET(_xlpm.lambda,L282,_xlpm.target,M282-VLOOKUP(D282,parameters!$F$1:$G$4,2,FALSE),_xlpm.n,_xlfn.SEQUENCE(100,1,0,1),INDEX(_xlpm.n,MATCH(TRUE,ROUND(POISSON(_xlpm.n,_xlpm.lambda,TRUE),2)>=_xlpm.target,0)))} -> 11 | Q282: =POISSON(P282, L282, TRUE) -> 0.98551266 | R282: =ROUND(M282-Q282, 2) -> -0.01 | S282: =IF(R282>VLOOKUP(D282, parameters!$F$1:$G$4, 2, FALSE), "Re-Calculate", "OK") -> OK | T282: =IF(D282=1, L282, " ") -> 5.72 | U282: =IF(D282=2, L282, " ") | V282: =IF(D282=3, L282, " ") | W282: =IF(D282=1, L282*Q282, " ") -> 5.6371324 | X282: =IF(D282=2, L282*Q282, " ") | Y282: =IF(D282=3, L282*Q282, " ") | Z282: =IF(D282=1, K282, " ") -> 65.28 | AA282: =IF(D282=2, K282, " ") | AB282: =IF(D282=3, K282, " ") | AC282: =IF(D282=1, K282*Q282, " ") -> 64.334267 | AD282: =IF(D282=2, K282*Q282, " ") | AE282: =IF(D282=3, K282*Q282, " ")

Sheet partNumbers
A1: PN | B1: Annual FH | C1: RRI | D1: Buy Price (USD) | E1: Aircraft Count | F1: FAM Class
A2: AR4709-13 | B2: 4000 | C2: 0 | D2: 19380 | E2: 126 | F2: STEAS00138
A3: AR4714-11 | B3: 4000 | C3: 0 | D3: 5877.3333 | E3: 165 | F3: STEAS00454
A4: AR4714-7 | B4: 4000 | C4: 0 | D4: 6100 | E4: 165 | F4: STEAS00453
A5: AR90122-5D605 | B5: 4000 | C5: 0 | D5: 117680 | E5: 60 | F5: STEAS00218
A6: Z014H010035C | B6: 4000 | C6: 0 | D6: 140502.45 | E6: 126 | F6: STEAS00179
A7: Z043H0101110 | B7: 4000 | C7: 0 | D7: 7441.22 | E7: 60 | F7: STEAS00178
A8: Z111H0040131 | B8: 4000 | C8: 0 | D8: 8029.07 | E8: 60 | F8: STEAS00052
A9: Z145HA452120 | B9: 4000 | C9: 0 | D9: 76480 | E9: 60 | F9: STEAS00216
A10: Z212H0001110 | B10: 4000 | C10: 0 | D10: 2968.04 | E10: 149 | F10: STEAS00127
A11: Z212H0009110 | B11: 4000 | C11: 0 | D11: 4550 | E11: 60 | F11: A320-FAM027
A12: Z213H0101111 | B12: 4000 | C12: 0 | D12: 8990 | E12: 60 | F12: A320-FAM028
A13: Z233H0000110 | B13: 4000 | C13: 0 | D13: 1124.21 | E13: 126 | F13: STEAS00085
... A282: RCF6717 | B282: 4000 | C282: 0 | D282: 9474.51 | E282: 153 | F282: STEAS00382

Sheet partCapability
A1: No | B1: PNR | C1: OEM | D1: ATA | E1: ADT | F1: SPC | G1: ESS | H1: MTBUR | I1: QPA | J1: MLP | K1: MLP Source | L1: Buy Price | M1: Buy Price Source | N1: Buy price/MLP % | O1: Include/Exclude from Repair Run | P1: Include/Exclude from IP Run | Q1: Grp A,B,C | R1: SPT | S1: To support MBH? (Bo Rong) | T1: Remarks (Bo Rong) | U1: FAM Class | V1: FAM Class Count | W1: Can you provide repair suport for this part? (YES/NO) | X1: Can you repair it internally within your own MRO, or external subcontracor? | Y1: MRO Cage Code | Z1: MRO Location
A2: 155 | B2: 25225-01 | C2: NORD-MICRO GMBH & CO OHG | D2: 21 | E2: HEATER-DUCT | F2: 2 | G2: 3 | H2: 48000 | I2: 2 | J2: 19030 | K2: Airbus web 23/3/26 | L2: 19030 | M2: Airbus web 23/3/26 | N2: 1 | O2: Include | P2: Include | Q2: Grp C (Others) | R2: 30 | U2: A320-FAM001 | V2: 1
A3: 158 | B3: 405005-00000 | C3: THALES AEROSPACE COMMUNICATIONS | D3: 23 | E3: ANTENNA-LOW GAIN | F3: 6 | G3: 2 | H3: 99750 | I3: 1 | J3: 72640 | K3: Airbus web 23/3/26 | L3: 72640 | M3: Airbus web 23/3/26 | N3: 1 | O3: Exclude | P3: Exclude | S3: No | T3: Reference to JAL experience | U3: A320-FAM002 | V3: 1
A4: 276 | B4: Z934H0503110 | C4: KID SYSTEME GMBH | D4: 23 | E4: CAMERA-CDSS | F4: 2 | G4: 3 | H4: 86400 | I4: 1 | J4: 7780 | K4: Airbus web 23/3/26 | L4: 7780 | M4: Airbus web 23/3/26 | N4: 1 | O4: Include | P4: Include | Q4: Grp C (Others) | R4: 30 | U4: A320-FAM003 | V4: 1
A5: 307 | B5: Z318H078031E | C5: AIRBUS OPERATIONS GMBH | D5: 23 | E5: PANEL-INFORMATION | F5: 2 | G5: 3 | H5: 90000 | I5: 1 | J5: 4770 | K5: Airbus web 23/3/26 | L5: 4770 | M5: Airbus web 23/3/26 | N5: 1 | O5: Include | P5: Include | Q5: Grp C (Others) | R5: 30 | U5: A320-FAM004 | V5: 1
A6: 92 | B6: Z318H015013E | C6: AIRBUS OPERATIONS GMBH | D6: 23 | E6: PSU-PASSENGER SERVICE UNIT | F6: 2 | G6: 3 | H6: 90000 | I6: 10 | J6: 7527.7 | K6: Airbus C9072 Catalogue 2026 | L6: 7527.7 | M6: Airbus C9072 Catalogue 2026 | N6: 1 | O6: Include | P6: Include | Q6: Grp C (Others) | R6: 30 | U6: A320-FAM005 | V6: 1
A7: 52 | B7: Z318H017013E | C7: AIRBUS OPERATIONS GMBH | D7: 23 | E7: PSU-PASSENGER SERVICE UNIT | F7: 2 | G7: 3 | H7: 90000 | I7: 36 | J7: 7527.7 | K7: Airbus C9072 Catalogue 2026 | L7: 7527.7 | M7: Airbus C9072 Catalogue 2026 | N7: 1 | O7: Include | P7: Include | Q7: Grp C (Others) | R7: 30 | U7: A320-FAM006 | V7: 1
A8: 83 | B8: Z318H037023E | C8: AIRBUS OPERATIONS GMBH | D8: 23 | E8: PSU-PASSENGER SERVICE UNIT | F8: 2 | G8: 3 | H8: 90000 | I8: 22 | J8: 9610 | K8: Airbus web 23/3/26 | L8: 9610 | M8: Airbus web 23/3/26 | N8: 1 | O8: Include | P8: Include | Q8: Grp C (Others) | R8: 30 | U8: A320-FAM007 | V8: 1
A9: 49 | B9: RMP4381AA110101 | C9: THALES AEROSPACE COMMUNICATIONS | D9: 23 | E9: RMP-RADIO MANAGEMENT PANEL | F9: 2 | G9: 1 | H9: 23400 | I9: 2 | J9: 52010 | K9: Airbus web 23/3/26 | L9: 52010 | M9: Airbus web 23/3/26 | N9: 1 | O9: Exclude (BTB with Thales) | P9: Include | Q9: Grp B (OEM) | R9: 30 | T9: Thales | U9: A320-FAM008 | V9: 1
A10: 61 | B10: 405045-00001 | C10: THALES AEROSPACE COMMUNICATIONS | D10: 23 | E10: SDU-SATELLITE DATA UNIT | F10: 6 | G10: 2 | H10: 29925 | I10: 1 | J10: 112260 | K10: Airbus web 23/3/26 | L10: 112260 | M10: Airbus web 23/3/26 | N10: 1 | O10: Include | P10: Include | Q10: Grp C (Others) | R10: 30 | U10: A320-FAM009 | V10: 1
A11: 313 | B11: 1J520-10140-000 | C11: DIEHL AEROSPACE GMBH | D11: 25 | E11: CLEDU-CABIN LED UNIT | F11: 2 | G11: 3 | H11: 57600 | I11: 1 | J11: 2020 | K11: Airbus web 23/3/26 | L11: 2020 | M11: Airbus web 23/3/26 | N11: 1 | O11: Exclude | P11: Exclude | S11: No | T11: High BER Rate | U11: A320-FAM010 | V11: 1
A12: 279 | B12: 1J520-10180-000 | C12: DIEHL AEROSPACE GMBH | D12: 25 | E12: CLEDU-CABIN LED UNIT | F12: 2 | G12: 3 | H12: 57600 | I12: 3 | J12: 1520 | K12: Airbus web 23/3/26 | L12: 1520 | M12: Airbus web 23/3/26 | N12: 1 | O12: Exclude | P12: Exclude | S12: No | T12: High BER Rate | U12: A320-FAM011 | V12: 1
A13: 374 | B13: 1J520-10260-000 | C13: DIEHL AEROSPACE GMBH | D13: 25 | E13: CLEDU-CABIN LED UNIT | F13: 2 | G13: 3 | H13: 999999 | I13: 3 | J13: 1520 | K13: Airbus web 23/3/26 | L13: 1520 | M13: Airbus web 23/3/26 | N13: 1 | O13: Exclude | P13: Exclude | S13: No | T13: High BER Rate | U13: A320-FAM012 | V13: 1
A14: 384 | B14: T900200 | C14: SAFRAN CABIN GERMANY GMBH | D14: 25 | E14: COMPACTOR-TRASH | F14: 2 | G14: 3 | H14: 11250 | I14: 1 | J14: 0 | K14: 0 | L14: 0 | M14: 0 | N14: 0 | O14: Exclude | P14: Exclude | S14: No | T14: High Removal | U14: A320-FAM013 | V14: 2
A15: 385 | B15: T900501 | C15: SAFRAN CABIN GERMANY GMBH | D15: 25 | E15: COMPACTOR-TRASH | F15: 2 | G15: 3 | H15: 11250 | I15: 1 | J15: 0 | K15: 0 | L15: 0 | M15: 0 | N15: 0 | O15: Exclude | P15: Exclude | S15: No | T15: High Removal | U15: A320-FAM013 | V15: 2
A16: 329 | B16: 22C15L120700009 | C16: BE AEROSPACE SYSTEMS GMBH | D16: 25 | E16: CONTAINER ASSY-CHEMICAL OXYGEN,TWO MASK | F16: 2 | G16: 2 | H16: 194400 | I16: 3 | J16: 1830 | K16: Airbus web 23/3/26 | L16: 1830 | M16: Airbus web 23/3/26 | N16: 1 | O16: Exclude | P16: Exclude | S16: No | T16: Typically not supported under MBH | U16: A320-FAM014 | V16: 2
A17: 340 | B17: 22C15L150700009 | C17: BE AEROSPACE SYSTEMS GMBH | D17: 25 | E17: CONTAINER ASSY-CHEMICAL OXYGEN,TWO MASK | F17: 2 | G17: 2 | H17: 390000 | I17: 4 | J17: 1830 | K17: Airbus web 23/3/26 | L17: 1830 | M17: Airbus web 23/3/26 | N17: 1 | O17: Exclude | P17: Exclude | S17: No | T17: Typically not supported under MBH | U17: A320-FAM014 | V17: 2
A18: 170 | B18: 25226-01AA | C18: NORD-MICRO GMBH & CO OHG | D18: 21 | E18: CONTROLLER-HEAT | F18: 2 | G18: 2 | H18: 60000 | I18: 2 | J18: 19370 | K18: Airbus web 23/3/26 | L18: 19370 | M18: Airbus web 23/3/26 | N18: 1 | O18: Include | P18: Include | Q18: Grp C (Others) | R18: 30 | U18: A320-FAM016 | V18: 1
A19: 391 | B19: FE459100002 | C19: RATIER-FIGEAC | D19: 27 | E19: RBPU-RUDDER AND BRAKE PEDAL UNIT,CAPT | F19: 2 | G19: 2 | H19: 37800 | I19: 1 | J19: 107810 | K19: Airbus web 23/3/26 | L19: 107810 | M19: Airbus web 23/3/26 | N19: 1 | O19: Include | P19: Include | Q19: Grp C (Others) | R19: 30 | U19: A320-FAM017 | V19: 1
A20: 392 | B20: FE459200002 | C20: RATIER-FIGEAC | D20: 27 | E20: RBPU-RUDDER AND BRAKE PEDAL UNIT,F0 | F20: 2 | G20: 2 | H20: 86400 | I20: 1 | J20: 68100 | K20: Airbus web 23/3/26 | L20: 68100 | M20: Airbus web 23/3/26 | N20: 1 | O20: Include | P20: Include | Q20: Grp C (Others) | R20: 30 | U20: A320-FAM018 | V20: 1
A21: 183 | B21: 812A0001-01 | C21: LIEBHERR-AEROSPACE LINDENBERG | D21: 27 | E21: SERVOVALVE | F21: 2 | G21: 2 | H21: 98336 | I21: 3 | J21: 14990 | K21: Airbus web 23/3/26 | L21: 14990 | M21: Airbus web 23/3/26 | N21: 1 | O21: Exclude (BTB with Liebherr) | P21: Include | Q21: Grp B (OEM) | R21: 30 | T21: Liebherr | U21: A320-FAM019 | V21: 1
A22: 227 | B22: 3863D0000-01 | C22: LIEBHERR-AEROSPACE LINDENBERG | D22: 27 | E22: TRANSDUCER,PRESSURE,FLUID-HYDRAULIC | F22: 2 | G22: 3 | H22: 152000 | I22: 6 | J22: 6130 | K22: Airbus web 23/3/26 | L22: 6130 | M22: Airbus web 23/3/26 | N22: 1 | O22: Exclude (BTB with Liebherr) | P22: Include | Q22: Grp B (OEM) | R22: 30 | T22: Liebherr | U22: A320-FAM020 | V22: 1
A23: 267 | B23: 12M0172 | C23: EATON LIMITED | D23: 28 | E23: FUEL-TRANSFER VALVE | F23: 2 | G23: 2 | H23: 210000 | I23: 2 | J23: 12770 | K23: Airbus web 23/3/26 | L23: 12770 | M23: Airbus web 23/3/26 | N23: 1 | O23: Include | P23: Include | Q23: Grp C (Others) | R23: 30 | U23: A320-FAM021 | V23: 1
A24: 305 | B24: 59127-0101 | C24: SIMMONDS PRECISION PRODUCTS INC | D24: 28 | E24: HARNESS 4S | F24: 6 | G24: 1 | H24: 117345 | I24: 1 | J24: 6230 | K24: Airbus web 23/3/26 | L24: 6230 | M24: Airbus web 23/3/26 | N24: 1 | O24: Include | P24: Include | Q24: Grp C (Others) | R24: 30 | U24: A320-FAM022 | V24: 1
A25: 306 | B25: 59128-0101 | C25: SIMMONDS PRECISION PRODUCTS INC | D25: 28 | E25: HARNESS 5S | F25: 6 | G25: 1 | H25: 117345 | I25: 1 | J25: 6230 | K25: Airbus web 23/3/26 | L25: 6230 | M25: Airbus web 23/3/26 | N25: 1 | O25: Include | P25: Include | Q25: Grp C (Others) | R25: 30 | U25: A320-FAM023 | V25: 1
A26: 343 | B26: 25K0037-1200 | C26: EATON LIMITED | D26: 28 | E26: REFUEL VALVE CANISTER | F26: 2 | G26: 2 | H26: 630882 | I26: 1 | J26: 9470 | K26: Airbus web 23/3/26 | L26: 9470 | M26: Airbus web 23/3/26 | N26: 1 | O26: Include | P26: Include | Q26: Grp C (Others) | R26: 30 | U26: A320-FAM024 | V26: 1
A27: 393 | B27: 12M0172-1100 | C27: EATON LIMITED | D27: 28 | E27: VALVE FUEL, TRANSFER | F27: 2 | G27: 2 | H27: 210000 | I27: 2 | J27: 12770 | K27: Airbus web 24/3/26 12M0172 | L27: 12770 | M27: Airbus web 24/3/26 12M0172 | N27: 1 | O27: Include | P27: Include | Q27: Grp C (Others) | R27: 30 | U27: A320-FAM025 | V27: 1
A28: 277 | B28: 12M0134-1100 | C28: EATON LIMITED | D28: 28 | E28: VALVE-LP FUEL | F28: 2 | G28: 1 | H28: 190391 | I28: 3 | J28: 6460 | K28: Airbus web 23/3/26 | L28: 6460 | M28: Airbus web 23/3/26 | N28: 1 | O28: Include | P28: Include | Q28: Grp C (Others) | R28: 30 | U28: A320-FAM026 | V28: 1
A29: 254 | B29: Z212H0009110 | C29: AIRBUS OPERATIONS GMBH | D29: 30 | E29: CONTROL UNIT | F29: 2 | G29: 3 | H29: 30000 | I29: 1 | J29: 4550 | K29: Airbus web 23/3/26 | L29: 4550 | M29: Airbus web 23/3/26 | N29: 1 | O29: Include | P29: Include | Q29: Grp C (Others) | R29: 30 | U29: A320-FAM027 | V29: 1
A30: 131 | B30: Z213H0101111 | C30: AIRBUS OPERATIONS GMBH | D30: 30 | E30: UNIT-CONTROL | F30: 2 | G30: 3 | H30: 30000 | I30: 4 | J30: 8990 | K30: Airbus web 23/3/26 | L30: 8990 | M30: Airbus web 23/3/26 | N30: 1 | O30: Include | P30: Include | Q30: Grp C (Others) | R30: 30 | U30: A320-FAM028 | V30: 1
A31: 120 | B31: C19628AD | C31: THALES AVS FRANCE SAS | D31: 31 | E31: HCU-HEAD UP COMBINIER UNIT CAPTAIN | F31: 6 | G31: 2 | H31: 86535 | I31: 1 | J31: 107200 | K31: Airbus web 23/3/26 | L31: 107200 | M31: Airbus web 23/3/26 | N31: 1 | O31: Exclude (BTB with Thales) | P31: Include | Q31: Grp B (OEM) | R31: 30 | T31: Thales | U31: A320-FAM029 | V31: 1
A32: 121 | B32: C19643AD | C32: THALES AVS FRANCE SAS | D32: 31 | E32: HCU-HEAD-UP COMBINER UNIT FIRST OFFICER | F32: 6 | G32: 2 | H32: 86535 | I32: 1 | J32: 107200 | K32: Airbus web 23/3/26 | L32: 107200 | M32: Airbus web 23/3/26 | N32: 1 | O32: Exclude (BTB with Thales) | P32: Include | Q32: Grp B (OEM) | R32: 30 | T32: Thales | U32: A320-FAM030 | V32: 1
A33: 341 | B33: 10-458301-000 | C33: SAFRAN LANDING SYSTEMS (SAS) | D33: 32 | E33: HARNESS, 1M AXLE | F33: 2 | G33: 1 | H33: 500000 | I33: 2 | J33: 5230 | K33: Airbus web 23/3/26 | L33: 5230 | M33: Airbus web 23/3/26 | N33: 1 | O33: Include | P33: Include | Q33: Grp C (Others) | R33: 30 | U33: A320-FAM031 | V33: 1
A34: 337 | B34: 10-458501-000 | C34: SAFRAN LANDING SYSTEMS (SAS) | D34: 32 | E34: HARNESS, 2M AXLE | F34: 2 | G34: 1 | H34: 500000 | I34: 2 | J34: 6540 | K34: Airbus web 23/3/26 | L34: 6540 | M34: Airbus web 23/3/26 | N34: 1 | O34: Include | P34: Include | Q34: Grp C (Others) | R34: 30 | U34: A320-FAM032 | V34: 1
A35: 296 | B35: 10-385401-001 | C35: SAFRAN LANDING SYSTEMS (SAS) | D35: 32 | E35: HARNESS-2M ELECTRICAL | F35: 2 | G35: 3 | H35: 297900 | I35: 1 | J35: 18500 | K35: Airbus web 23/3/26 | L35: 18500 | M35: Airbus web 23/3/26 | N35: 1 | O35: Include | P35: Include | Q35: Grp C (Others) | R35: 30 | U35: A320-FAM033 | V35: 1
A36: 93 | B36: 10-386001-001 | C36: SAFRAN LANDING SYSTEMS (SAS) | D36: 32 | E36: RETRACTION ACTUATOR COMPLETE | F36: 2 | G36: 1 | H36: 37500 | I36: 1 | J36: 64160 | K36: Airbus web 23/3/26 | L36: 64160 | M36: Airbus web 23/3/26 | N36: 1 | O36: Include | P36: Include | Q36: Grp C (Others) | R36: 30 | U36: A320-FAM038 | V36: 1
A37: 247 | B37: 2A522-10000-000 | C37: DIEHL AEROSPACE GMBH | D37: 33 | E37: PSU-MINI EMERGENCY POWER SUPPLY UNIT,LIGHT | F37: 2 | G37: 3 | H37: 90000 | I37: 4 | J37: 3780 | K37: Airbus web 23/3/26 | L37: 3780 | M37: Airbus web 23/3/26 | N37: 1 | O37: Include | P37: Include | Q37: Grp C (Others) | R37: 30 | U37: A320-FAM039 | V37: 1
A38: 159 | B38: 2LA456884-01 | C38: GOODRICH LIGHTING SYSTEMS GMBH | D38: 33 | F38: 2 | G38: 3 | H38: 24881 | I38: 1 | J38: 21230 | K38: Airbus web 23/3/26 | L38: 21230 | M38: Airbus web 23/3/26 | N38: 1 | O38: Include | P38: Include | Q38: Grp C (Others) | R38: 30 | U38: A320-FAM040 | V38: 1
A39: 141 | B39: 2LA456884-02 | C39: GOODRICH LIGHTING SYSTEMS GMBH | D39: 33 | F39: 2 | G39: 3 | H39: 24881 | I39: 1 | J39: 21230 | K39: Airbus web 23/3/26 | L39: 21230 | M39: Airbus web 23/3/26 | N39: 1 | O39: Include | P39: Include | Q39: Grp C (Others) | R39: 30 | U39: A320-FAM041 | V39: 1
A40: 78 | B40: 822-3150-301 | C40: ROCKWELL COLLINS INC | D40: 34 | E40: TRANSCEIVER-WEATHER RADAR | F40: 2 | G40: 2 | H40: 36000 | I40: 1 | J40: 95370 | K40: Airbus web 23/3/26 | L40: 95370 | M40: Airbus web 23/3/26 | N40: 1 | O40: Include | P40: Include | Q40: Grp C (Others) | R40: 30 | T40: Rockwell Collins | U40: A320-FAM042 | V40: 1
...

Sheet parameters
A1: Supported Fleet Statistics | F1: ESS CODE | G1: Tolerance Level
A2: Annual Flying Hours (per aircraft) | C2: see Column B in Provisioning Model tab | F2: 1 | G2: 0
A3: Total Repair Time (Including Freight) | C3: see Column J in Provisioning Model tab | F3: 2 | G3: 0
A4: CRF | B4: 0 | C4: 0-1 | F4: 3 | G4: 0
A8: Provisioning Criteria | B8: ESS | C8: Protection Level | D8: Minimum Annual Demand (MAD) | E8: Arisings TRT | F8: Actual TRT Demand | G8: Actual Fill Rate (TAT) | H8: Arisings TRT (Annual) | I8: Actual TRT Demand (Annual) | J8: Actual Fill Rate (Annual) | L8: Desired SL%
A9: Target Fill Rate % Ess 1 | B9: 1 | C9: 0.98 | D9: 0.1 | L9: 98
A10: Target Fill Rate % Ess 2 | B10: 2 | C10: 0.93 | D10: 0.1 | L10: 95
A11: Target Fill Rate % Ess 3 | B11: 3 | C11: 0.9 | D11: 0.1 | L11: 92
C12: Vary the Protection Level in Column C such that the "Actual Fill Rate" in Column G meets the Desired Service Level% in Column L
A16: PNs with #N/A output issues - record data if applicable
A17: Prt Number | B17: Selected MTBUR | C17: amended MTBUR
